Workbook

Sheet Acumulado
A1: Sigmaseg S.A. de C.V. | B1: Anual P | C1: Anual R | D1: Anual D | E1: Ene P | F1: Enero | G1: Ene D | H1: Feb P | I1: Febrero | J1: Feb D | K1: Mar P | L1: Marzo | M1: Mar D | N1: Abr P | O1: Abril | P1: Abr D | Q1: May P | R1: Mayo | S1: May D | T1: Jun P | U1: Junio | V1: Jun D | W1: Jul P | X1: Julio | Y1: Jul D | Z1: Ago P | AA1: Agosto | AB1: Ago D | AC1: Sep P | AD1: Septiembre | AE1: Sep D | AF1: Oct P | AG1: Octubre | AH1: Oct D | AI1: Nov P | AJ1: Noviembre | AK1: Nov D | AL1: Dic P | AM1: Diciembre | AN1: Dic D
A3: Utilidad Bruta | B3: =B5-B10+B49-B54 -> 0 | C3: =C5-C10+C49-C54 -> 0 | D3: =C3-B3 -> 0 | E3: =E5-E10+E49-E54 -> 0 | F3: =F5-F10+F49-F54 -> 0 | G3: =F3-E3 -> 0 | H3: =H5-H10+H49-H54 -> 0 | I3: =I5-I10+I49-I54 -> 0 | J3: =I3-H3 -> 0 | K3: =K5-K10+K49-K54 -> 0 | L3: =L5-L10+L49-L54 -> 0 | M3: =L3-K3 -> 0 | N3: =N5-N10+N49-N54 -> 0 | O3: =O5-O10+O49-O54 -> 0 | P3: =O3-N3 -> 0 | Q3: =Q5-Q10+Q49-Q54 -> 0 | R3: =R5-R10+R49-R54 -> 0 | S3: =R3-Q3 -> 0 | T3: =T5-T10+T49-T54 -> 0 | U3: =U5-U10+U49-U54 -> 0 | V3: =U3-T3 -> 0 | W3: =W5-W10+W49-W54 -> 0 | X3: =X5-X10+X49-X54 -> 0 | Y3: =X3-W3 -> 0 | Z3: =Z5-Z10+Z49-Z54 -> 0 | AA3: =AA5-AA10+AA49-AA54 -> 0 | AB3: =AA3-Z3 -> 0 | AC3: =AC5-AC10+AC49-AC54 -> 0 | AD3: =AD5-AD10+AD49-AD54 -> 0 | AE3: =AD3-AC3 -> 0 | AF3: =AF5-AF10+AF49-AF54 -> 0 | AG3: =AG5-AG10+AG49-AG54 -> 0 | AH3: =AG3-AF3 -> 0 | AI3: =AI5-AI10+AI49-AI54 -> 0 | AJ3: =AJ5-AJ10+AJ49-AJ54 -> 0 | AK3: =AJ3-AI3 -> 0 | AL3: =AL5-AL10+AL49-AL54 -> 0 | AM3: =AM5-AM10+AM49-AM54 -> 0 | AN3: =AM3-AL3 -> 0
A5: Total de Ingresos | B5: =SUM(B6:B8) -> 0 | C5: =SUM(C6:C8) -> 0 | D5: =C5-B5 -> 0 | E5: =SUM(E6:E8) -> 0 | F5: =SUM(F6:F8) -> 0 | G5: =F5-E5 -> 0 | H5: =SUM(H6:H8) -> 0 | I5: =SUM(I6:I8) -> 0 | J5: =SUM(J6:J8) -> 0 | K5: =SUM(K6:K8) -> 0 | L5: =SUM(L6:L8) -> 0 | M5: =SUM(M6:M8) -> 0 | N5: =SUM(N6:N8) -> 0 | O5: =SUM(O6:O8) -> 0 | ... AN5: =SUM(AN6:AN8) -> 0
A6: A01 Seguridad | B6: =SUM(IF(MONTH(TODAY())>1,E6,0), IF(MONTH(TODAY())>2,H6,0), IF(MONTH(TODAY())>3,K6,0), IF(MONTH(TODAY())>4,N6,0), IF(MONTH(TODAY())>5,Q6,0), IF(MONTH(TODAY())>6,T6,0), IF(MONTH(TODAY())>7,W6,0), IF(MONTH(TODAY())>8,Z6,0), IF(MONTH(TODAY())>9,AC6,0), IF(MONTH(TODAY())>10,AF6,0), IF(MONTH(TODAY())>11,AI6,0), IF(MONTH(TODAY())>12,AL6,0)) -> 0 | C6: =SUM(IF(MONTH(TODAY())>1,F6,0), IF(MONTH(TODAY())>2,I6,0), IF(MONTH(TODAY())>3,L6,0), IF(MONTH(TODAY())>4,O6,0), IF(MONTH(TODAY())>5,R6,0), IF(MONTH(TODAY())>6,U6,0), IF(MONTH(TODAY())>7,X6,0), IF(MONTH(TODAY())>8,AA6,0), IF(MONTH(TODAY())>9,AD6,0), IF(MONTH(TODAY())>10,AG6,0), IF(MONTH(TODAY())>11,AJ6,0), IF(MONTH(TODAY())>12,AM6,0)) -> 0 | D6: =C6-B6 -> 0 | E6: {=IFERROR(SUMIF(Consolidado!$C$3:$C63, $A6, INDEX(Consolidado!$E$3:$P$100, , MATCH(E$1, Consolidado!$E$2:$P$2, 0))), "")} | F6: =IFERROR( LET( hoja, LEFT(F$1,3)&"R", fila, MATCH( RIGHT($A6, LEN($A6)-4), INDIRECT(hoja&"!$A:$A"), 0 ), columna, MATCH( "Totales", INDIRECT(hoja&"!$6:$6"), 0 ), valor, INDEX( INDIRECT(hoja&"!$A:$ZZ"), fila, columna ), IF(valor="-", "", valor) ), "") | G6: =F6-E6 -> 0 | H6: {=IFERROR(SUMIF(Consolidado!$C$3:$C63, $A6, INDEX(Consolidado!$E$3:$P$100, , MATCH(H$1, Consolidado!$E$2:$P$2, 0))), "")} | I6: =IFERROR( LET( hoja, LEFT(I$1,3)&"R", fila, MATCH( RIGHT($A6, LEN($A6)-4), INDIRECT(hoja&"!$A:$A"), 0 ), columna, MATCH( "Totales", INDIRECT(hoja&"!$6:$6"), 0 ), valor, INDEX( INDIRECT(hoja&"!$A:$ZZ"), fila, columna ), IF(valor="-", "", valor) ), "") | J6: =I6-H6 -> 0 | K6: {=IFERROR(SUMIF(Consolidado!$C$3:$C63, $A6, INDEX(Consolidado!$E$3:$P$100, , MATCH(K$1, Consolidado!$E$2:$P$2, 0))), "")} | L6: =IFERROR( LET( hoja, LEFT(L$1,3)&"R", fila, MATCH( RIGHT($A6, LEN($A6)-4), INDIRECT(hoja&"!$A:$A"), 0 ), columna, MATCH( "Totales", INDIRECT(hoja&"!$6:$6"), 0 ), valor, INDEX( INDIRECT(hoja&"!$A:$ZZ"), fila, columna ), IF(valor="-", "", valor) ), "") | M6: =L6-K6 -> 0 | N6: {=IFERROR(SUMIF(Consolidado!$C$3:$C63, $A6, INDEX(Consolidado!$E$3:$P$100, , MATCH(N$1, Consolidado!$E$2:$P$2, 0))), "")} | O6: =IFERROR( LET( hoja, LEFT(O$1,3)&"R", fila, MATCH( RIGHT($A6, LEN($A6)-4), INDIRECT(hoja&"!$A:$A"), 0 ), columna, MATCH( "Totales", INDIRECT(hoja&"!$6:$6"), 0 ), valor, INDEX( INDIRECT(hoja&"!$A:$ZZ"), fila, columna ), IF(valor="-", "", valor) ), "") | P6: =O6-N6 -> 0 | Q6: {=IFERROR(SUMIF(Consolidado!$C$3:$C63, $A6, INDEX(Consolidado!$E$3:$P$100, , MATCH(Q$1, Consolidado!$E$2:$P$2, 0))), "")} | R6: =IFERROR( LET( hoja, LEFT(R$1,3)&"R", fila, MATCH( RIGHT($A6, LEN($A6)-4), INDIRECT(hoja&"!$A:$A"), 0 ), columna, MATCH( "Totales", INDIRECT(hoja&"!$6:$6"), 0 ), valor, INDEX( INDIRECT(hoja&"!$A:$ZZ"), fila, columna ), IF(valor="-", "", valor) ), "") | S6: =R6-Q6 -> 0 | T6: {=IFERROR(SUMIF(Consolidado!$C$3:$C63, $A6, INDEX(Consolidado!$E$3:$P$100, , MATCH(T$1, Consolidado!$E$2:$P$2, 0))), "")} | U6: =IFERROR( LET( hoja, LEFT(U$1,3)&"R", fila, MATCH( RIGHT($A6, LEN($A6)-4), INDIRECT(hoja&"!$A:$A"), 0 ), columna, MATCH( "Totales", INDIRECT(hoja&"!$6:$6"), 0 ), valor, INDEX( INDIRECT(hoja&"!$A:$ZZ"), fila, columna ), IF(valor="-", "", valor) ), "") | V6: =U6-T6 -> 0 | W6: {=IFERROR(SUMIF(Consolidado!$C$3:$C63, $A6, INDEX(Consolidado!$E$3:$P$100, , MATCH(W$1, Consolidado!$E$2:$P$2, 0))), "")} | X6: =IFERROR( LET( hoja, LEFT(X$1,3)&"R", fila, MATCH( RIGHT($A6, LEN($A6)-4), INDIRECT(hoja&"!$A:$A"), 0 ), columna, MATCH( "Totales", INDIRECT(hoja&"!$6:$6"), 0 ), valor, INDEX( INDIRECT(hoja&"!$A:$ZZ"), fila, columna ), IF(valor="-", "", valor) ), "") | Y6: =X6-W6 -> 0 | Z6: {=IFERROR(SUMIF(Consolidado!$C$3:$C63, $A6, INDEX(Consolidado!$E$3:$P$100, , MATCH(Z$1, Consolidado!$E$2:$P$2, 0))), "")} | AA6: =IFERROR( LET( hoja, LEFT(AA$1,3)&"R", fila, MATCH( RIGHT($A6, LEN($A6)-4), INDIRECT(hoja&"!$A:$A"), 0 ), columna, MATCH( "Totales", INDIRECT(hoja&"!$6:$6"), 0 ), valor, INDEX( INDIRECT(hoja&"!$A:$ZZ"), fila, columna ), IF(valor="-", "", valor) ), "") | AB6: =AA6-Z6 -> 0 | AC6: {=IFERROR(SUMIF(Consolidado!$C$3:$C63, $A6, INDEX(Consolidado!$E$3:$P$100, , MATCH(AC$1, Consolidado!$E$2:$P$2, 0))), "")} | AD6: =IFERROR( LET( hoja, LEFT(AD$1,3)&"R", fila, MATCH( RIGHT($A6, LEN($A6)-4), INDIRECT(hoja&"!$A:$A"), 0 ), columna, MATCH( "Totales", INDIRECT(hoja&"!$6:$6"), 0 ), valor, INDEX( INDIRECT(hoja&"!$A:$ZZ"), fila, columna ), IF(valor="-", "", valor) ), "") | AE6: =AD6-AC6 -> 0 | AF6: {=IFERROR(SUMIF(Consolidado!$C$3:$C63, $A6, INDEX(Consolidado!$E$3:$P$100, , MATCH(AF$1, Consolidado!$E$2:$P$2, 0))), "")} | AG6: =IFERROR( LET( hoja, LEFT(AG$1,3)&"R", fila, MATCH( RIGHT($A6, LEN($A6)-4), INDIRECT(hoja&"!$A:$A"), 0 ), columna, MATCH( "Totales", INDIRECT(hoja&"!$6:$6"), 0 ), valor, INDEX( INDIRECT(hoja&"!$A:$ZZ"), fila, columna ), IF(valor="-", "", valor) ), "") | AH6: =AG6-AF6 -> 0 | AI6: {=IFERROR(SUMIF(Consolidado!$C$3:$C63, $A6, INDEX(Consolidado!$E$3:$P$100, , MATCH(AI$1, Consolidado!$E$2:$P$2, 0))), "")} | AJ6: =IFERROR( LET( hoja, LEFT(AJ$1,3)&"R", fila, MATCH( RIGHT($A6, LEN($A6)-4), INDIRECT(hoja&"!$A:$A"), 0 ), columna, MATCH( "Totales", INDIRECT(hoja&"!$6:$6"), 0 ), valor, INDEX( INDIRECT(hoja&"!$A:$ZZ"), fila, columna ), IF(valor="-", "", valor) ), "") | AK6: =AJ6-AI6 -> 0 | AL6: {=IFERROR(SUMIF(Consolidado!$C$3:$C63, $A6, INDEX(Consolidado!$E$3:$P$100, , MATCH(AL$1, Consolidado!$E$2:$P$2, 0))), "")} | AM6: =IFERROR( LET( hoja, LEFT(AM$1,3)&"R", fila, MATCH( RIGHT($A6, LEN($A6)-4), INDIRECT(hoja&"!$A:$A"), 0 ), columna, MATCH( "Totales", INDIRECT(hoja&"!$6:$6"), 0 ), valor, INDEX( INDIRECT(hoja&"!$A:$ZZ"), fila, columna ), IF(valor="-", "", valor) ), "") | AN6: =AM6-AL6 -> 0
A7: A02 Monitoreo | B7: =SUM(IF(MONTH(TODAY())>1,E7,0), IF(MONTH(TODAY())>2,H7,0), IF(MONTH(TODAY())>3,K7,0), IF(MONTH(TODAY())>4,N7,0), IF(MONTH(TODAY())>5,Q7,0), IF(MONTH(TODAY())>6,T7,0), IF(MONTH(TODAY())>7,W7,0), IF(MONTH(TODAY())>8,Z7,0), IF(MONTH(TODAY())>9,AC7,0), IF(MONTH(TODAY())>10,AF7,0), IF(MONTH(TODAY())>11,AI7,0), IF(MONTH(TODAY())>12,AL7,0)) -> 0 | C7: =SUM(IF(MONTH(TODAY())>1,F7,0), IF(MONTH(TODAY())>2,I7,0), IF(MONTH(TODAY())>3,L7,0), IF(MONTH(TODAY())>4,O7,0), IF(MONTH(TODAY())>5,R7,0), IF(MONTH(TODAY())>6,U7,0), IF(MONTH(TODAY())>7,X7,0), IF(MONTH(TODAY())>8,AA7,0), IF(MONTH(TODAY())>9,AD7,0), IF(MONTH(TODAY())>10,AG7,0), IF(MONTH(TODAY())>11,AJ7,0), IF(MONTH(TODAY())>12,AM7,0)) -> 0 | D7: =C7-B7 -> 0 | E7: {=IFERROR(SUMIF(Consolidado!$C$3:$C$100, $A7, INDEX(Consolidado!$E$3:$P$100, , MATCH(E$1, Consolidado!$E$2:$P$2, 0))), "")} | F7: =IFERROR( LET( hoja, LEFT(F$1,3)&"R", fila, MATCH( RIGHT($A7, LEN($A7)-4), INDIRECT(hoja&"!$A:$A"), 0 ), columna, MATCH( "Totales", INDIRECT(hoja&"!$6:$6"), 0 ), valor, INDEX( INDIRECT(hoja&"!$A:$ZZ"), fila, columna ), IF(valor="-", "", valor) ), "") | G7: =F7-E7 -> 0 | H7: {=IFERROR(SUMIF(Consolidado!$C$3:$C$100, $A7, INDEX(Consolidado!$E$3:$P$100, , MATCH(H$1, Consolidado!$E$2:$P$2, 0))), "")} | I7: =IFERROR( LET( hoja, LEFT(I$1,3)&"R", fila, MATCH( RIGHT($A7, LEN($A7)-4), INDIRECT(hoja&"!$A:$A"), 0 ), columna, MATCH( "Totales", INDIRECT(hoja&"!$6:$6"), 0 ), valor, INDEX( INDIRECT(hoja&"!$A:$ZZ"), fila, columna ), IF(valor="-", "", valor) ), "") | J7: =I7-H7 -> 0 | K7: {=IFERROR(SUMIF(Consolidado!$C$3:$C$100, $A7, INDEX(Consolidado!$E$3:$P$100, , MATCH(K$1, Consolidado!$E$2:$P$2, 0))), "")} | L7: =IFERROR( LET( hoja, LEFT(L$1,3)&"R", fila, MATCH( RIGHT($A7, LEN($A7)-4), INDIRECT(hoja&"!$A:$A"), 0 ), columna, MATCH( "Totales", INDIRECT(hoja&"!$6:$6"), 0 ), valor, INDEX( INDIRECT(hoja&"!$A:$ZZ"), fila, columna ), IF(valor="-", "", valor) ), "") | M7: =L7-K7 -> 0 | N7: {=IFERROR(SUMIF(Consolidado!$C$3:$C$100, $A7, INDEX(Consolidado!$E$3:$P$100, , MATCH(N$1, Consolidado!$E$2:$P$2, 0))), "")} | O7: =IFERROR( LET( hoja, LEFT(O$1,3)&"R", fila, MATCH( RIGHT($A7, LEN($A7)-4), INDIRECT(hoja&"!$A:$A"), 0 ), columna, MATCH( "Totales", INDIRECT(hoja&"!$6:$6"), 0 ), valor, INDEX( INDIRECT(hoja&"!$A:$ZZ"), fila, columna ), IF(valor="-", "", valor) ), "") | P7: =O7-N7 -> 0 | Q7: {=IFERROR(SUMIF(Consolidado!$C$3:$C$100, $A7, INDEX(Consolidado!$E$3:$P$100, , MATCH(Q$1, Consolidado!$E$2:$P$2, 0))), "")} | R7: =IFERROR( LET( hoja, LEFT(R$1,3)&"R", fila, MATCH( RIGHT($A7, LEN($A7)-4), INDIRECT(hoja&"!$A:$A"), 0 ), columna, MATCH( "Totales", INDIRECT(hoja&"!$6:$6"), 0 ), valor, INDEX( INDIRECT(hoja&"!$A:$ZZ"), fila, columna ), IF(valor="-", "", valor) ), "") | S7: =R7-Q7 -> 0 | T7: {=IFERROR(SUMIF(Consolidado!$C$3:$C$100, $A7, INDEX(Consolidado!$E$3:$P$100, , MATCH(T$1, Consolidado!$E$2:$P$2, 0))), "")} | U7: =IFERROR( LET( hoja, LEFT(U$1,3)&"R", fila, MATCH( RIGHT($A7, LEN($A7)-4), INDIRECT(hoja&"!$A:$A"), 0 ), columna, MATCH( "Totales", INDIRECT(hoja&"!$6:$6"), 0 ), valor, INDEX( INDIRECT(hoja&"!$A:$ZZ"), fila, columna ), IF(valor="-", "", valor) ), "") | V7: =U7-T7 -> 0 | W7: {=IFERROR(SUMIF(Consolidado!$C$3:$C$100, $A7, INDEX(Consolidado!$E$3:$P$100, , MATCH(W$1, Consolidado!$E$2:$P$2, 0))), "")} | X7: =IFERROR( LET( hoja, LEFT(X$1,3)&"R", fila, MATCH( RIGHT($A7, LEN($A7)-4), INDIRECT(hoja&"!$A:$A"), 0 ), columna, MATCH( "Totales", INDIRECT(hoja&"!$6:$6"), 0 ), valor, INDEX( INDIRECT(hoja&"!$A:$ZZ"), fila, columna ), IF(valor="-", "", valor) ), "") | Y7: =X7-W7 -> 0 | Z7: {=IFERROR(SUMIF(Consolidado!$C$3:$C$100, $A7, INDEX(Consolidado!$E$3:$P$100, , MATCH(Z$1, Consolidado!$E$2:$P$2, 0))), "")} | AA7: =IFERROR( LET( hoja, LEFT(AA$1,3)&"R", fila, MATCH( RIGHT($A7, LEN($A7)-4), INDIRECT(hoja&"!$A:$A"), 0 ), columna, MATCH( "Totales", INDIRECT(hoja&"!$6:$6"), 0 ), valor, INDEX( INDIRECT(hoja&"!$A:$ZZ"), fila, columna ), IF(valor="-", "", valor) ), "") | AB7: =AA7-Z7 -> 0 | AC7: {=IFERROR(SUMIF(Consolidado!$C$3:$C$100, $A7, INDEX(Consolidado!$E$3:$P$100, , MATCH(AC$1, Consolidado!$E$2:$P$2, 0))), "")} | AD7: =IFERROR( LET( hoja, LEFT(AD$1,3)&"R", fila, MATCH( RIGHT($A7, LEN($A7)-4), INDIRECT(hoja&"!$A:$A"), 0 ), columna, MATCH( "Totales", INDIRECT(hoja&"!$6:$6"), 0 ), valor, INDEX( INDIRECT(hoja&"!$A:$ZZ"), fila, columna ), IF(valor="-", "", valor) ), "") | AE7: =AD7-AC7 -> 0 | AF7: {=IFERROR(SUMIF(Consolidado!$C$3:$C$100, $A7, INDEX(Consolidado!$E$3:$P$100, , MATCH(AF$1, Consolidado!$E$2:$P$2, 0))), "")} | AG7: =IFERROR( LET( hoja, LEFT(AG$1,3)&"R", fila, MATCH( RIGHT($A7, LEN($A7)-4), INDIRECT(hoja&"!$A:$A"), 0 ), columna, MATCH( "Totales", INDIRECT(hoja&"!$6:$6"), 0 ), valor, INDEX( INDIRECT(hoja&"!$A:$ZZ"), fila, columna ), IF(valor="-", "", valor) ), "") | AH7: =AG7-AF7 -> 0 | AI7: {=IFERROR(SUMIF(Consolidado!$C$3:$C$100, $A7, INDEX(Consolidado!$E$3:$P$100, , MATCH(AI$1, Consolidado!$E$2:$P$2, 0))), "")} | AJ7: =IFERROR( LET( hoja, LEFT(AJ$1,3)&"R", fila, MATCH( RIGHT($A7, LEN($A7)-4), INDIRECT(hoja&"!$A:$A"), 0 ), columna, MATCH( "Totales", INDIRECT(hoja&"!$6:$6"), 0 ), valor, INDEX( INDIRECT(hoja&"!$A:$ZZ"), fila, columna ), IF(valor="-", "", valor) ), "") | AK7: =AJ7-AI7 -> 0 | AL7: {=IFERROR(SUMIF(Consolidado!$C$3:$C$100, $A7, INDEX(Consolidado!$E$3:$P$100, , MATCH(AL$1, Consolidado!$E$2:$P$2, 0))), "")} | AM7: =IFERROR( LET( hoja, LEFT(AM$1,3)&"R", fila, MATCH( RIGHT($A7, LEN($A7)-4), INDIRECT(hoja&"!$A:$A"), 0 ), columna, MATCH( "Totales", INDIRECT(hoja&"!$6:$6"), 0 ), valor, INDEX( INDIRECT(hoja&"!$A:$ZZ"), fila, columna ), IF(valor="-", "", valor) ), "") | AN7: =AM7-AL7 -> 0
B8: =SUM(IF(MONTH(TODAY())>1,E8,0), IF(MONTH(TODAY())>2,H8,0), IF(MONTH(TODAY())>3,K8,0), IF(MONTH(TODAY())>4,N8,0), IF(MONTH(TODAY())>5,Q8,0), IF(MONTH(TODAY())>6,T8,0), IF(MONTH(TODAY())>7,W8,0), IF(MONTH(TODAY())>8,Z8,0), IF(MONTH(TODAY())>9,AC8,0), IF(MONTH(TODAY())>10,AF8,0), IF(MONTH(TODAY())>11,AI8,0), IF(MONTH(TODAY())>12,AL8,0)) -> 0 | C8: =SUM(IF(MONTH(TODAY())>1,F8,0), IF(MONTH(TODAY())>2,I8,0), IF(MONTH(TODAY())>3,L8,0), IF(MONTH(TODAY())>4,O8,0), IF(MONTH(TODAY())>5,R8,0), IF(MONTH(TODAY())>6,U8,0), IF(MONTH(TODAY())>7,X8,0), IF(MONTH(TODAY())>8,AA8,0), IF(MONTH(TODAY())>9,AD8,0), IF(MONTH(TODAY())>10,AG8,0), IF(MONTH(TODAY())>11,AJ8,0), IF(MONTH(TODAY())>12,AM8,0)) -> 0 | D8: =C8-B8 -> 0 | E8: {=IFERROR(SUMIF(Consolidado!$C$3:$C$100, $A8, INDEX(Consolidado!$E$3:$P$100, , MATCH(E$1, Consolidado!$E$2:$P$2, 0))), "")} | F8: =IFERROR( LET( hoja, LEFT(F$1,3)&"R", fila, MATCH( RIGHT($A8, LEN($A8)-4), INDIRECT(hoja&"!$A:$A"), 0 ), columna, MATCH( "Totales", INDIRECT(hoja&"!$6:$6"), 0 ), valor, INDEX( INDIRECT(hoja&"!$A:$ZZ"), fila, columna ), IF(valor="-", "", valor) ), "") | G8: =F8-E8 -> 0 | H8: {=IFERROR(SUMIF(Consolidado!$C$3:$C$100, $A8, INDEX(Consolidado!$E$3:$P$100, , MATCH(H$1, Consolidado!$E$2:$P$2, 0))), "")} | I8: =IFERROR( LET( hoja, LEFT(I$1,3)&"R", fila, MATCH( RIGHT($A8, LEN($A8)-4), INDIRECT(hoja&"!$A:$A"), 0 ), columna, MATCH( "Totales", INDIRECT(hoja&"!$6:$6"), 0 ), valor, INDEX( INDIRECT(hoja&"!$A:$ZZ"), fila, columna ), IF(valor="-", "", valor) ), "") | J8: =I8-H8 -> 0 | K8: {=IFERROR(SUMIF(Consolidado!$C$3:$C$100, $A8, INDEX(Consolidado!$E$3:$P$100, , MATCH(K$1, Consolidado!$E$2:$P$2, 0))), "")} | L8: =IFERROR( LET( hoja, LEFT(L$1,3)&"R", fila, MATCH( RIGHT($A8, LEN($A8)-4), INDIRECT(hoja&"!$A:$A"), 0 ), columna, MATCH( "Totales", INDIRECT(hoja&"!$6:$6"), 0 ), valor, INDEX( INDIRECT(hoja&"!$A:$ZZ"), fila, columna ), IF(valor="-", "", valor) ), "") | M8: =L8-K8 -> 0 | N8: {=IFERROR(SUMIF(Consolidado!$C$3:$C$100, $A8, INDEX(Consolidado!$E$3:$P$100, , MATCH(N$1, Consolidado!$E$2:$P$2, 0))), "")} | O8: =IFERROR( LET( hoja, LEFT(O$1,3)&"R", fila, MATCH( RIGHT($A8, LEN($A8)-4), INDIRECT(hoja&"!$A:$A"), 0 ), columna, MATCH( "Totales", INDIRECT(hoja&"!$6:$6"), 0 ), valor, INDEX( INDIRECT(hoja&"!$A:$ZZ"), fila, columna ), IF(valor="-", "", valor) ), "") | P8: =O8-N8 -> 0 | Q8: {=IFERROR(SUMIF(Consolidado!$C$3:$C$100, $A8, INDEX(Consolidado!$E$3:$P$100, , MATCH(Q$1, Consolidado!$E$2:$P$2, 0))), "")} | R8: =IFERROR( LET( hoja, LEFT(R$1,3)&"R", fila, MATCH( RIGHT($A8, LEN($A8)-4), INDIRECT(hoja&"!$A:$A"), 0 ), columna, MATCH( "Totales", INDIRECT(hoja&"!$6:$6"), 0 ), valor, INDEX( INDIRECT(hoja&"!$A:$ZZ"), fila, columna ), IF(valor="-", "", valor) ), "") | S8: =R8-Q8 -> 0 | T8: {=IFERROR(SUMIF(Consolidado!$C$3:$C$100, $A8, INDEX(Consolidado!$E$3:$P$100, , MATCH(T$1, Consolidado!$E$2:$P$2, 0))), "")} | U8: =IFERROR( LET( hoja, LEFT(U$1,3)&"R", fila, MATCH( RIGHT($A8, LEN($A8)-4), INDIRECT(hoja&"!$A:$A"), 0 ), columna, MATCH( "Totales", INDIRECT(hoja&"!$6:$6"), 0 ), valor, INDEX( INDIRECT(hoja&"!$A:$ZZ"), fila, columna ), IF(valor="-", "", valor) ), "") | V8: =U8-T8 -> 0 | W8: {=IFERROR(SUMIF(Consolidado!$C$3:$C$100, $A8, INDEX(Consolidado!$E$3:$P$100, , MATCH(W$1, Consolidado!$E$2:$P$2, 0))), "")} | X8: =IFERROR( LET( hoja, LEFT(X$1,3)&"R", fila, MATCH( RIGHT($A8, LEN($A8)-4), INDIRECT(hoja&"!$A:$A"), 0 ), columna, MATCH( "Totales", INDIRECT(hoja&"!$6:$6"), 0 ), valor, INDEX( INDIRECT(hoja&"!$A:$ZZ"), fila, columna ), IF(valor="-", "", valor) ), "") | Y8: =X8-W8 -> 0 | Z8: {=IFERROR(SUMIF(Consolidado!$C$3:$C$100, $A8, INDEX(Consolidado!$E$3:$P$100, , MATCH(Z$1, Consolidado!$E$2:$P$2, 0))), "")} | AA8: =IFERROR( LET( hoja, LEFT(AA$1,3)&"R", fila, MATCH( RIGHT($A8, LEN($A8)-4), INDIRECT(hoja&"!$A:$A"), 0 ), columna, MATCH( "Totales", INDIRECT(hoja&"!$6:$6"), 0 ), valor, INDEX( INDIRECT(hoja&"!$A:$ZZ"), fila, columna ), IF(valor="-", "", valor) ), "") | AB8: =AA8-Z8 -> 0 | AC8: {=IFERROR(SUMIF(Consolidado!$C$3:$C$100, $A8, INDEX(Consolidado!$E$3:$P$100, , MATCH(AC$1, Consolidado!$E$2:$P$2, 0))), "")} | AD8: =IFERROR( LET( hoja, LEFT(AD$1,3)&"R", fila, MATCH( RIGHT($A8, LEN($A8)-4), INDIRECT(hoja&"!$A:$A"), 0 ), columna, MATCH( "Totales", INDIRECT(hoja&"!$6:$6"), 0 ), valor, INDEX( INDIRECT(hoja&"!$A:$ZZ"), fila, columna ), IF(valor="-", "", valor) ), "") | AE8: =AD8-AC8 -> 0 | AF8: {=IFERROR(SUMIF(Consolidado!$C$3:$C$100, $A8, INDEX(Consolidado!$E$3:$P$100, , MATCH(AF$1, Consolidado!$E$2:$P$2, 0))), "")} | AG8: =IFERROR( LET( hoja, LEFT(AG$1,3)&"R", fila, MATCH( RIGHT($A8, LEN($A8)-4), INDIRECT(hoja&"!$A:$A"), 0 ), columna, MATCH( "Totales", INDIRECT(hoja&"!$6:$6"), 0 ), valor, INDEX( INDIRECT(hoja&"!$A:$ZZ"), fila, columna ), IF(valor="-", "", valor) ), "") | AH8: =AG8-AF8 -> 0 | AI8: {=IFERROR(SUMIF(Consolidado!$C$3:$C$100, $A8, INDEX(Consolidado!$E$3:$P$100, , MATCH(AI$1, Consolidado!$E$2:$P$2, 0))), "")} | AJ8: =IFERROR( LET( hoja, LEFT(AJ$1,3)&"R", fila, MATCH( RIGHT($A8, LEN($A8)-4), INDIRECT(hoja&"!$A:$A"), 0 ), columna, MATCH( "Totales", INDIRECT(hoja&"!$6:$6"), 0 ), valor, INDEX( INDIRECT(hoja&"!$A:$ZZ"), fila, columna ), IF(valor="-", "", valor) ), "") | AK8: =AJ8-AI8 -> 0 | AL8: {=IFERROR(SUMIF(Consolidado!$C$3:$C$100, $A8, INDEX(Consolidado!$E$3:$P$100, , MATCH(AL$1, Consolidado!$E$2:$P$2, 0))), "")} | AM8: =IFERROR( LET( hoja, LEFT(AM$1,3)&"R", fila, MATCH( RIGHT($A8, LEN($A8)-4), INDIRECT(hoja&"!$A:$A"), 0 ), columna, MATCH( "Totales", INDIRECT(hoja&"!$6:$6"), 0 ), valor, INDEX( INDIRECT(hoja&"!$A:$ZZ"), fila, columna ), IF(valor="-", "", valor) ), "") | AN8: =AM8-AL8 -> 0
A10: Total de Egresos | B10: =SUM(B11:B47) -> 0 | C10: =SUM(C11:C47) -> 0 | D10: =C10-B10 -> 0 | E10: =SUM(E11:E47) -> 0 | F10: =SUM(F11:F47) -> 0 | G10: =F10-E10 -> 0 | H10: =SUM(H11:H47) -> 0 | I10: =SUM(I11:I47) -> 0 | J10: =SUM(J11:J47) -> 0 | K10: =SUM(K11:K47) -> 0 | L10: =SUM(L11:L47) -> 0 | M10: =SUM(M11:M47) -> 0 | N10: =SUM(N11:N47) -> 0 | O10: =SUM(O11:O47) -> 0 | ... AN10: =SUM(AN11:AN47) -> 0
A11: =Menus!B4 -> B01 Nomina | B11: =SUM(IF(MONTH(TODAY())>1,E11,0), IF(MONTH(TODAY())>2,H11,0), IF(MONTH(TODAY())>3,K11,0), IF(MONTH(TODAY())>4,N11,0), IF(MONTH(TODAY())>5,Q11,0), IF(MONTH(TODAY())>6,T11,0), IF(MONTH(TODAY())>7,W11,0), IF(MONTH(TODAY())>8,Z11,0), IF(MONTH(TODAY())>9,AC11,0), IF(MONTH(TODAY())>10,AF11,0), IF(MONTH(TODAY())>11,AI11,0), IF(MONTH(TODAY())>12,AL11,0)) -> 0 | C11: =SUM(IF(MONTH(TODAY())>1,F11,0), IF(MONTH(TODAY())>2,I11,0), IF(MONTH(TODAY())>3,L11,0), IF(MONTH(TODAY())>4,O11,0), IF(MONTH(TODAY())>5,R11,0), IF(MONTH(TODAY())>6,U11,0), IF(MONTH(TODAY())>7,X11,0), IF(MONTH(TODAY())>8,AA11,0), IF(MONTH(TODAY())>9,AD11,0), IF(MONTH(TODAY())>10,AG11,0), IF(MONTH(TODAY())>11,AJ11,0), IF(MONTH(TODAY())>12,AM11,0)) -> 0 | D11: =B11-C11 -> 0 | E11: {=IFERROR(SUMIF(Consolidado!$C$3:$C63, $A11, INDEX(Consolidado!$E$3:$P$100, , MATCH(E$1, Consolidado!$E$2:$P$2, 0))), "")} | F11: =IFERROR( LET( hoja, LEFT(F$1,3)&"R", fila, MATCH( RIGHT($A11, LEN($A11)-4), INDIRECT(hoja&"!$A:$A"), 0 ), columna, MATCH( "Totales", INDIRECT(hoja&"!$6:$6"), 0 ), valor, INDEX( INDIRECT(hoja&"!$A:$ZZ"), fila, columna ), IF(valor="-", "", valor) ), "") | G11: =E11-F11 -> 0 | H11: {=IFERROR(SUMIF(Consolidado!$C$3:$C63, $A11, INDEX(Consolidado!$E$3:$P$100, , MATCH(H$1, Consolidado!$E$2:$P$2, 0))), "")} | I11: =IFERROR( LET( hoja, LEFT(I$1,3)&"R", fila, MATCH( RIGHT($A11, LEN($A11)-4), INDIRECT(hoja&"!$A:$A"), 0 ), columna, MATCH( "Totales", INDIRECT(hoja&"!$6:$6"), 0 ), valor, INDEX( INDIRECT(hoja&"!$A:$ZZ"), fila, columna ), IF(valor="-", "", valor) ), "") | J11: =H11-I11 -> 0 | K11: {=IFERROR(SUMIF(Consolidado!$C$3:$C63, $A11, INDEX(Consolidado!$E$3:$P$100, , MATCH(K$1, Consolidado!$E$2:$P$2, 0))), "")} | L11: =IFERROR( LET( hoja, LEFT(L$1,3)&"R", fila, MATCH( RIGHT($A11, LEN($A11)-4), INDIRECT(hoja&"!$A:$A"), 0 ), columna, MATCH( "Totales", INDIRECT(hoja&"!$6:$6"), 0 ), valor, INDEX( INDIRECT(hoja&"!$A:$ZZ"), fila, columna ), IF(valor="-", "", valor) ), "") | M11: =K11-L11 -> 0 | N11: {=IFERROR(SUMIF(Consolidado!$C$3:$C63, $A11, INDEX(Consolidado!$E$3:$P$100, , MATCH(N$1, Consolidado!$E$2:$P$2, 0))), "")} | O11: =IFERROR( LET( hoja, LEFT(O$1,3)&"R", fila, MATCH( RIGHT($A11, LEN($A11)-4), INDIRECT(hoja&"!$A:$A"), 0 ), columna, MATCH( "Totales", INDIRECT(hoja&"!$6:$6"), 0 ), valor, INDEX( INDIRECT(hoja&"!$A:$ZZ"), fila, columna ), IF(valor="-", "", valor) ), "") | P11: =N11-O11 -> 0 | Q11: {=IFERROR(SUMIF(Consolidado!$C$3:$C63, $A11, INDEX(Consolidado!$E$3:$P$100, , MATCH(Q$1, Consolidado!$E$2:$P$2, 0))), "")} | R11: =IFERROR( LET( hoja, LEFT(R$1,3)&"R", fila, MATCH( RIGHT($A11, LEN($A11)-4), INDIRECT(hoja&"!$A:$A"), 0 ), columna, MATCH( "Totales", INDIRECT(hoja&"!$6:$6"), 0 ), valor, INDEX( INDIRECT(hoja&"!$A:$ZZ"), fila, columna ), IF(valor="-", "", valor) ), "") | S11: =Q11-R11 -> 0 | T11: {=IFERROR(SUMIF(Consolidado!$C$3:$C63, $A11, INDEX(Consolidado!$E$3:$P$100, , MATCH(T$1, Consolidado!$E$2:$P$2, 0))), "")} | U11: =IFERROR( LET( hoja, LEFT(U$1,3)&"R", fila, MATCH( RIGHT($A11, LEN($A11)-4), INDIRECT(hoja&"!$A:$A"), 0 ), columna, MATCH( "Totales", INDIRECT(hoja&"!$6:$6"), 0 ), valor, INDEX( INDIRECT(hoja&"!$A:$ZZ"), fila, columna ), IF(valor="-", "", valor) ), "") | V11: =T11-U11 -> 0 | W11: {=IFERROR(SUMIF(Consolidado!$C$3:$C63, $A11, INDEX(Consolidado!$E$3:$P$100, , MATCH(W$1, Consolidado!$E$2:$P$2, 0))), "")} | X11: =IFERROR( LET( hoja, LEFT(X$1,3)&"R", fila, MATCH( RIGHT($A11, LEN($A11)-4), INDIRECT(hoja&"!$A:$A"), 0 ), columna, MATCH( "Totales", INDIRECT(hoja&"!$6:$6"), 0 ), valor, INDEX( INDIRECT(hoja&"!$A:$ZZ"), fila, columna ), IF(valor="-", "", valor) ), "") | Y11: =W11-X11 -> 0 | Z11: {=IFERROR(SUMIF(Consolidado!$C$3:$C63, $A11, INDEX(Consolidado!$E$3:$P$100, , MATCH(Z$1, Consolidado!$E$2:$P$2, 0))), "")} | AA11: =IFERROR( LET( hoja, LEFT(AA$1,3)&"R", fila, MATCH( RIGHT($A11, LEN($A11)-4), INDIRECT(hoja&"!$A:$A"), 0 ), columna, MATCH( "Totales", INDIRECT(hoja&"!$6:$6"), 0 ), valor, INDEX( INDIRECT(hoja&"!$A:$ZZ"), fila, columna ), IF(valor="-", "", valor) ), "") | AB11: =Z11-AA11 -> 0 | AC11: {=IFERROR(SUMIF(Consolidado!$C$3:$C63, $A11, INDEX(Consolidado!$E$3:$P$100, , MATCH(AC$1, Consolidado!$E$2:$P$2, 0))), "")} | AD11: =IFERROR( LET( hoja, LEFT(AD$1,3)&"R", fila, MATCH( RIGHT($A11, LEN($A11)-4), INDIRECT(hoja&"!$A:$A"), 0 ), columna, MATCH( "Totales", INDIRECT(hoja&"!$6:$6"), 0 ), valor, INDEX( INDIRECT(hoja&"!$A:$ZZ"), fila, columna ), IF(valor="-", "", valor) ), "") | AE11: =AC11-AD11 -> 0 | AF11: {=IFERROR(SUMIF(Consolidado!$C$3:$C63, $A11, INDEX(Consolidado!$E$3:$P$100, , MATCH(AF$1, Consolidado!$E$2:$P$2, 0))), "")} | AG11: =IFERROR( LET( hoja, LEFT(AG$1,3)&"R", fila, MATCH( RIGHT($A11, LEN($A11)-4), INDIRECT(hoja&"!$A:$A"), 0 ), columna, MATCH( "Totales", INDIRECT(hoja&"!$6:$6"), 0 ), valor, INDEX( INDIRECT(hoja&"!$A:$ZZ"), fila, columna ), IF(valor="-", "", valor) ), "") | AH11: =AF11-AG11 -> 0 | AI11: {=IFERROR(SUMIF(Consolidado!$C$3:$C63, $A11, INDEX(Consolidado!$E$3:$P$100, , MATCH(AI$1, Consolidado!$E$2:$P$2, 0))), "")} | AJ11: =IFERROR( LET( hoja, LEFT(AJ$1,3)&"R", fila, MATCH( RIGHT($A11, LEN($A11)-4), INDIRECT(hoja&"!$A:$A"), 0 ), columna, MATCH( "Totales", INDIRECT(hoja&"!$6:$6"), 0 ), valor, INDEX( INDIRECT(hoja&"!$A:$ZZ"), fila, columna ), IF(valor="-", "", valor) ), "") | AK11: =AI11-AJ11 -> 0 | AL11: {=IFERROR(SUMIF(Consolidado!$C$3:$C63, $A11, INDEX(Consolidado!$E$3:$P$100, , MATCH(AL$1, Consolidado!$E$2:$P$2, 0))), "")} | AM11: =IFERROR( LET( hoja, LEFT(AM$1,3)&"R", fila, MATCH( RIGHT($A11, LEN($A11)-4), INDIRECT(hoja&"!$A:$A"), 0 ), columna, MATCH( "Totales", INDIRECT(hoja&"!$6:$6"), 0 ), valor, INDEX( INDIRECT(hoja&"!$A:$ZZ"), fila, columna ), IF(valor="-", "", valor) ), "") | AN11: =AL11-AM11 -> 0
A12: =Menus!B5 -> B02 Cuotas IMSS | B12: =SUM(IF(MONTH(TODAY())>1,E12,0), IF(MONTH(TODAY())>2,H12,0), IF(MONTH(TODAY())>3,K12,0), IF(MONTH(TODAY())>4,N12,0), IF(MONTH(TODAY())>5,Q12,0), IF(MONTH(TODAY())>6,T12,0), IF(MONTH(TODAY())>7,W12,0), IF(MONTH(TODAY())>8,Z12,0), IF(MONTH(TODAY())>9,AC12,0), IF(MONTH(TODAY())>10,AF12,0), IF(MONTH(TODAY())>11,AI12,0), IF(MONTH(TODAY())>12,AL12,0)) -> 0 | C12: =SUM(IF(MONTH(TODAY())>1,F12,0), IF(MONTH(TODAY())>2,I12,0), IF(MONTH(TODAY())>3,L12,0), IF(MONTH(TODAY())>4,O12,0), IF(MONTH(TODAY())>5,R12,0), IF(MONTH(TODAY())>6,U12,0), IF(MONTH(TODAY())>7,X12,0), IF(MONTH(TODAY())>8,AA12,0), IF(MONTH(TODAY())>9,AD12,0), IF(MONTH(TODAY())>10,AG12,0), IF(MONTH(TODAY())>11,AJ12,0), IF(MONTH(TODAY())>12,AM12,0)) -> 0 | D12: =B12-C12 -> 0 | E12: {=IFERROR(SUMIF(Consolidado!$C$3:$C63, $A12, INDEX(Consolidado!$E$3:$P$100, , MATCH(E$1, Consolidado!$E$2:$P$2, 0))), "")} | F12: =IFERROR( LET( hoja, LEFT(F$1,3)&"R", fila, MATCH( RIGHT($A12, LEN($A12)-4), INDIRECT(hoja&"!$A:$A"), 0 ), columna, MATCH( "Totales", INDIRECT(hoja&"!$6:$6"), 0 ), valor, INDEX( INDIRECT(hoja&"!$A:$ZZ"), fila, columna ), IF(valor="-", "", valor) ), "") | G12: =E12-F12 -> 0 | H12: {=IFERROR(SUMIF(Consolidado!$C$3:$C63, $A12, INDEX(Consolidado!$E$3:$P$100, , MATCH(H$1, Consolidado!$E$2:$P$2, 0))), "")} | I12: =IFERROR( LET( hoja, LEFT(I$1,3)&"R", fila, MATCH( RIGHT($A12, LEN($A12)-4), INDIRECT(hoja&"!$A:$A"), 0 ), columna, MATCH( "Totales", INDIRECT(hoja&"!$6:$6"), 0 ), valor, INDEX( INDIRECT(hoja&"!$A:$ZZ"), fila, columna ), IF(valor="-", "", valor) ), "") | J12: =H12-I12 -> 0 | K12: {=IFERROR(SUMIF(Consolidado!$C$3:$C63, $A12, INDEX(Consolidado!$E$3:$P$100, , MATCH(K$1, Consolidado!$E$2:$P$2, 0))), "")} | L12: =IFERROR( LET( hoja, LEFT(L$1,3)&"R", fila, MATCH( RIGHT($A12, LEN($A12)-4), INDIRECT(hoja&"!$A:$A"), 0 ), columna, MATCH( "Totales", INDIRECT(hoja&"!$6:$6"), 0 ), valor, INDEX( INDIRECT(hoja&"!$A:$ZZ"), fila, columna ), IF(valor="-", "", valor) ), "") | M12: =K12-L12 -> 0 | N12: {=IFERROR(SUMIF(Consolidado!$C$3:$C63, $A12, INDEX(Consolidado!$E$3:$P$100, , MATCH(N$1, Consolidado!$E$2:$P$2, 0))), "")} | O12: =IFERROR( LET( hoja, LEFT(O$1,3)&"R", fila, MATCH( RIGHT($A12, LEN($A12)-4), INDIRECT(hoja&"!$A:$A"), 0 ), columna, MATCH( "Totales", INDIRECT(hoja&"!$6:$6"), 0 ), valor, INDEX( INDIRECT(hoja&"!$A:$ZZ"), fila, columna ), IF(valor="-", "", valor) ), "") | P12: =N12-O12 -> 0 | Q12: {=IFERROR(SUMIF(Consolidado!$C$3:$C63, $A12, INDEX(Consolidado!$E$3:$P$100, , MATCH(Q$1, Consolidado!$E$2:$P$2, 0))), "")} | R12: =IFERROR( LET( hoja, LEFT(R$1,3)&"R", fila, MATCH( RIGHT($A12, LEN($A12)-4), INDIRECT(hoja&"!$A:$A"), 0 ), columna, MATCH( "Totales", INDIRECT(hoja&"!$6:$6"), 0 ), valor, INDEX( INDIRECT(hoja&"!$A:$ZZ"), fila, columna ), IF(valor="-", "", valor) ), "") | S12: =Q12-R12 -> 0 | T12: {=IFERROR(SUMIF(Consolidado!$C$3:$C63, $A12, INDEX(Consolidado!$E$3:$P$100, , MATCH(T$1, Consolidado!$E$2:$P$2, 0))), "")} | U12: =IFERROR( LET( hoja, LEFT(U$1,3)&"R", fila, MATCH( RIGHT($A12, LEN($A12)-4), INDIRECT(hoja&"!$A:$A"), 0 ), columna, MATCH( "Totales", INDIRECT(hoja&"!$6:$6"), 0 ), valor, INDEX( INDIRECT(hoja&"!$A:$ZZ"), fila, columna ), IF(valor="-", "", valor) ), "") | V12: =T12-U12 -> 0 | W12: {=IFERROR(SUMIF(Consolidado!$C$3:$C63, $A12, INDEX(Consolidado!$E$3:$P$100, , MATCH(W$1, Consolidado!$E$2:$P$2, 0))), "")} | X12: =IFERROR( LET( hoja, LEFT(X$1,3)&"R", fila, MATCH( RIGHT($A12, LEN($A12)-4), INDIRECT(hoja&"!$A:$A"), 0 ), columna, MATCH( "Totales", INDIRECT(hoja&"!$6:$6"), 0 ), valor, INDEX( INDIRECT(hoja&"!$A:$ZZ"), fila, columna ), IF(valor="-", "", valor) ), "") | Y12: =W12-X12 -> 0 | Z12: {=IFERROR(SUMIF(Consolidado!$C$3:$C63, $A12, INDEX(Consolidado!$E$3:$P$100, , MATCH(Z$1, Consolidado!$E$2:$P$2, 0))), "")} | AA12: =IFERROR( LET( hoja, LEFT(AA$1,3)&"R", fila, MATCH( RIGHT($A12, LEN($A12)-4), INDIRECT(hoja&"!$A:$A"), 0 ), columna, MATCH( "Totales", INDIRECT(hoja&"!$6:$6"), 0 ), valor, INDEX( INDIRECT(hoja&"!$A:$ZZ"), fila, columna ), IF(valor="-", "", valor) ), "") | AB12: =Z12-AA12 -> 0 | AC12: {=IFERROR(SUMIF(Consolidado!$C$3:$C63, $A12, INDEX(Consolidado!$E$3:$P$100, , MATCH(AC$1, Consolidado!$E$2:$P$2, 0))), "")} | AD12: =IFERROR( LET( hoja, LEFT(AD$1,3)&"R", fila, MATCH( RIGHT($A12, LEN($A12)-4), INDIRECT(hoja&"!$A:$A"), 0 ), columna, MATCH( "Totales", INDIRECT(hoja&"!$6:$6"), 0 ), valor, INDEX( INDIRECT(hoja&"!$A:$ZZ"), fila, columna ), IF(valor="-", "", valor) ), "") | AE12: =AC12-AD12 -> 0 | AF12: {=IFERROR(SUMIF(Consolidado!$C$3:$C63, $A12, INDEX(Consolidado!$E$3:$P$100, , MATCH(AF$1, Consolidado!$E$2:$P$2, 0))), "")} | AG12: =IFERROR( LET( hoja, LEFT(AG$1,3)&"R", fila, MATCH( RIGHT($A12, LEN($A12)-4), INDIRECT(hoja&"!$A:$A"), 0 ), columna, MATCH( "Totales", INDIRECT(hoja&"!$6:$6"), 0 ), valor, INDEX( INDIRECT(hoja&"!$A:$ZZ"), fila, columna ), IF(valor="-", "", valor) ), "") | AH12: =AF12-AG12 -> 0 | AI12: {=IFERROR(SUMIF(Consolidado!$C$3:$C63, $A12, INDEX(Consolidado!$E$3:$P$100, , MATCH(AI$1, Consolidado!$E$2:$P$2, 0))), "")} | AJ12: =IFERROR( LET( hoja, LEFT(AJ$1,3)&"R", fila, MATCH( RIGHT($A12, LEN($A12)-4), INDIRECT(hoja&"!$A:$A"), 0 ), columna, MATCH( "Totales", INDIRECT(hoja&"!$6:$6"), 0 ), valor, INDEX( INDIRECT(hoja&"!$A:$ZZ"), fila, columna ), IF(valor="-", "", valor) ), "") | AK12: =AI12-AJ12 -> 0 | AL12: {=IFERROR(SUMIF(Consolidado!$C$3:$C63, $A12, INDEX(Consolidado!$E$3:$P$100, , MATCH(AL$1, Consolidado!$E$2:$P$2, 0))), "")} | AM12: =IFERROR( LET( hoja, LEFT(AM$1,3)&"R", fila, MATCH( RIGHT($A12, LEN($A12)-4), INDIRECT(hoja&"!$A:$A"), 0 ), columna, MATCH( "Totales", INDIRECT(hoja&"!$6:$6"), 0 ), valor, INDEX( INDIRECT(hoja&"!$A:$ZZ"), fila, columna ), IF(valor="-", "", valor) ), "") | AN12: =AL12-AM12 -> 0
A13: =Menus!B6 -> B03 Cuotas AFORE | B13: =SUM(IF(MONTH(TODAY())>1,E13,0), IF(MONTH(TODAY())>2,H13,0), IF(MONTH(TODAY())>3,K13,0), IF(MONTH(TODAY())>4,N13,0), IF(MONTH(TODAY())>5,Q13,0), IF(MONTH(TODAY())>6,T13,0), IF(MONTH(TODAY())>7,W13,0), IF(MONTH(TODAY())>8,Z13,0), IF(MONTH(TODAY())>9,AC13,0), IF(MONTH(TODAY())>10,AF13,0), IF(MONTH(TODAY())>11,AI13,0), IF(MONTH(TODAY())>12,AL13,0)) -> 0 | C13: =SUM(IF(MONTH(TODAY())>1,F13,0), IF(MONTH(TODAY())>2,I13,0), IF(MONTH(TODAY())>3,L13,0), IF(MONTH(TODAY())>4,O13,0), IF(MONTH(TODAY())>5,R13,0), IF(MONTH(TODAY())>6,U13,0), IF(MONTH(TODAY())>7,X13,0), IF(MONTH(TODAY())>8,AA13,0), IF(MONTH(TODAY())>9,AD13,0), IF(MONTH(TODAY())>10,AG13,0), IF(MONTH(TODAY())>11,AJ13,0), IF(MONTH(TODAY())>12,AM13,0)) -> 0 | D13: =B13-C13 -> 0 | E13: {=IFERROR(SUMIF(Consolidado!$C$3:$C63, $A13, INDEX(Consolidado!$E$3:$P$100, , MATCH(E$1, Consolidado!$E$2:$P$2, 0))), "")} | F13: =IFERROR( LET( hoja, LEFT(F$1,3)&"R", fila, MATCH( RIGHT($A13, LEN($A13)-4), INDIRECT(hoja&"!$A:$A"), 0 ), columna, MATCH( "Totales", INDIRECT(hoja&"!$6:$6"), 0 ), valor, INDEX( INDIRECT(hoja&"!$A:$ZZ"), fila, columna ), IF(valor="-", "", valor) ), "") | G13: =E13-F13 -> 0 | H13: {=IFERROR(SUMIF(Consolidado!$C$3:$C63, $A13, INDEX(Consolidado!$E$3:$P$100, , MATCH(H$1, Consolidado!$E$2:$P$2, 0))), "")} | I13: =IFERROR( LET( hoja, LEFT(I$1,3)&"R", fila, MATCH( RIGHT($A13, LEN($A13)-4), INDIRECT(hoja&"!$A:$A"), 0 ), columna, MATCH( "Totales", INDIRECT(hoja&"!$6:$6"), 0 ), valor, INDEX( INDIRECT(hoja&"!$A:$ZZ"), fila, columna ), IF(valor="-", "", valor) ), "") | J13: =H13-I13 -> 0 | K13: {=IFERROR(SUMIF(Consolidado!$C$3:$C63, $A13, INDEX(Consolidado!$E$3:$P$100, , MATCH(K$1, Consolidado!$E$2:$P$2, 0))), "")} | L13: =IFERROR( LET( hoja, LEFT(L$1,3)&"R", fila, MATCH( RIGHT($A13, LEN($A13)-4), INDIRECT(hoja&"!$A:$A"), 0 ), columna, MATCH( "Totales", INDIRECT(hoja&"!$6:$6"), 0 ), valor, INDEX( INDIRECT(hoja&"!$A:$ZZ"), fila, columna ), IF(valor="-", "", valor) ), "") | M13: =K13-L13 -> 0 | N13: {=IFERROR(SUMIF(Consolidado!$C$3:$C63, $A13, INDEX(Consolidado!$E$3:$P$100, , MATCH(N$1, Consolidado!$E$2:$P$2, 0))), "")} | O13: =IFERROR( LET( hoja, LEFT(O$1,3)&"R", fila, MATCH( RIGHT($A13, LEN($A13)-4), INDIRECT(hoja&"!$A:$A"), 0 ), columna, MATCH( "Totales", INDIRECT(hoja&"!$6:$6"), 0 ), valor, INDEX( INDIRECT(hoja&"!$A:$ZZ"), fila, columna ), IF(valor="-", "", valor) ), "") | P13: =N13-O13 -> 0 | Q13: {=IFERROR(SUMIF(Consolidado!$C$3:$C63, $A13, INDEX(Consolidado!$E$3:$P$100, , MATCH(Q$1, Consolidado!$E$2:$P$2, 0))), "")} | R13: =IFERROR( LET( hoja, LEFT(R$1,3)&"R", fila, MATCH( RIGHT($A13, LEN($A13)-4), INDIRECT(hoja&"!$A:$A"), 0 ), columna, MATCH( "Totales", INDIRECT(hoja&"!$6:$6"), 0 ), valor, INDEX( INDIRECT(hoja&"!$A:$ZZ"), fila, columna ), IF(valor="-", "", valor) ), "") | S13: =Q13-R13 -> 0 | T13: {=IFERROR(SUMIF(Consolidado!$C$3:$C63, $A13, INDEX(Consolidado!$E$3:$P$100, , MATCH(T$1, Consolidado!$E$2:$P$2, 0))), "")} | U13: =IFERROR( LET( hoja, LEFT(U$1,3)&"R", fila, MATCH( RIGHT($A13, LEN($A13)-4), INDIRECT(hoja&"!$A:$A"), 0 ), columna, MATCH( "Totales", INDIRECT(hoja&"!$6:$6"), 0 ), valor, INDEX( INDIRECT(hoja&"!$A:$ZZ"), fila, columna ), IF(valor="-", "", valor) ), "") | V13: =T13-U13 -> 0 | W13: {=IFERROR(SUMIF(Consolidado!$C$3:$C63, $A13, INDEX(Consolidado!$E$3:$P$100, , MATCH(W$1, Consolidado!$E$2:$P$2, 0))), "")} | X13: =IFERROR( LET( hoja, LEFT(X$1,3)&"R", fila, MATCH( RIGHT($A13, LEN($A13)-4), INDIRECT(hoja&"!$A:$A"), 0 ), columna, MATCH( "Totales", INDIRECT(hoja&"!$6:$6"), 0 ), valor, INDEX( INDIRECT(hoja&"!$A:$ZZ"), fila, columna ), IF(valor="-", "", valor) ), "") | Y13: =W13-X13 -> 0 | Z13: {=IFERROR(SUMIF(Consolidado!$C$3:$C63, $A13, INDEX(Consolidado!$E$3:$P$100, , MATCH(Z$1, Consolidado!$E$2:$P$2, 0))), "")} | AA13: =IFERROR( LET( hoja, LEFT(AA$1,3)&"R", fila, MATCH( RIGHT($A13, LEN($A13)-4), INDIRECT(hoja&"!$A:$A"), 0 ), columna, MATCH( "Totales", INDIRECT(hoja&"!$6:$6"), 0 ), valor, INDEX( INDIRECT(hoja&"!$A:$ZZ"), fila, columna ), IF(valor="-", "", valor) ), "") | AB13: =Z13-AA13 -> 0 | AC13: {=IFERROR(SUMIF(Consolidado!$C$3:$C63, $A13, INDEX(Consolidado!$E$3:$P$100, , MATCH(AC$1, Consolidado!$E$2:$P$2, 0))), "")} | AD13: =IFERROR( LET( hoja, LEFT(AD$1,3)&"R", fila, MATCH( RIGHT($A13, LEN($A13)-4), INDIRECT(hoja&"!$A:$A"), 0 ), columna, MATCH( "Totales", INDIRECT(hoja&"!$6:$6"), 0 ), valor, INDEX( INDIRECT(hoja&"!$A:$ZZ"), fila, columna ), IF(valor="-", "", valor) ), "") | AE13: =AC13-AD13 -> 0 | AF13: {=IFERROR(SUMIF(Consolidado!$C$3:$C63, $A13, INDEX(Consolidado!$E$3:$P$100, , MATCH(AF$1, Consolidado!$E$2:$P$2, 0))), "")} | AG13: =IFERROR( LET( hoja, LEFT(AG$1,3)&"R", fila, MATCH( RIGHT($A13, LEN($A13)-4), INDIRECT(hoja&"!$A:$A"), 0 ), columna, MATCH( "Totales", INDIRECT(hoja&"!$6:$6"), 0 ), valor, INDEX( INDIRECT(hoja&"!$A:$ZZ"), fila, columna ), IF(valor="-", "", valor) ), "") | AH13: =AF13-AG13 -> 0 | AI13: {=IFERROR(SUMIF(Consolidado!$C$3:$C63, $A13, INDEX(Consolidado!$E$3:$P$100, , MATCH(AI$1, Consolidado!$E$2:$P$2, 0))), "")} | AJ13: =IFERROR( LET( hoja, LEFT(AJ$1,3)&"R", fila, MATCH( RIGHT($A13, LEN($A13)-4), INDIRECT(hoja&"!$A:$A"), 0 ), columna, MATCH( "Totales", INDIRECT(hoja&"!$6:$6"), 0 ), valor, INDEX( INDIRECT(hoja&"!$A:$ZZ"), fila, columna ), IF(valor="-", "", valor) ), "") | AK13: =AI13-AJ13 -> 0 | AL13: {=IFERROR(SUMIF(Consolidado!$C$3:$C63, $A13, INDEX(Consolidado!$E$3:$P$100, , MATCH(AL$1, Consolidado!$E$2:$P$2, 0))), "")} | AM13: =IFERROR( LET( hoja, LEFT(AM$1,3)&"R", fila, MATCH( RIGHT($A13, LEN($A13)-4), INDIRECT(hoja&"!$A:$A"), 0 ), columna, MATCH( "Totales", INDIRECT(hoja&"!$6:$6"), 0 ), valor, INDEX( INDIRECT(hoja&"!$A:$ZZ"), fila, columna ), IF(valor="-", "", valor) ), "") | AN13: =AL13-AM13 -> 0
A14: =Menus!B7 -> B04 Cuotas INFONAVIT | B14: =SUM(IF(MONTH(TODAY())>1,E14,0), IF(MONTH(TODAY())>2,H14,0), IF(MONTH(TODAY())>3,K14,0), IF(MONTH(TODAY())>4,N14,0), IF(MONTH(TODAY())>5,Q14,0), IF(MONTH(TODAY())>6,T14,0), IF(MONTH(TODAY())>7,W14,0), IF(MONTH(TODAY())>8,Z14,0), IF(MONTH(TODAY())>9,AC14,0), IF(MONTH(TODAY())>10,AF14,0), IF(MONTH(TODAY())>11,AI14,0), IF(MONTH(TODAY())>12,AL14,0)) -> 0 | C14: =SUM(IF(MONTH(TODAY())>1,F14,0), IF(MONTH(TODAY())>2,I14,0), IF(MONTH(TODAY())>3,L14,0), IF(MONTH(TODAY())>4,O14,0), IF(MONTH(TODAY())>5,R14,0), IF(MONTH(TODAY())>6,U14,0), IF(MONTH(TODAY())>7,X14,0), IF(MONTH(TODAY())>8,AA14,0), IF(MONTH(TODAY())>9,AD14,0), IF(MONTH(TODAY())>10,AG14,0), IF(MONTH(TODAY())>11,AJ14,0), IF(MONTH(TODAY())>12,AM14,0)) -> 0 | D14: =B14-C14 -> 0 | E14: {=IFERROR(SUMIF(Consolidado!$C$3:$C63, $A14, INDEX(Consolidado!$E$3:$P$100, , MATCH(E$1, Consolidado!$E$2:$P$2, 0))), "")} | F14: =IFERROR( LET( hoja, LEFT(F$1,3)&"R", fila, MATCH( RIGHT($A14, LEN($A14)-4), INDIRECT(hoja&"!$A:$A"), 0 ), columna, MATCH( "Totales", INDIRECT(hoja&"!$6:$6"), 0 ), valor, INDEX( INDIRECT(hoja&"!$A:$ZZ"), fila, columna ), IF(valor="-", "", valor) ), "") | G14: =E14-F14 -> 0 | H14: {=IFERROR(SUMIF(Consolidado!$C$3:$C63, $A14, INDEX(Consolidado!$E$3:$P$100, , MATCH(H$1, Consolidado!$E$2:$P$2, 0))), "")} | I14: =IFERROR( LET( hoja, LEFT(I$1,3)&"R", fila, MATCH( RIGHT($A14, LEN($A14)-4), INDIRECT(hoja&"!$A:$A"), 0 ), columna, MATCH( "Totales", INDIRECT(hoja&"!$6:$6"), 0 ), valor, INDEX( INDIRECT(hoja&"!$A:$ZZ"), fila, columna ), IF(valor="-", "", valor) ), "") | J14: =H14-I14 -> 0 | K14: {=IFERROR(SUMIF(Consolidado!$C$3:$C63, $A14, INDEX(Consolidado!$E$3:$P$100, , MATCH(K$1, Consolidado!$E$2:$P$2, 0))), "")} | L14: =IFERROR( LET( hoja, LEFT(L$1,3)&"R", fila, MATCH( RIGHT($A14, LEN($A14)-4), INDIRECT(hoja&"!$A:$A"), 0 ), columna, MATCH( "Totales", INDIRECT(hoja&"!$6:$6"), 0 ), valor, INDEX( INDIRECT(hoja&"!$A:$ZZ"), fila, columna ), IF(valor="-", "", valor) ), "") | M14: =K14-L14 -> 0 | N14: {=IFERROR(SUMIF(Consolidado!$C$3:$C63, $A14, INDEX(Consolidado!$E$3:$P$100, , MATCH(N$1, Consolidado!$E$2:$P$2, 0))), "")} | O14: =IFERROR( LET( hoja, LEFT(O$1,3)&"R", fila, MATCH( RIGHT($A14, LEN($A14)-4), INDIRECT(hoja&"!$A:$A"), 0 ), columna, MATCH( "Totales", INDIRECT(hoja&"!$6:$6"), 0 ), valor, INDEX( INDIRECT(hoja&"!$A:$ZZ"), fila, columna ), IF(valor="-", "", valor) ), "") | P14: =N14-O14 -> 0 | Q14: {=IFERROR(SUMIF(Consolidado!$C$3:$C63, $A14, INDEX(Consolidado!$E$3:$P$100, , MATCH(Q$1, Consolidado!$E$2:$P$2, 0))), "")} | R14: =IFERROR( LET( hoja, LEFT(R$1,3)&"R", fila, MATCH( RIGHT($A14, LEN($A14)-4), INDIRECT(hoja&"!$A:$A"), 0 ), columna, MATCH( "Totales", INDIRECT(hoja&"!$6:$6"), 0 ), valor, INDEX( INDIRECT(hoja&"!$A:$ZZ"), fila, columna ), IF(valor="-", "", valor) ), "") | S14: =Q14-R14 -> 0 | T14: {=IFERROR(SUMIF(Consolidado!$C$3:$C63, $A14, INDEX(Consolidado!$E$3:$P$100, , MATCH(T$1, Consolidado!$E$2:$P$2, 0))), "")} | U14: =IFERROR( LET( hoja, LEFT(U$1,3)&"R", fila, MATCH( RIGHT($A14, LEN($A14)-4), INDIRECT(hoja&"!$A:$A"), 0 ), columna, MATCH( "Totales", INDIRECT(hoja&"!$6:$6"), 0 ), valor, INDEX( INDIRECT(hoja&"!$A:$ZZ"), fila, columna ), IF(valor="-", "", valor) ), "") | V14: =T14-U14 -> 0 | W14: {=IFERROR(SUMIF(Consolidado!$C$3:$C63, $A14, INDEX(Consolidado!$E$3:$P$100, , MATCH(W$1, Consolidado!$E$2:$P$2, 0))), "")} | X14: =IFERROR( LET( hoja, LEFT(X$1,3)&"R", fila, MATCH( RIGHT($A14, LEN($A14)-4), INDIRECT(hoja&"!$A:$A"), 0 ), columna, MATCH( "Totales", INDIRECT(hoja&"!$6:$6"), 0 ), valor, INDEX( INDIRECT(hoja&"!$A:$ZZ"), fila, columna ), IF(valor="-", "", valor) ), "") | Y14: =W14-X14 -> 0 | Z14: {=IFERROR(SUMIF(Consolidado!$C$3:$C63, $A14, INDEX(Consolidado!$E$3:$P$100, , MATCH(Z$1, Consolidado!$E$2:$P$2, 0))), "")} | AA14: =IFERROR( LET( hoja, LEFT(AA$1,3)&"R", fila, MATCH( RIGHT($A14, LEN($A14)-4), INDIRECT(hoja&"!$A:$A"), 0 ), columna, MATCH( "Totales", INDIRECT(hoja&"!$6:$6"), 0 ), valor, INDEX( INDIRECT(hoja&"!$A:$ZZ"), fila, columna ), IF(valor="-", "", valor) ), "") | AB14: =Z14-AA14 -> 0 | AC14: {=IFERROR(SUMIF(Consolidado!$C$3:$C63, $A14, INDEX(Consolidado!$E$3:$P$100, , MATCH(AC$1, Consolidado!$E$2:$P$2, 0))), "")} | AD14: =IFERROR( LET( hoja, LEFT(AD$1,3)&"R", fila, MATCH( RIGHT($A14, LEN($A14)-4), INDIRECT(hoja&"!$A:$A"), 0 ), columna, MATCH( "Totales", INDIRECT(hoja&"!$6:$6"), 0 ), valor, INDEX( INDIRECT(hoja&"!$A:$ZZ"), fila, columna ), IF(valor="-", "", valor) ), "") | AE14: =AC14-AD14 -> 0 | AF14: {=IFERROR(SUMIF(Consolidado!$C$3:$C63, $A14, INDEX(Consolidado!$E$3:$P$100, , MATCH(AF$1, Consolidado!$E$2:$P$2, 0))), "")} | AG14: =IFERROR( LET( hoja, LEFT(AG$1,3)&"R", fila, MATCH( RIGHT($A14, LEN($A14)-4), INDIRECT(hoja&"!$A:$A"), 0 ), columna, MATCH( "Totales", INDIRECT(hoja&"!$6:$6"), 0 ), valor, INDEX( INDIRECT(hoja&"!$A:$ZZ"), fila, columna ), IF(valor="-", "", valor) ), "") | AH14: =AF14-AG14 -> 0 | AI14: {=IFERROR(SUMIF(Consolidado!$C$3:$C63, $A14, INDEX(Consolidado!$E$3:$P$100, , MATCH(AI$1, Consolidado!$E$2:$P$2, 0))), "")} | AJ14: =IFERROR( LET( hoja, LEFT(AJ$1,3)&"R", fila, MATCH( RIGHT($A14, LEN($A14)-4), INDIRECT(hoja&"!$A:$A"), 0 ), columna, MATCH( "Totales", INDIRECT(hoja&"!$6:$6"), 0 ), valor, INDEX( INDIRECT(hoja&"!$A:$ZZ"), fila, columna ), IF(valor="-", "", valor) ), "") | AK14: =AI14-AJ14 -> 0 | AL14: {=IFERROR(SUMIF(Consolidado!$C$3:$C63, $A14, INDEX(Consolidado!$E$3:$P$100, , MATCH(AL$1, Consolidado!$E$2:$P$2, 0))), "")} | AM14: =IFERROR( LET( hoja, LEFT(AM$1,3)&"R", fila, MATCH( RIGHT($A14, LEN($A14)-4), INDIRECT(hoja&"!$A:$A"), 0 ), columna, MATCH( "Totales", INDIRECT(hoja&"!$6:$6"), 0 ), valor, INDEX( INDIRECT(hoja&"!$A:$ZZ"), fila, columna ), IF(valor="-", "", valor) ), "") | AN14: =AL14-AM14 -> 0
A15: =Menus!B8 -> B05 2.5% sobre nomina | B15: =SUM(IF(MONTH(TODAY())>1,E15,0), IF(MONTH(TODAY())>2,H15,0), IF(MONTH(TODAY())>3,K15,0), IF(MONTH(TODAY())>4,N15,0), IF(MONTH(TODAY())>5,Q15,0), IF(MONTH(TODAY())>6,T15,0), IF(MONTH(TODAY())>7,W15,0), IF(MONTH(TODAY())>8,Z15,0), IF(MONTH(TODAY())>9,AC15,0), IF(MONTH(TODAY())>10,AF15,0), IF(MONTH(TODAY())>11,AI15,0), IF(MONTH(TODAY())>12,AL15,0)) -> 0 | C15: =SUM(IF(MONTH(TODAY())>1,F15,0), IF(MONTH(TODAY())>2,I15,0), IF(MONTH(TODAY())>3,L15,0), IF(MONTH(TODAY())>4,O15,0), IF(MONTH(TODAY())>5,R15,0), IF(MONTH(TODAY())>6,U15,0), IF(MONTH(TODAY())>7,X15,0), IF(MONTH(TODAY())>8,AA15,0), IF(MONTH(TODAY())>9,AD15,0), IF(MONTH(TODAY())>10,AG15,0), IF(MONTH(TODAY())>11,AJ15,0), IF(MONTH(TODAY())>12,AM15,0)) -> 0 | D15: =B15-C15 -> 0 | E15: {=IFERROR(SUMIF(Consolidado!$C$3:$C63, $A15, INDEX(Consolidado!$E$3:$P$100, , MATCH(E$1, Consolidado!$E$2:$P$2, 0))), "")} | F15: =IFERROR( LET( hoja, LEFT(F$1,3)&"R", fila, MATCH( RIGHT($A15, LEN($A15)-4), INDIRECT(hoja&"!$A:$A"), 0 ), columna, MATCH( "Totales", INDIRECT(hoja&"!$6:$6"), 0 ), valor, INDEX( INDIRECT(hoja&"!$A:$ZZ"), fila, columna ), IF(valor="-", "", valor) ), "") | G15: =E15-F15 -> 0 | H15: {=IFERROR(SUMIF(Consolidado!$C$3:$C63, $A15, INDEX(Consolidado!$E$3:$P$100, , MATCH(H$1, Consolidado!$E$2:$P$2, 0))), "")} | I15: =IFERROR( LET( hoja, LEFT(I$1,3)&"R", fila, MATCH( RIGHT($A15, LEN($A15)-4), INDIRECT(hoja&"!$A:$A"), 0 ), columna, MATCH( "Totales", INDIRECT(hoja&"!$6:$6"), 0 ), valor, INDEX( INDIRECT(hoja&"!$A:$ZZ"), fila, columna ), IF(valor="-", "", valor) ), "") | J15: =H15-I15 -> 0 | K15: {=IFERROR(SUMIF(Consolidado!$C$3:$C63, $A15, INDEX(Consolidado!$E$3:$P$100, , MATCH(K$1, Consolidado!$E$2:$P$2, 0))), "")} | L15: =IFERROR( LET( hoja, LEFT(L$1,3)&"R", fila, MATCH( RIGHT($A15, LEN($A15)-4), INDIRECT(hoja&"!$A:$A"), 0 ), columna, MATCH( "Totales", INDIRECT(hoja&"!$6:$6"), 0 ), valor, INDEX( INDIRECT(hoja&"!$A:$ZZ"), fila, columna ), IF(valor="-", "", valor) ), "") | M15: =K15-L15 -> 0 | N15: {=IFERROR(SUMIF(Consolidado!$C$3:$C63, $A15, INDEX(Consolidado!$E$3:$P$100, , MATCH(N$1, Consolidado!$E$2:$P$2, 0))), "")} | O15: =IFERROR( LET( hoja, LEFT(O$1,3)&"R", fila, MATCH( RIGHT($A15, LEN($A15)-4), INDIRECT(hoja&"!$A:$A"), 0 ), columna, MATCH( "Totales", INDIRECT(hoja&"!$6:$6"), 0 ), valor, INDEX( INDIRECT(hoja&"!$A:$ZZ"), fila, columna ), IF(valor="-", "", valor) ), "") | P15: =N15-O15 -> 0 | Q15: {=IFERROR(SUMIF(Consolidado!$C$3:$C63, $A15, INDEX(Consolidado!$E$3:$P$100, , MATCH(Q$1, Consolidado!$E$2:$P$2, 0))), "")} | R15: =IFERROR( LET( hoja, LEFT(R$1,3)&"R", fila, MATCH( RIGHT($A15, LEN($A15)-4), INDIRECT(hoja&"!$A:$A"), 0 ), columna, MATCH( "Totales", INDIRECT(hoja&"!$6:$6"), 0 ), valor, INDEX( INDIRECT(hoja&"!$A:$ZZ"), fila, columna ), IF(valor="-", "", valor) ), "") | S15: =Q15-R15 -> 0 | T15: {=IFERROR(SUMIF(Consolidado!$C$3:$C63, $A15, INDEX(Consolidado!$E$3:$P$100, , MATCH(T$1, Consolidado!$E$2:$P$2, 0))), "")} | U15: =IFERROR( LET( hoja, LEFT(U$1,3)&"R", fila, MATCH( RIGHT($A15, LEN($A15)-4), INDIRECT(hoja&"!$A:$A"), 0 ), columna, MATCH( "Totales", INDIRECT(hoja&"!$6:$6"), 0 ), valor, INDEX( INDIRECT(hoja&"!$A:$ZZ"), fila, columna ), IF(valor="-", "", valor) ), "") | V15: =T15-U15 -> 0 | W15: {=IFERROR(SUMIF(Consolidado!$C$3:$C63, $A15, INDEX(Consolidado!$E$3:$P$100, , MATCH(W$1, Consolidado!$E$2:$P$2, 0))), "")} | X15: =IFERROR( LET( hoja, LEFT(X$1,3)&"R", fila, MATCH( RIGHT($A15, LEN($A15)-4), INDIRECT(hoja&"!$A:$A"), 0 ), columna, MATCH( "Totales", INDIRECT(hoja&"!$6:$6"), 0 ), valor, INDEX( INDIRECT(hoja&"!$A:$ZZ"), fila, columna ), IF(valor="-", "", valor) ), "") | Y15: =W15-X15 -> 0 | Z15: {=IFERROR(SUMIF(Consolidado!$C$3:$C63, $A15, INDEX(Consolidado!$E$3:$P$100, , MATCH(Z$1, Consolidado!$E$2:$P$2, 0))), "")} | AA15: =IFERROR( LET( hoja, LEFT(AA$1,3)&"R", fila, MATCH( RIGHT($A15, LEN($A15)-4), INDIRECT(hoja&"!$A:$A"), 0 ), columna, MATCH( "Totales", INDIRECT(hoja&"!$6:$6"), 0 ), valor, INDEX( INDIRECT(hoja&"!$A:$ZZ"), fila, columna ), IF(valor="-", "", valor) ), "") | AB15: =Z15-AA15 -> 0 | AC15: {=IFERROR(SUMIF(Consolidado!$C$3:$C63, $A15, INDEX(Consolidado!$E$3:$P$100, , MATCH(AC$1, Consolidado!$E$2:$P$2, 0))), "")} | AD15: =IFERROR( LET( hoja, LEFT(AD$1,3)&"R", fila, MATCH( RIGHT($A15, LEN($A15)-4), INDIRECT(hoja&"!$A:$A"), 0 ), columna, MATCH( "Totales", INDIRECT(hoja&"!$6:$6"), 0 ), valor, INDEX( INDIRECT(hoja&"!$A:$ZZ"), fila, columna ), IF(valor="-", "", valor) ), "") | AE15: =AC15-AD15 -> 0 | AF15: {=IFERROR(SUMIF(Consolidado!$C$3:$C63, $A15, INDEX(Consolidado!$E$3:$P$100, , MATCH(AF$1, Consolidado!$E$2:$P$2, 0))), "")} | AG15: =IFERROR( LET( hoja, LEFT(AG$1,3)&"R", fila, MATCH( RIGHT($A15, LEN($A15)-4), INDIRECT(hoja&"!$A:$A"), 0 ), columna, MATCH( "Totales", INDIRECT(hoja&"!$6:$6"), 0 ), valor, INDEX( INDIRECT(hoja&"!$A:$ZZ"), fila, columna ), IF(valor="-", "", valor) ), "") | AH15: =AF15-AG15 -> 0 | AI15: {=IFERROR(SUMIF(Consolidado!$C$3:$C63, $A15, INDEX(Consolidado!$E$3:$P$100, , MATCH(AI$1, Consolidado!$E$2:$P$2, 0))), "")} | AJ15: =IFERROR( LET( hoja, LEFT(AJ$1,3)&"R", fila, MATCH( RIGHT($A15, LEN($A15)-4), INDIRECT(hoja&"!$A:$A"), 0 ), columna, MATCH( "Totales", INDIRECT(hoja&"!$6:$6"), 0 ), valor, INDEX( INDIRECT(hoja&"!$A:$ZZ"), fila, columna ), IF(valor="-", "", valor) ), "") | AK15: =AI15-AJ15 -> 0 | AL15: {=IFERROR(SUMIF(Consolidado!$C$3:$C63, $A15, INDEX(Consolidado!$E$3:$P$100, , MATCH(AL$1, Consolidado!$E$2:$P$2, 0))), "")} | AM15: =IFERROR( LET( hoja, LEFT(AM$1,3)&"R", fila, MATCH( RIGHT($A15, LEN($A15)-4), INDIRECT(hoja&"!$A:$A"), 0 ), columna, MATCH( "Totales", INDIRECT(hoja&"!$6:$6"), 0 ), valor, INDEX( INDIRECT(hoja&"!$A:$ZZ"), fila, columna ), IF(valor="-", "", valor) ), "") | AN15: =AL15-AM15 -> 0
A16: =Menus!B9 -> B06 Aguinaldo | B16: =SUM(IF(MONTH(TODAY())>1,E16,0), IF(MONTH(TODAY())>2,H16,0), IF(MONTH(TODAY())>3,K16,0), IF(MONTH(TODAY())>4,N16,0), IF(MONTH(TODAY())>5,Q16,0), IF(MONTH(TODAY())>6,T16,0), IF(MONTH(TODAY())>7,W16,0), IF(MONTH(TODAY())>8,Z16,0), IF(MONTH(TODAY())>9,AC16,0), IF(MONTH(TODAY())>10,AF16,0), IF(MONTH(TODAY())>11,AI16,0), IF(MONTH(TODAY())>12,AL16,0)) -> 0 | C16: =SUM(IF(MONTH(TODAY())>1,F16,0), IF(MONTH(TODAY())>2,I16,0), IF(MONTH(TODAY())>3,L16,0), IF(MONTH(TODAY())>4,O16,0), IF(MONTH(TODAY())>5,R16,0), IF(MONTH(TODAY())>6,U16,0), IF(MONTH(TODAY())>7,X16,0), IF(MONTH(TODAY())>8,AA16,0), IF(MONTH(TODAY())>9,AD16,0), IF(MONTH(TODAY())>10,AG16,0), IF(MONTH(TODAY())>11,AJ16,0), IF(MONTH(TODAY())>12,AM16,0)) -> 0 | D16: =B16-C16 -> 0 | E16: {=IFERROR(SUMIF(Consolidado!$C$3:$C63, $A16, INDEX(Consolidado!$E$3:$P$100, , MATCH(E$1, Consolidado!$E$2:$P$2, 0))), "")} | F16: =IFERROR( LET( hoja, LEFT(F$1,3)&"R", fila, MATCH( RIGHT($A16, LEN($A16)-4), INDIRECT(hoja&"!$A:$A"), 0 ), columna, MATCH( "Totales", INDIRECT(hoja&"!$6:$6"), 0 ), valor, INDEX( INDIRECT(hoja&"!$A:$ZZ"), fila, columna ), IF(valor="-", "", valor) ), "") | G16: =E16-F16 -> 0 | H16: {=IFERROR(SUMIF(Consolidado!$C$3:$C63, $A16, INDEX(Consolidado!$E$3:$P$100, , MATCH(H$1, Consolidado!$E$2:$P$2, 0))), "")} | I16: =IFERROR( LET( hoja, LEFT(I$1,3)&"R", fila, MATCH( RIGHT($A16, LEN($A16)-4), INDIRECT(hoja&"!$A:$A"), 0 ), columna, MATCH( "Totales", INDIRECT(hoja&"!$6:$6"), 0 ), valor, INDEX( INDIRECT(hoja&"!$A:$ZZ"), fila, columna ), IF(valor="-", "", valor) ), "") | J16: =H16-I16 -> 0 | K16: {=IFERROR(SUMIF(Consolidado!$C$3:$C63, $A16, INDEX(Consolidado!$E$3:$P$100, , MATCH(K$1, Consolidado!$E$2:$P$2, 0))), "")} | L16: =IFERROR( LET( hoja, LEFT(L$1,3)&"R", fila, MATCH( RIGHT($A16, LEN($A16)-4), INDIRECT(hoja&"!$A:$A"), 0 ), columna, MATCH( "Totales", INDIRECT(hoja&"!$6:$6"), 0 ), valor, INDEX( INDIRECT(hoja&"!$A:$ZZ"), fila, columna ), IF(valor="-", "", valor) ), "") | M16: =K16-L16 -> 0 | N16: {=IFERROR(SUMIF(Consolidado!$C$3:$C63, $A16, INDEX(Consolidado!$E$3:$P$100, , MATCH(N$1, Consolidado!$E$2:$P$2, 0))), "")} | O16: =IFERROR( LET( hoja, LEFT(O$1,3)&"R", fila, MATCH( RIGHT($A16, LEN($A16)-4), INDIRECT(hoja&"!$A:$A"), 0 ), columna, MATCH( "Totales", INDIRECT(hoja&"!$6:$6"), 0 ), valor, INDEX( INDIRECT(hoja&"!$A:$ZZ"), fila, columna ), IF(valor="-", "", valor) ), "") | P16: =N16-O16 -> 0 | Q16: {=IFERROR(SUMIF(Consolidado!$C$3:$C63, $A16, INDEX(Consolidado!$E$3:$P$100, , MATCH(Q$1, Consolidado!$E$2:$P$2, 0))), "")} | R16: =IFERROR( LET( hoja, LEFT(R$1,3)&"R", fila, MATCH( RIGHT($A16, LEN($A16)-4), INDIRECT(hoja&"!$A:$A"), 0 ), columna, MATCH( "Totales", INDIRECT(hoja&"!$6:$6"), 0 ), valor, INDEX( INDIRECT(hoja&"!$A:$ZZ"), fila, columna ), IF(valor="-", "", valor) ), "") | S16: =Q16-R16 -> 0 | T16: {=IFERROR(SUMIF(Consolidado!$C$3:$C63, $A16, INDEX(Consolidado!$E$3:$P$100, , MATCH(T$1, Consolidado!$E$2:$P$2, 0))), "")} | U16: =IFERROR( LET( hoja, LEFT(U$1,3)&"R", fila, MATCH( RIGHT($A16, LEN($A16)-4), INDIRECT(hoja&"!$A:$A"), 0 ), columna, MATCH( "Totales", INDIRECT(hoja&"!$6:$6"), 0 ), valor, INDEX( INDIRECT(hoja&"!$A:$ZZ"), fila, columna ), IF(valor="-", "", valor) ), "") | V16: =T16-U16 -> 0 | W16: {=IFERROR(SUMIF(Consolidado!$C$3:$C63, $A16, INDEX(Consolidado!$E$3:$P$100, , MATCH(W$1, Consolidado!$E$2:$P$2, 0))), "")} | X16: =IFERROR( LET( hoja, LEFT(X$1,3)&"R", fila, MATCH( RIGHT($A16, LEN($A16)-4), INDIRECT(hoja&"!$A:$A"), 0 ), columna, MATCH( "Totales", INDIRECT(hoja&"!$6:$6"), 0 ), valor, INDEX( INDIRECT(hoja&"!$A:$ZZ"), fila, columna ), IF(valor="-", "", valor) ), "") | Y16: =W16-X16 -> 0 | Z16: {=IFERROR(SUMIF(Consolidado!$C$3:$C63, $A16, INDEX(Consolidado!$E$3:$P$100, , MATCH(Z$1, Consolidado!$E$2:$P$2, 0))), "")} | AA16: =IFERROR( LET( hoja, LEFT(AA$1,3)&"R", fila, MATCH( RIGHT($A16, LEN($A16)-4), INDIRECT(hoja&"!$A:$A"), 0 ), columna, MATCH( "Totales", INDIRECT(hoja&"!$6:$6"), 0 ), valor, INDEX( INDIRECT(hoja&"!$A:$ZZ"), fila, columna ), IF(valor="-", "", valor) ), "") | AB16: =Z16-AA16 -> 0 | AC16: {=IFERROR(SUMIF(Consolidado!$C$3:$C63, $A16, INDEX(Consolidado!$E$3:$P$100, , MATCH(AC$1, Consolidado!$E$2:$P$2, 0))), "")} | AD16: =IFERROR( LET( hoja, LEFT(AD$1,3)&"R", fila, MATCH( RIGHT($A16, LEN($A16)-4), INDIRECT(hoja&"!$A:$A"), 0 ), columna, MATCH( "Totales", INDIRECT(hoja&"!$6:$6"), 0 ), valor, INDEX( INDIRECT(hoja&"!$A:$ZZ"), fila, columna ), IF(valor="-", "", valor) ), "") | AE16: =AC16-AD16 -> 0 | AF16: {=IFERROR(SUMIF(Consolidado!$C$3:$C63, $A16, INDEX(Consolidado!$E$3:$P$100, , MATCH(AF$1, Consolidado!$E$2:$P$2, 0))), "")} | AG16: =IFERROR( LET( hoja, LEFT(AG$1,3)&"R", fila, MATCH( RIGHT($A16, LEN($A16)-4), INDIRECT(hoja&"!$A:$A"), 0 ), columna, MATCH( "Totales", INDIRECT(hoja&"!$6:$6"), 0 ), valor, INDEX( INDIRECT(hoja&"!$A:$ZZ"), fila, columna ), IF(valor="-", "", valor) ), "") | AH16: =AF16-AG16 -> 0 | AI16: {=IFERROR(SUMIF(Consolidado!$C$3:$C63, $A16, INDEX(Consolidado!$E$3:$P$100, , MATCH(AI$1, Consolidado!$E$2:$P$2, 0))), "")} | AJ16: =IFERROR( LET( hoja, LEFT(AJ$1,3)&"R", fila, MATCH( RIGHT($A16, LEN($A16)-4), INDIRECT(hoja&"!$A:$A"), 0 ), columna, MATCH( "Totales", INDIRECT(hoja&"!$6:$6"), 0 ), valor, INDEX( INDIRECT(hoja&"!$A:$ZZ"), fila, columna ), IF(valor="-", "", valor) ), "") | AK16: =AI16-AJ16 -> 0 | AL16: {=IFERROR(SUMIF(Consolidado!$C$3:$C63, $A16, INDEX(Consolidado!$E$3:$P$100, , MATCH(AL$1, Consolidado!$E$2:$P$2, 0))), "")} | AM16: =IFERROR( LET( hoja, LEFT(AM$1,3)&"R", fila, MATCH( RIGHT($A16, LEN($A16)-4), INDIRECT(hoja&"!$A:$A"), 0 ), columna, MATCH( "Totales", INDIRECT(hoja&"!$6:$6"), 0 ), valor, INDEX( INDIRECT(hoja&"!$A:$ZZ"), fila, columna ), IF(valor="-", "", valor) ), "") | AN16: =AL16-AM16 -> 0
A17: =Menus!B10 -> B07 Comisiones Bancarias | B17: =SUM(IF(MONTH(TODAY())>1,E17,0), IF(MONTH(TODAY())>2,H17,0), IF(MONTH(TODAY())>3,K17,0), IF(MONTH(TODAY())>4,N17,0), IF(MONTH(TODAY())>5,Q17,0), IF(MONTH(TODAY())>6,T17,0), IF(MONTH(TODAY())>7,W17,0), IF(MONTH(TODAY())>8,Z17,0), IF(MONTH(TODAY())>9,AC17,0), IF(MONTH(TODAY())>10,AF17,0), IF(MONTH(TODAY())>11,AI17,0), IF(MONTH(TODAY())>12,AL17,0)) -> 0 | C17: =SUM(IF(MONTH(TODAY())>1,F17,0), IF(MONTH(TODAY())>2,I17,0), IF(MONTH(TODAY())>3,L17,0), IF(MONTH(TODAY())>4,O17,0), IF(MONTH(TODAY())>5,R17,0), IF(MONTH(TODAY())>6,U17,0), IF(MONTH(TODAY())>7,X17,0), IF(MONTH(TODAY())>8,AA17,0), IF(MONTH(TODAY())>9,AD17,0), IF(MONTH(TODAY())>10,AG17,0), IF(MONTH(TODAY())>11,AJ17,0), IF(MONTH(TODAY())>12,AM17,0)) -> 0 | D17: =B17-C17 -> 0 | E17: {=IFERROR(SUMIF(Consolidado!$C$3:$C63, $A17, INDEX(Consolidado!$E$3:$P$100, , MATCH(E$1, Consolidado!$E$2:$P$2, 0))), "")} | F17: =IFERROR( LET( hoja, LEFT(F$1,3)&"R", fila, MATCH( RIGHT($A17, LEN($A17)-4), INDIRECT(hoja&"!$A:$A"), 0 ), columna, MATCH( "Totales", INDIRECT(hoja&"!$6:$6"), 0 ), valor, INDEX( INDIRECT(hoja&"!$A:$ZZ"), fila, columna ), IF(valor="-", "", valor) ), "") | G17: =E17-F17 -> 0 | H17: {=IFERROR(SUMIF(Consolidado!$C$3:$C63, $A17, INDEX(Consolidado!$E$3:$P$100, , MATCH(H$1, Consolidado!$E$2:$P$2, 0))), "")} | I17: =IFERROR( LET( hoja, LEFT(I$1,3)&"R", fila, MATCH( RIGHT($A17, LEN($A17)-4), INDIRECT(hoja&"!$A:$A"), 0 ), columna, MATCH( "Totales", INDIRECT(hoja&"!$6:$6"), 0 ), valor, INDEX( INDIRECT(hoja&"!$A:$ZZ"), fila, columna ), IF(valor="-", "", valor) ), "") | J17: =H17-I17 -> 0 | K17: {=IFERROR(SUMIF(Consolidado!$C$3:$C63, $A17, INDEX(Consolidado!$E$3:$P$100, , MATCH(K$1, Consolidado!$E$2:$P$2, 0))), "")} | L17: =IFERROR( LET( hoja, LEFT(L$1,3)&"R", fila, MATCH( RIGHT($A17, LEN($A17)-4), INDIRECT(hoja&"!$A:$A"), 0 ), columna, MATCH( "Totales", INDIRECT(hoja&"!$6:$6"), 0 ), valor, INDEX( INDIRECT(hoja&"!$A:$ZZ"), fila, columna ), IF(valor="-", "", valor) ), "") | M17: =K17-L17 -> 0 | N17: {=IFERROR(SUMIF(Consolidado!$C$3:$C63, $A17, INDEX(Consolidado!$E$3:$P$100, , MATCH(N$1, Consolidado!$E$2:$P$2, 0))), "")} | O17: =IFERROR( LET( hoja, LEFT(O$1,3)&"R", fila, MATCH( RIGHT($A17, LEN($A17)-4), INDIRECT(hoja&"!$A:$A"), 0 ), columna, MATCH( "Totales", INDIRECT(hoja&"!$6:$6"), 0 ), valor, INDEX( INDIRECT(hoja&"!$A:$ZZ"), fila, columna ), IF(valor="-", "", valor) ), "") | P17: =N17-O17 -> 0 | Q17: {=IFERROR(SUMIF(Consolidado!$C$3:$C63, $A17, INDEX(Consolidado!$E$3:$P$100, , MATCH(Q$1, Consolidado!$E$2:$P$2, 0))), "")} | R17: =IFERROR( LET( hoja, LEFT(R$1,3)&"R", fila, MATCH( RIGHT($A17, LEN($A17)-4), INDIRECT(hoja&"!$A:$A"), 0 ), columna, MATCH( "Totales", INDIRECT(hoja&"!$6:$6"), 0 ), valor, INDEX( INDIRECT(hoja&"!$A:$ZZ"), fila, columna ), IF(valor="-", "", valor) ), "") | S17: =Q17-R17 -> 0 | T17: {=IFERROR(SUMIF(Consolidado!$C$3:$C63, $A17, INDEX(Consolidado!$E$3:$P$100, , MATCH(T$1, Consolidado!$E$2:$P$2, 0))), "")} | U17: =IFERROR( LET( hoja, LEFT(U$1,3)&"R", fila, MATCH( RIGHT($A17, LEN($A17)-4), INDIRECT(hoja&"!$A:$A"), 0 ), columna, MATCH( "Totales", INDIRECT(hoja&"!$6:$6"), 0 ), valor, INDEX( INDIRECT(hoja&"!$A:$ZZ"), fila, columna ), IF(valor="-", "", valor) ), "") | V17: =T17-U17 -> 0 | W17: {=IFERROR(SUMIF(Consolidado!$C$3:$C63, $A17, INDEX(Consolidado!$E$3:$P$100, , MATCH(W$1, Consolidado!$E$2:$P$2, 0))), "")} | X17: =IFERROR( LET( hoja, LEFT(X$1,3)&"R", fila, MATCH( RIGHT($A17, LEN($A17)-4), INDIRECT(hoja&"!$A:$A"), 0 ), columna, MATCH( "Totales", INDIRECT(hoja&"!$6:$6"), 0 ), valor, INDEX( INDIRECT(hoja&"!$A:$ZZ"), fila, columna ), IF(valor="-", "", valor) ), "") | Y17: =W17-X17 -> 0 | Z17: {=IFERROR(SUMIF(Consolidado!$C$3:$C63, $A17, INDEX(Consolidado!$E$3:$P$100, , MATCH(Z$1, Consolidado!$E$2:$P$2, 0))), "")} | AA17: =IFERROR( LET( hoja, LEFT(AA$1,3)&"R", fila, MATCH( RIGHT($A17, LEN($A17)-4), INDIRECT(hoja&"!$A:$A"), 0 ), columna, MATCH( "Totales", INDIRECT(hoja&"!$6:$6"), 0 ), valor, INDEX( INDIRECT(hoja&"!$A:$ZZ"), fila, columna ), IF(valor="-", "", valor) ), "") | AB17: =Z17-AA17 -> 0 | AC17: {=IFERROR(SUMIF(Consolidado!$C$3:$C63, $A17, INDEX(Consolidado!$E$3:$P$100, , MATCH(AC$1, Consolidado!$E$2:$P$2, 0))), "")} | AD17: =IFERROR( LET( hoja, LEFT(AD$1,3)&"R", fila, MATCH( RIGHT($A17, LEN($A17)-4), INDIRECT(hoja&"!$A:$A"), 0 ), columna, MATCH( "Totales", INDIRECT(hoja&"!$6:$6"), 0 ), valor, INDEX( INDIRECT(hoja&"!$A:$ZZ"), fila, columna ), IF(valor="-", "", valor) ), "") | AE17: =AC17-AD17 -> 0 | AF17: {=IFERROR(SUMIF(Consolidado!$C$3:$C63, $A17, INDEX(Consolidado!$E$3:$P$100, , MATCH(AF$1, Consolidado!$E$2:$P$2, 0))), "")} | AG17: =IFERROR( LET( hoja, LEFT(AG$1,3)&"R", fila, MATCH( RIGHT($A17, LEN($A17)-4), INDIRECT(hoja&"!$A:$A"), 0 ), columna, MATCH( "Totales", INDIRECT(hoja&"!$6:$6"), 0 ), valor, INDEX( INDIRECT(hoja&"!$A:$ZZ"), fila, columna ), IF(valor="-", "", valor) ), "") | AH17: =AF17-AG17 -> 0 | AI17: {=IFERROR(SUMIF(Consolidado!$C$3:$C63, $A17, INDEX(Consolidado!$E$3:$P$100, , MATCH(AI$1, Consolidado!$E$2:$P$2, 0))), "")} | AJ17: =IFERROR( LET( hoja, LEFT(AJ$1,3)&"R", fila, MATCH( RIGHT($A17, LEN($A17)-4), INDIRECT(hoja&"!$A:$A"), 0 ), columna, MATCH( "Totales", INDIRECT(hoja&"!$6:$6"), 0 ), valor, INDEX( INDIRECT(hoja&"!$A:$ZZ"), fila, columna ), IF(valor="-", "", valor) ), "") | AK17: =AI17-AJ17 -> 0 | AL17: {=IFERROR(SUMIF(Consolidado!$C$3:$C63, $A17, INDEX(Consolidado!$E$3:$P$100, , MATCH(AL$1, Consolidado!$E$2:$P$2, 0))), "")} | AM17: =IFERROR( LET( hoja, LEFT(AM$1,3)&"R", fila, MATCH( RIGHT($A17, LEN($A17)-4), INDIRECT(hoja&"!$A:$A"), 0 ), columna, MATCH( "Totales", INDIRECT(hoja&"!$6:$6"), 0 ), valor, INDEX( INDIRECT(hoja&"!$A:$ZZ"), fila, columna ), IF(valor="-", "", valor) ), "") | AN17: =AL17-AM17 -> 0
