Workbook

Sheet xProyecto
A1: Wepark S.A. de C.V. | B1: Total | C1: Interlomas | D1: {=TRANSPOSE(Menus!A2:A127)}
A3: Utilidad Wepark | B3: =SUM(D3:AZ3) -> 0 | C3: =C5-C36+C101 -> 0 | D3: =D5-D36+D105 -> 0 | E3: =E9-E40+E105 -> 0 | F3: =F9-F40+F105 -> 0 | G3: =G9-G40+G105 -> 0 | H3: =H9-H40+H105 -> 0 | I3: =I9-I40+I105 -> 0 | J3: =J9-J40+J105 -> 0 | K3: =K9-K40+K105 -> 0 | L3: =L9-L40+L105 -> 0 | ... AZ3: =AZ9-AZ40+AZ105 -> 0
A5: Honorario Wepark | B5: =SUM(D5:AZ5) -> 0 | C5: =IF(ISNA(VLOOKUP(C$1,Utilidades!$A$1:$B127,2,FALSE)),"",VLOOKUP(C$1,Utilidades!$A$1:$B127,2,FALSE)) | D5: =IF(ISNA(VLOOKUP(D$1,Utilidades!$A$1:$B127,2,FALSE)),"",VLOOKUP(D$1,Utilidades!$A$1:$B127,2,FALSE)) | E5: =IF(ISNA(VLOOKUP(E$1,Utilidades!$A$1:$B127,2,FALSE)),"",VLOOKUP(E$1,Utilidades!$A$1:$B127,2,FALSE)) | F5: =IF(ISNA(VLOOKUP(F$1,Utilidades!$A$1:$B127,2,FALSE)),"",VLOOKUP(F$1,Utilidades!$A$1:$B127,2,FALSE)) | G5: =IF(ISNA(VLOOKUP(G$1,Utilidades!$A$1:$B127,2,FALSE)),"",VLOOKUP(G$1,Utilidades!$A$1:$B127,2,FALSE)) | H5: =IF(ISNA(VLOOKUP(H$1,Utilidades!$A$1:$B127,2,FALSE)),"",VLOOKUP(H$1,Utilidades!$A$1:$B127,2,FALSE)) | I5: =IF(ISNA(VLOOKUP(I$1,Utilidades!$A$1:$B127,2,FALSE)),"",VLOOKUP(I$1,Utilidades!$A$1:$B127,2,FALSE)) | J5: =IF(ISNA(VLOOKUP(J$1,Utilidades!$A$1:$B127,2,FALSE)),"",VLOOKUP(J$1,Utilidades!$A$1:$B127,2,FALSE)) | ... AZ5: =IF(ISNA(VLOOKUP(AZ$1,Utilidades!$A$1:$B127,2,FALSE)),"",VLOOKUP(AZ$1,Utilidades!$A$1:$B127,2,FALSE))
A7: Utilidad Bruta | B7: =SUM(D7:AZ7) -> 0 | C7: =C9-C40+C105 -> 0 | D7: =D9-D40 -> 0 | E7: =E9-E40 -> 0 | F7: =F9-F40 -> 0 | G7: =G9-G40 -> 0 | H7: =H9-H40 -> 0 | I7: =I9-I40 -> 0 | J7: =J9-J40 -> 0 | K7: =K9-K40 -> 0 | ... AZ7: =AZ9-AZ40 -> 0
A9: Total de Ingresos | B9: =SUM(B10:B38) -> 0 | C9: =SUM(C10:C38) -> 0 | D9: =SUM(D10:D38) -> 0 | E9: =SUM(E10:E38) -> 0 | F9: =SUM(F10:F38) -> 0 | G9: =SUM(G10:G38) -> 0 | H9: =SUM(H10:H38) -> 0 | I9: =SUM(I10:I38) -> 0 | ... AY9: =SUM(AY10:AY38) -> 0
A10: =Menus!R2 | B10: =IFERROR(SUM(D10:AZ10),"") -> 0 | C10: =IFERROR(INDEX($D$1:$AQ127, MATCH($A10, $A$1:$A127, 0), MATCH(C$1, $D$1:AZ$1, 0)), "") | D10: {=SUM( IFERROR( VLOOKUP($A10, INDIRECT("EneR!$A$6:$ZZ$1048576"), MATCH(D$1, EneR!$6:$6, 0), FALSE), 0 ) + IFERROR( VLOOKUP($A10, INDIRECT("FebR!$A$6:$ZZ$1048576"), MATCH(D$1, FebR!$6:$6, 0), FALSE), 0 ) + IFERROR( VLOOKUP($A10, INDIRECT("MarR!$A$6:$ZZ$1048576"), MATCH(D$1, MarR!$6:$6, 0), FALSE), 0 ) + IFERROR( VLOOKUP($A10, INDIRECT("AbrR!$A$6:$ZZ$1048576"), MATCH(D$1, AbrR!$6:$6, 0), FALSE), 0 ) + IFERROR( VLOOKUP($A10, INDIRECT("MayR!$A$6:$ZZ$1048576"), MATCH(D$1, MayR!$6:$6, 0), FALSE), 0 ) + IFERROR( VLOOKUP($A10, INDIRECT("JunR!$A$6:$ZZ$1048576"), MATCH(D$1, JunR!$6:$6, 0), FALSE), 0 ) + IFERROR( VLOOKUP($A10, INDIRECT("JulR!$A$6:$ZZ$1048576"), MATCH(D$1, JulR!$6:$6, 0), FALSE), 0 ) + IFERROR( VLOOKUP($A10, INDIRECT("AgoR!$A$6:$ZZ$1048576"), MATCH(D$1, AgoR!$6:$6, 0), FALSE), 0 ) + IFERROR( VLOOKUP($A10, INDIRECT("SepR!$A$6:$ZZ$1048576"), MATCH(D$1, SepR!$6:$6, 0), FALSE), 0 ) + IFERROR( VLOOKUP($A10, INDIRECT("OctR!$A$6:$ZZ$1048576"), MATCH(D$1, OctR!$6:$6, 0), FALSE), 0 ) + IFERROR( VLOOKUP($A10, INDIRECT("NovR!$A$6:$ZZ$1048576"), MATCH(D$1, NovR!$6:$6, 0), FALSE), 0 ) + IFERROR( VLOOKUP($A10, INDIRECT("DicR!$A$6:$ZZ$1048576"), MATCH(D$1, DicR!$6:$6, 0), FALSE), 0 ) )} -> 0 | E10: {=SUM( IFERROR( VLOOKUP($A10, INDIRECT("EneR!$A$6:$ZZ$1048576"), MATCH(E$1, EneR!$6:$6, 0), FALSE), 0 ) + IFERROR( VLOOKUP($A10, INDIRECT("FebR!$A$6:$ZZ$1048576"), MATCH(E$1, FebR!$6:$6, 0), FALSE), 0 ) + IFERROR( VLOOKUP($A10, INDIRECT("MarR!$A$6:$ZZ$1048576"), MATCH(E$1, MarR!$6:$6, 0), FALSE), 0 ) + IFERROR( VLOOKUP($A10, INDIRECT("AbrR!$A$6:$ZZ$1048576"), MATCH(E$1, AbrR!$6:$6, 0), FALSE), 0 ) + IFERROR( VLOOKUP($A10, INDIRECT("MayR!$A$6:$ZZ$1048576"), MATCH(E$1, MayR!$6:$6, 0), FALSE), 0 ) + IFERROR( VLOOKUP($A10, INDIRECT("JunR!$A$6:$ZZ$1048576"), MATCH(E$1, JunR!$6:$6, 0), FALSE), 0 ) + IFERROR( VLOOKUP($A10, INDIRECT("JulR!$A$6:$ZZ$1048576"), MATCH(E$1, JulR!$6:$6, 0), FALSE), 0 ) + IFERROR( VLOOKUP($A10, INDIRECT("AgoR!$A$6:$ZZ$1048576"), MATCH(E$1, AgoR!$6:$6, 0), FALSE), 0 ) + IFERROR( VLOOKUP($A10, INDIRECT("SepR!$A$6:$ZZ$1048576"), MATCH(E$1, SepR!$6:$6, 0), FALSE), 0 ) + IFERROR( VLOOKUP($A10, INDIRECT("OctR!$A$6:$ZZ$1048576"), MATCH(E$1, OctR!$6:$6, 0), FALSE), 0 ) + IFERROR( VLOOKUP($A10, INDIRECT("NovR!$A$6:$ZZ$1048576"), MATCH(E$1, NovR!$6:$6, 0), FALSE), 0 ) + IFERROR( VLOOKUP($A10, INDIRECT("DicR!$A$6:$ZZ$1048576"), MATCH(E$1, DicR!$6:$6, 0), FALSE), 0 ) )} -> 0 | F10: {=SUM( IFERROR( VLOOKUP($A10, INDIRECT("EneR!$A$6:$ZZ$1048576"), MATCH(F$1, EneR!$6:$6, 0), FALSE), 0 ) + IFERROR( VLOOKUP($A10, INDIRECT("FebR!$A$6:$ZZ$1048576"), MATCH(F$1, FebR!$6:$6, 0), FALSE), 0 ) + IFERROR( VLOOKUP($A10, INDIRECT("MarR!$A$6:$ZZ$1048576"), MATCH(F$1, MarR!$6:$6, 0), FALSE), 0 ) + IFERROR( VLOOKUP($A10, INDIRECT("AbrR!$A$6:$ZZ$1048576"), MATCH(F$1, AbrR!$6:$6, 0), FALSE), 0 ) + IFERROR( VLOOKUP($A10, INDIRECT("MayR!$A$6:$ZZ$1048576"), MATCH(F$1, MayR!$6:$6, 0), FALSE), 0 ) + IFERROR( VLOOKUP($A10, INDIRECT("JunR!$A$6:$ZZ$1048576"), MATCH(F$1, JunR!$6:$6, 0), FALSE), 0 ) + IFERROR( VLOOKUP($A10, INDIRECT("JulR!$A$6:$ZZ$1048576"), MATCH(F$1, JulR!$6:$6, 0), FALSE), 0 ) + IFERROR( VLOOKUP($A10, INDIRECT("AgoR!$A$6:$ZZ$1048576"), MATCH(F$1, AgoR!$6:$6, 0), FALSE), 0 ) + IFERROR( VLOOKUP($A10, INDIRECT("SepR!$A$6:$ZZ$1048576"), MATCH(F$1, SepR!$6:$6, 0), FALSE), 0 ) + IFERROR( VLOOKUP($A10, INDIRECT("OctR!$A$6:$ZZ$1048576"), MATCH(F$1, OctR!$6:$6, 0), FALSE), 0 ) + IFERROR( VLOOKUP($A10, INDIRECT("NovR!$A$6:$ZZ$1048576"), MATCH(F$1, NovR!$6:$6, 0), FALSE), 0 ) + IFERROR( VLOOKUP($A10, INDIRECT("DicR!$A$6:$ZZ$1048576"), MATCH(F$1, DicR!$6:$6, 0), FALSE), 0 ) )} -> 0 | G10: {=SUM( IFERROR( VLOOKUP($A10, INDIRECT("EneR!$A$6:$ZZ$1048576"), MATCH(G$1, EneR!$6:$6, 0), FALSE), 0 ) + IFERROR( VLOOKUP($A10, INDIRECT("FebR!$A$6:$ZZ$1048576"), MATCH(G$1, FebR!$6:$6, 0), FALSE), 0 ) + IFERROR( VLOOKUP($A10, INDIRECT("MarR!$A$6:$ZZ$1048576"), MATCH(G$1, MarR!$6:$6, 0), FALSE), 0 ) + IFERROR( VLOOKUP($A10, INDIRECT("AbrR!$A$6:$ZZ$1048576"), MATCH(G$1, AbrR!$6:$6, 0), FALSE), 0 ) + IFERROR( VLOOKUP($A10, INDIRECT("MayR!$A$6:$ZZ$1048576"), MATCH(G$1, MayR!$6:$6, 0), FALSE), 0 ) + IFERROR( VLOOKUP($A10, INDIRECT("JunR!$A$6:$ZZ$1048576"), MATCH(G$1, JunR!$6:$6, 0), FALSE), 0 ) + IFERROR( VLOOKUP($A10, INDIRECT("JulR!$A$6:$ZZ$1048576"), MATCH(G$1, JulR!$6:$6, 0), FALSE), 0 ) + IFERROR( VLOOKUP($A10, INDIRECT("AgoR!$A$6:$ZZ$1048576"), MATCH(G$1, AgoR!$6:$6, 0), FALSE), 0 ) + IFERROR( VLOOKUP($A10, INDIRECT("SepR!$A$6:$ZZ$1048576"), MATCH(G$1, SepR!$6:$6, 0), FALSE), 0 ) + IFERROR( VLOOKUP($A10, INDIRECT("OctR!$A$6:$ZZ$1048576"), MATCH(G$1, OctR!$6:$6, 0), FALSE), 0 ) + IFERROR( VLOOKUP($A10, INDIRECT("NovR!$A$6:$ZZ$1048576"), MATCH(G$1, NovR!$6:$6, 0), FALSE), 0 ) + IFERROR( VLOOKUP($A10, INDIRECT("DicR!$A$6:$ZZ$1048576"), MATCH(G$1, DicR!$6:$6, 0), FALSE), 0 ) )} -> 0 | H10: {=SUM( IFERROR( VLOOKUP($A10, INDIRECT("EneR!$A$6:$ZZ$1048576"), MATCH(H$1, EneR!$6:$6, 0), FALSE), 0 ) + IFERROR( VLOOKUP($A10, INDIRECT("FebR!$A$6:$ZZ$1048576"), MATCH(H$1, FebR!$6:$6, 0), FALSE), 0 ) + IFERROR( VLOOKUP($A10, INDIRECT("MarR!$A$6:$ZZ$1048576"), MATCH(H$1, MarR!$6:$6, 0), FALSE), 0 ) + IFERROR( VLOOKUP($A10, INDIRECT("AbrR!$A$6:$ZZ$1048576"), MATCH(H$1, AbrR!$6:$6, 0), FALSE), 0 ) + IFERROR( VLOOKUP($A10, INDIRECT("MayR!$A$6:$ZZ$1048576"), MATCH(H$1, MayR!$6:$6, 0), FALSE), 0 ) + IFERROR( VLOOKUP($A10, INDIRECT("JunR!$A$6:$ZZ$1048576"), MATCH(H$1, JunR!$6:$6, 0), FALSE), 0 ) + IFERROR( VLOOKUP($A10, INDIRECT("JulR!$A$6:$ZZ$1048576"), MATCH(H$1, JulR!$6:$6, 0), FALSE), 0 ) + IFERROR( VLOOKUP($A10, INDIRECT("AgoR!$A$6:$ZZ$1048576"), MATCH(H$1, AgoR!$6:$6, 0), FALSE), 0 ) + IFERROR( VLOOKUP($A10, INDIRECT("SepR!$A$6:$ZZ$1048576"), MATCH(H$1, SepR!$6:$6, 0), FALSE), 0 ) + IFERROR( VLOOKUP($A10, INDIRECT("OctR!$A$6:$ZZ$1048576"), MATCH(H$1, OctR!$6:$6, 0), FALSE), 0 ) + IFERROR( VLOOKUP($A10, INDIRECT("NovR!$A$6:$ZZ$1048576"), MATCH(H$1, NovR!$6:$6, 0), FALSE), 0 ) + IFERROR( VLOOKUP($A10, INDIRECT("DicR!$A$6:$ZZ$1048576"), MATCH(H$1, DicR!$6:$6, 0), FALSE), 0 ) )} -> 0 | I10: {=SUM( IFERROR( VLOOKUP($A10, INDIRECT("EneR!$A$6:$ZZ$1048576"), MATCH(I$1, EneR!$6:$6, 0), FALSE), 0 ) + IFERROR( VLOOKUP($A10, INDIRECT("FebR!$A$6:$ZZ$1048576"), MATCH(I$1, FebR!$6:$6, 0), FALSE), 0 ) + IFERROR( VLOOKUP($A10, INDIRECT("MarR!$A$6:$ZZ$1048576"), MATCH(I$1, MarR!$6:$6, 0), FALSE), 0 ) + IFERROR( VLOOKUP($A10, INDIRECT("AbrR!$A$6:$ZZ$1048576"), MATCH(I$1, AbrR!$6:$6, 0), FALSE), 0 ) + IFERROR( VLOOKUP($A10, INDIRECT("MayR!$A$6:$ZZ$1048576"), MATCH(I$1, MayR!$6:$6, 0), FALSE), 0 ) + IFERROR( VLOOKUP($A10, INDIRECT("JunR!$A$6:$ZZ$1048576"), MATCH(I$1, JunR!$6:$6, 0), FALSE), 0 ) + IFERROR( VLOOKUP($A10, INDIRECT("JulR!$A$6:$ZZ$1048576"), MATCH(I$1, JulR!$6:$6, 0), FALSE), 0 ) + IFERROR( VLOOKUP($A10, INDIRECT("AgoR!$A$6:$ZZ$1048576"), MATCH(I$1, AgoR!$6:$6, 0), FALSE), 0 ) + IFERROR( VLOOKUP($A10, INDIRECT("SepR!$A$6:$ZZ$1048576"), MATCH(I$1, SepR!$6:$6, 0), FALSE), 0 ) + IFERROR( VLOOKUP($A10, INDIRECT("OctR!$A$6:$ZZ$1048576"), MATCH(I$1, OctR!$6:$6, 0), FALSE), 0 ) + IFERROR( VLOOKUP($A10, INDIRECT("NovR!$A$6:$ZZ$1048576"), MATCH(I$1, NovR!$6:$6, 0), FALSE), 0 ) + IFERROR( VLOOKUP($A10, INDIRECT("DicR!$A$6:$ZZ$1048576"), MATCH(I$1, DicR!$6:$6, 0), FALSE), 0 ) )} -> 0 | J10: {=SUM( IFERROR( VLOOKUP($A10, INDIRECT("EneR!$A$6:$ZZ$1048576"), MATCH(J$1, EneR!$6:$6, 0), FALSE), 0 ) + IFERROR( VLOOKUP($A10, INDIRECT("FebR!$A$6:$ZZ$1048576"), MATCH(J$1, FebR!$6:$6, 0), FALSE), 0 ) + IFERROR( VLOOKUP($A10, INDIRECT("MarR!$A$6:$ZZ$1048576"), MATCH(J$1, MarR!$6:$6, 0), FALSE), 0 ) + IFERROR( VLOOKUP($A10, INDIRECT("AbrR!$A$6:$ZZ$1048576"), MATCH(J$1, AbrR!$6:$6, 0), FALSE), 0 ) + IFERROR( VLOOKUP($A10, INDIRECT("MayR!$A$6:$ZZ$1048576"), MATCH(J$1, MayR!$6:$6, 0), FALSE), 0 ) + IFERROR( VLOOKUP($A10, INDIRECT("JunR!$A$6:$ZZ$1048576"), MATCH(J$1, JunR!$6:$6, 0), FALSE), 0 ) + IFERROR( VLOOKUP($A10, INDIRECT("JulR!$A$6:$ZZ$1048576"), MATCH(J$1, JulR!$6:$6, 0), FALSE), 0 ) + IFERROR( VLOOKUP($A10, INDIRECT("AgoR!$A$6:$ZZ$1048576"), MATCH(J$1, AgoR!$6:$6, 0), FALSE), 0 ) + IFERROR( VLOOKUP($A10, INDIRECT("SepR!$A$6:$ZZ$1048576"), MATCH(J$1, SepR!$6:$6, 0), FALSE), 0 ) + IFERROR( VLOOKUP($A10, INDIRECT("OctR!$A$6:$ZZ$1048576"), MATCH(J$1, OctR!$6:$6, 0), FALSE), 0 ) + IFERROR( VLOOKUP($A10, INDIRECT("NovR!$A$6:$ZZ$1048576"), MATCH(J$1, NovR!$6:$6, 0), FALSE), 0 ) + IFERROR( VLOOKUP($A10, INDIRECT("DicR!$A$6:$ZZ$1048576"), MATCH(J$1, DicR!$6:$6, 0), FALSE), 0 ) )} -> 0 | K10: {=SUM( IFERROR( VLOOKUP($A10, INDIRECT("EneR!$A$6:$ZZ$1048576"), MATCH(K$1, EneR!$6:$6, 0), FALSE), 0 ) + IFERROR( VLOOKUP($A10, INDIRECT("FebR!$A$6:$ZZ$1048576"), MATCH(K$1, FebR!$6:$6, 0), FALSE), 0 ) + IFERROR( VLOOKUP($A10, INDIRECT("MarR!$A$6:$ZZ$1048576"), MATCH(K$1, MarR!$6:$6, 0), FALSE), 0 ) + IFERROR( VLOOKUP($A10, INDIRECT("AbrR!$A$6:$ZZ$1048576"), MATCH(K$1, AbrR!$6:$6, 0), FALSE), 0 ) + IFERROR( VLOOKUP($A10, INDIRECT("MayR!$A$6:$ZZ$1048576"), MATCH(K$1, MayR!$6:$6, 0), FALSE), 0 ) + IFERROR( VLOOKUP($A10, INDIRECT("JunR!$A$6:$ZZ$1048576"), MATCH(K$1, JunR!$6:$6, 0), FALSE), 0 ) + IFERROR( VLOOKUP($A10, INDIRECT("JulR!$A$6:$ZZ$1048576"), MATCH(K$1, JulR!$6:$6, 0), FALSE), 0 ) + IFERROR( VLOOKUP($A10, INDIRECT("AgoR!$A$6:$ZZ$1048576"), MATCH(K$1, AgoR!$6:$6, 0), FALSE), 0 ) + IFERROR( VLOOKUP($A10, INDIRECT("SepR!$A$6:$ZZ$1048576"), MATCH(K$1, SepR!$6:$6, 0), FALSE), 0 ) + IFERROR( VLOOKUP($A10, INDIRECT("OctR!$A$6:$ZZ$1048576"), MATCH(K$1, OctR!$6:$6, 0), FALSE), 0 ) + IFERROR( VLOOKUP($A10, INDIRECT("NovR!$A$6:$ZZ$1048576"), MATCH(K$1, NovR!$6:$6, 0), FALSE), 0 ) + IFERROR( VLOOKUP($A10, INDIRECT("DicR!$A$6:$ZZ$1048576"), MATCH(K$1, DicR!$6:$6, 0), FALSE), 0 ) )} -> 0 | ... AY10: {=SUM( IFERROR( VLOOKUP($A10, INDIRECT("EneR!$A$6:$ZZ$1048576"), MATCH(AY$1, EneR!$6:$6, 0), FALSE), 0 ) + IFERROR( VLOOKUP($A10, INDIRECT("FebR!$A$6:$ZZ$1048576"), MATCH(AY$1, FebR!$6:$6, 0), FALSE), 0 ) + IFERROR( VLOOKUP($A10, INDIRECT("MarR!$A$6:$ZZ$1048576"), MATCH(AY$1, MarR!$6:$6, 0), FALSE), 0 ) + IFERROR( VLOOKUP($A10, INDIRECT("AbrR!$A$6:$ZZ$1048576"), MATCH(AY$1, AbrR!$6:$6, 0), FALSE), 0 ) + IFERROR( VLOOKUP($A10, INDIRECT("MayR!$A$6:$ZZ$1048576"), MATCH(AY$1, MayR!$6:$6, 0), FALSE), 0 ) + IFERROR( VLOOKUP($A10, INDIRECT("JunR!$A$6:$ZZ$1048576"), MATCH(AY$1, JunR!$6:$6, 0), FALSE), 0 ) + IFERROR( VLOOKUP($A10, INDIRECT("JulR!$A$6:$ZZ$1048576"), MATCH(AY$1, JulR!$6:$6, 0), FALSE), 0 ) + IFERROR( VLOOKUP($A10, INDIRECT("AgoR!$A$6:$ZZ$1048576"), MATCH(AY$1, AgoR!$6:$6, 0), FALSE), 0 ) + IFERROR( VLOOKUP($A10, INDIRECT("SepR!$A$6:$ZZ$1048576"), MATCH(AY$1, SepR!$6:$6, 0), FALSE), 0 ) + IFERROR( VLOOKUP($A10, INDIRECT("OctR!$A$6:$ZZ$1048576"), MATCH(AY$1, OctR!$6:$6, 0), FALSE), 0 ) + IFERROR( VLOOKUP($A10, INDIRECT("NovR!$A$6:$ZZ$1048576"), MATCH(AY$1, NovR!$6:$6, 0), FALSE), 0 ) + IFERROR( VLOOKUP($A10, INDIRECT("DicR!$A$6:$ZZ$1048576"), MATCH(AY$1, DicR!$6:$6, 0), FALSE), 0 ) )} -> 0
A11: =Menus!R3 | B11: =IFERROR(SUM(D11:AZ11),"") -> 0 | C11: =IFERROR(INDEX($D$1:$AQ128, MATCH($A11, $A$1:$A128, 0), MATCH(C$1, $D$1:AZ$1, 0)), "") | D11: {=SUM( IFERROR( VLOOKUP($A11, INDIRECT("EneR!$A$6:$ZZ$1048576"), MATCH(D$1, EneR!$6:$6, 0), FALSE), 0 ) + IFERROR( VLOOKUP($A11, INDIRECT("FebR!$A$6:$ZZ$1048576"), MATCH(D$1, FebR!$6:$6, 0), FALSE), 0 ) + IFERROR( VLOOKUP($A11, INDIRECT("MarR!$A$6:$ZZ$1048576"), MATCH(D$1, MarR!$6:$6, 0), FALSE), 0 ) + IFERROR( VLOOKUP($A11, INDIRECT("AbrR!$A$6:$ZZ$1048576"), MATCH(D$1, AbrR!$6:$6, 0), FALSE), 0 ) + IFERROR( VLOOKUP($A11, INDIRECT("MayR!$A$6:$ZZ$1048576"), MATCH(D$1, MayR!$6:$6, 0), FALSE), 0 ) + IFERROR( VLOOKUP($A11, INDIRECT("JunR!$A$6:$ZZ$1048576"), MATCH(D$1, JunR!$6:$6, 0), FALSE), 0 ) + IFERROR( VLOOKUP($A11, INDIRECT("JulR!$A$6:$ZZ$1048576"), MATCH(D$1, JulR!$6:$6, 0), FALSE), 0 ) + IFERROR( VLOOKUP($A11, INDIRECT("AgoR!$A$6:$ZZ$1048576"), MATCH(D$1, AgoR!$6:$6, 0), FALSE), 0 ) + IFERROR( VLOOKUP($A11, INDIRECT("SepR!$A$6:$ZZ$1048576"), MATCH(D$1, SepR!$6:$6, 0), FALSE), 0 ) + IFERROR( VLOOKUP($A11, INDIRECT("OctR!$A$6:$ZZ$1048576"), MATCH(D$1, OctR!$6:$6, 0), FALSE), 0 ) + IFERROR( VLOOKUP($A11, INDIRECT("NovR!$A$6:$ZZ$1048576"), MATCH(D$1, NovR!$6:$6, 0), FALSE), 0 ) + IFERROR( VLOOKUP($A11, INDIRECT("DicR!$A$6:$ZZ$1048576"), MATCH(D$1, DicR!$6:$6, 0), FALSE), 0 ) )} -> 0 | E11: {=SUM( IFERROR( VLOOKUP($A11, INDIRECT("EneR!$A$6:$ZZ$1048576"), MATCH(E$1, EneR!$6:$6, 0), FALSE), 0 ) + IFERROR( VLOOKUP($A11, INDIRECT("FebR!$A$6:$ZZ$1048576"), MATCH(E$1, FebR!$6:$6, 0), FALSE), 0 ) + IFERROR( VLOOKUP($A11, INDIRECT("MarR!$A$6:$ZZ$1048576"), MATCH(E$1, MarR!$6:$6, 0), FALSE), 0 ) + IFERROR( VLOOKUP($A11, INDIRECT("AbrR!$A$6:$ZZ$1048576"), MATCH(E$1, AbrR!$6:$6, 0), FALSE), 0 ) + IFERROR( VLOOKUP($A11, INDIRECT("MayR!$A$6:$ZZ$1048576"), MATCH(E$1, MayR!$6:$6, 0), FALSE), 0 ) + IFERROR( VLOOKUP($A11, INDIRECT("JunR!$A$6:$ZZ$1048576"), MATCH(E$1, JunR!$6:$6, 0), FALSE), 0 ) + IFERROR( VLOOKUP($A11, INDIRECT("JulR!$A$6:$ZZ$1048576"), MATCH(E$1, JulR!$6:$6, 0), FALSE), 0 ) + IFERROR( VLOOKUP($A11, INDIRECT("AgoR!$A$6:$ZZ$1048576"), MATCH(E$1, AgoR!$6:$6, 0), FALSE), 0 ) + IFERROR( VLOOKUP($A11, INDIRECT("SepR!$A$6:$ZZ$1048576"), MATCH(E$1, SepR!$6:$6, 0), FALSE), 0 ) + IFERROR( VLOOKUP($A11, INDIRECT("OctR!$A$6:$ZZ$1048576"), MATCH(E$1, OctR!$6:$6, 0), FALSE), 0 ) + IFERROR( VLOOKUP($A11, INDIRECT("NovR!$A$6:$ZZ$1048576"), MATCH(E$1, NovR!$6:$6, 0), FALSE), 0 ) + IFERROR( VLOOKUP($A11, INDIRECT("DicR!$A$6:$ZZ$1048576"), MATCH(E$1, DicR!$6:$6, 0), FALSE), 0 ) )} -> 0 | F11: {=SUM( IFERROR( VLOOKUP($A11, INDIRECT("EneR!$A$6:$ZZ$1048576"), MATCH(F$1, EneR!$6:$6, 0), FALSE), 0 ) + IFERROR( VLOOKUP($A11, INDIRECT("FebR!$A$6:$ZZ$1048576"), MATCH(F$1, FebR!$6:$6, 0), FALSE), 0 ) + IFERROR( VLOOKUP($A11, INDIRECT("MarR!$A$6:$ZZ$1048576"), MATCH(F$1, MarR!$6:$6, 0), FALSE), 0 ) + IFERROR( VLOOKUP($A11, INDIRECT("AbrR!$A$6:$ZZ$1048576"), MATCH(F$1, AbrR!$6:$6, 0), FALSE), 0 ) + IFERROR( VLOOKUP($A11, INDIRECT("MayR!$A$6:$ZZ$1048576"), MATCH(F$1, MayR!$6:$6, 0), FALSE), 0 ) + IFERROR( VLOOKUP($A11, INDIRECT("JunR!$A$6:$ZZ$1048576"), MATCH(F$1, JunR!$6:$6, 0), FALSE), 0 ) + IFERROR( VLOOKUP($A11, INDIRECT("JulR!$A$6:$ZZ$1048576"), MATCH(F$1, JulR!$6:$6, 0), FALSE), 0 ) + IFERROR( VLOOKUP($A11, INDIRECT("AgoR!$A$6:$ZZ$1048576"), MATCH(F$1, AgoR!$6:$6, 0), FALSE), 0 ) + IFERROR( VLOOKUP($A11, INDIRECT("SepR!$A$6:$ZZ$1048576"), MATCH(F$1, SepR!$6:$6, 0), FALSE), 0 ) + IFERROR( VLOOKUP($A11, INDIRECT("OctR!$A$6:$ZZ$1048576"), MATCH(F$1, OctR!$6:$6, 0), FALSE), 0 ) + IFERROR( VLOOKUP($A11, INDIRECT("NovR!$A$6:$ZZ$1048576"), MATCH(F$1, NovR!$6:$6, 0), FALSE), 0 ) + IFERROR( VLOOKUP($A11, INDIRECT("DicR!$A$6:$ZZ$1048576"), MATCH(F$1, DicR!$6:$6, 0), FALSE), 0 ) )} -> 0 | G11: {=SUM( IFERROR( VLOOKUP($A11, INDIRECT("EneR!$A$6:$ZZ$1048576"), MATCH(G$1, EneR!$6:$6, 0), FALSE), 0 ) + IFERROR( VLOOKUP($A11, INDIRECT("FebR!$A$6:$ZZ$1048576"), MATCH(G$1, FebR!$6:$6, 0), FALSE), 0 ) + IFERROR( VLOOKUP($A11, INDIRECT("MarR!$A$6:$ZZ$1048576"), MATCH(G$1, MarR!$6:$6, 0), FALSE), 0 ) + IFERROR( VLOOKUP($A11, INDIRECT("AbrR!$A$6:$ZZ$1048576"), MATCH(G$1, AbrR!$6:$6, 0), FALSE), 0 ) + IFERROR( VLOOKUP($A11, INDIRECT("MayR!$A$6:$ZZ$1048576"), MATCH(G$1, MayR!$6:$6, 0), FALSE), 0 ) + IFERROR( VLOOKUP($A11, INDIRECT("JunR!$A$6:$ZZ$1048576"), MATCH(G$1, JunR!$6:$6, 0), FALSE), 0 ) + IFERROR( VLOOKUP($A11, INDIRECT("JulR!$A$6:$ZZ$1048576"), MATCH(G$1, JulR!$6:$6, 0), FALSE), 0 ) + IFERROR( VLOOKUP($A11, INDIRECT("AgoR!$A$6:$ZZ$1048576"), MATCH(G$1, AgoR!$6:$6, 0), FALSE), 0 ) + IFERROR( VLOOKUP($A11, INDIRECT("SepR!$A$6:$ZZ$1048576"), MATCH(G$1, SepR!$6:$6, 0), FALSE), 0 ) + IFERROR( VLOOKUP($A11, INDIRECT("OctR!$A$6:$ZZ$1048576"), MATCH(G$1, OctR!$6:$6, 0), FALSE), 0 ) + IFERROR( VLOOKUP($A11, INDIRECT("NovR!$A$6:$ZZ$1048576"), MATCH(G$1, NovR!$6:$6, 0), FALSE), 0 ) + IFERROR( VLOOKUP($A11, INDIRECT("DicR!$A$6:$ZZ$1048576"), MATCH(G$1, DicR!$6:$6, 0), FALSE), 0 ) )} -> 0 | H11: {=SUM( IFERROR( VLOOKUP($A11, INDIRECT("EneR!$A$6:$ZZ$1048576"), MATCH(H$1, EneR!$6:$6, 0), FALSE), 0 ) + IFERROR( VLOOKUP($A11, INDIRECT("FebR!$A$6:$ZZ$1048576"), MATCH(H$1, FebR!$6:$6, 0), FALSE), 0 ) + IFERROR( VLOOKUP($A11, INDIRECT("MarR!$A$6:$ZZ$1048576"), MATCH(H$1, MarR!$6:$6, 0), FALSE), 0 ) + IFERROR( VLOOKUP($A11, INDIRECT("AbrR!$A$6:$ZZ$1048576"), MATCH(H$1, AbrR!$6:$6, 0), FALSE), 0 ) + IFERROR( VLOOKUP($A11, INDIRECT("MayR!$A$6:$ZZ$1048576"), MATCH(H$1, MayR!$6:$6, 0), FALSE), 0 ) + IFERROR( VLOOKUP($A11, INDIRECT("JunR!$A$6:$ZZ$1048576"), MATCH(H$1, JunR!$6:$6, 0), FALSE), 0 ) + IFERROR( VLOOKUP($A11, INDIRECT("JulR!$A$6:$ZZ$1048576"), MATCH(H$1, JulR!$6:$6, 0), FALSE), 0 ) + IFERROR( VLOOKUP($A11, INDIRECT("AgoR!$A$6:$ZZ$1048576"), MATCH(H$1, AgoR!$6:$6, 0), FALSE), 0 ) + IFERROR( VLOOKUP($A11, INDIRECT("SepR!$A$6:$ZZ$1048576"), MATCH(H$1, SepR!$6:$6, 0), FALSE), 0 ) + IFERROR( VLOOKUP($A11, INDIRECT("OctR!$A$6:$ZZ$1048576"), MATCH(H$1, OctR!$6:$6, 0), FALSE), 0 ) + IFERROR( VLOOKUP($A11, INDIRECT("NovR!$A$6:$ZZ$1048576"), MATCH(H$1, NovR!$6:$6, 0), FALSE), 0 ) + IFERROR( VLOOKUP($A11, INDIRECT("DicR!$A$6:$ZZ$1048576"), MATCH(H$1, DicR!$6:$6, 0), FALSE), 0 ) )} -> 0 | I11: {=SUM( IFERROR( VLOOKUP($A11, INDIRECT("EneR!$A$6:$ZZ$1048576"), MATCH(I$1, EneR!$6:$6, 0), FALSE), 0 ) + IFERROR( VLOOKUP($A11, INDIRECT("FebR!$A$6:$ZZ$1048576"), MATCH(I$1, FebR!$6:$6, 0), FALSE), 0 ) + IFERROR( VLOOKUP($A11, INDIRECT("MarR!$A$6:$ZZ$1048576"), MATCH(I$1, MarR!$6:$6, 0), FALSE), 0 ) + IFERROR( VLOOKUP($A11, INDIRECT("AbrR!$A$6:$ZZ$1048576"), MATCH(I$1, AbrR!$6:$6, 0), FALSE), 0 ) + IFERROR( VLOOKUP($A11, INDIRECT("MayR!$A$6:$ZZ$1048576"), MATCH(I$1, MayR!$6:$6, 0), FALSE), 0 ) + IFERROR( VLOOKUP($A11, INDIRECT("JunR!$A$6:$ZZ$1048576"), MATCH(I$1, JunR!$6:$6, 0), FALSE), 0 ) + IFERROR( VLOOKUP($A11, INDIRECT("JulR!$A$6:$ZZ$1048576"), MATCH(I$1, JulR!$6:$6, 0), FALSE), 0 ) + IFERROR( VLOOKUP($A11, INDIRECT("AgoR!$A$6:$ZZ$1048576"), MATCH(I$1, AgoR!$6:$6, 0), FALSE), 0 ) + IFERROR( VLOOKUP($A11, INDIRECT("SepR!$A$6:$ZZ$1048576"), MATCH(I$1, SepR!$6:$6, 0), FALSE), 0 ) + IFERROR( VLOOKUP($A11, INDIRECT("OctR!$A$6:$ZZ$1048576"), MATCH(I$1, OctR!$6:$6, 0), FALSE), 0 ) + IFERROR( VLOOKUP($A11, INDIRECT("NovR!$A$6:$ZZ$1048576"), MATCH(I$1, NovR!$6:$6, 0), FALSE), 0 ) + IFERROR( VLOOKUP($A11, INDIRECT("DicR!$A$6:$ZZ$1048576"), MATCH(I$1, DicR!$6:$6, 0), FALSE), 0 ) )} -> 0 | J11: {=SUM( IFERROR( VLOOKUP($A11, INDIRECT("EneR!$A$6:$ZZ$1048576"), MATCH(J$1, EneR!$6:$6, 0), FALSE), 0 ) + IFERROR( VLOOKUP($A11, INDIRECT("FebR!$A$6:$ZZ$1048576"), MATCH(J$1, FebR!$6:$6, 0), FALSE), 0 ) + IFERROR( VLOOKUP($A11, INDIRECT("MarR!$A$6:$ZZ$1048576"), MATCH(J$1, MarR!$6:$6, 0), FALSE), 0 ) + IFERROR( VLOOKUP($A11, INDIRECT("AbrR!$A$6:$ZZ$1048576"), MATCH(J$1, AbrR!$6:$6, 0), FALSE), 0 ) + IFERROR( VLOOKUP($A11, INDIRECT("MayR!$A$6:$ZZ$1048576"), MATCH(J$1, MayR!$6:$6, 0), FALSE), 0 ) + IFERROR( VLOOKUP($A11, INDIRECT("JunR!$A$6:$ZZ$1048576"), MATCH(J$1, JunR!$6:$6, 0), FALSE), 0 ) + IFERROR( VLOOKUP($A11, INDIRECT("JulR!$A$6:$ZZ$1048576"), MATCH(J$1, JulR!$6:$6, 0), FALSE), 0 ) + IFERROR( VLOOKUP($A11, INDIRECT("AgoR!$A$6:$ZZ$1048576"), MATCH(J$1, AgoR!$6:$6, 0), FALSE), 0 ) + IFERROR( VLOOKUP($A11, INDIRECT("SepR!$A$6:$ZZ$1048576"), MATCH(J$1, SepR!$6:$6, 0), FALSE), 0 ) + IFERROR( VLOOKUP($A11, INDIRECT("OctR!$A$6:$ZZ$1048576"), MATCH(J$1, OctR!$6:$6, 0), FALSE), 0 ) + IFERROR( VLOOKUP($A11, INDIRECT("NovR!$A$6:$ZZ$1048576"), MATCH(J$1, NovR!$6:$6, 0), FALSE), 0 ) + IFERROR( VLOOKUP($A11, INDIRECT("DicR!$A$6:$ZZ$1048576"), MATCH(J$1, DicR!$6:$6, 0), FALSE), 0 ) )} -> 0 | K11: {=SUM( IFERROR( VLOOKUP($A11, INDIRECT("EneR!$A$6:$ZZ$1048576"), MATCH(K$1, EneR!$6:$6, 0), FALSE), 0 ) + IFERROR( VLOOKUP($A11, INDIRECT("FebR!$A$6:$ZZ$1048576"), MATCH(K$1, FebR!$6:$6, 0), FALSE), 0 ) + IFERROR( VLOOKUP($A11, INDIRECT("MarR!$A$6:$ZZ$1048576"), MATCH(K$1, MarR!$6:$6, 0), FALSE), 0 ) + IFERROR( VLOOKUP($A11, INDIRECT("AbrR!$A$6:$ZZ$1048576"), MATCH(K$1, AbrR!$6:$6, 0), FALSE), 0 ) + IFERROR( VLOOKUP($A11, INDIRECT("MayR!$A$6:$ZZ$1048576"), MATCH(K$1, MayR!$6:$6, 0), FALSE), 0 ) + IFERROR( VLOOKUP($A11, INDIRECT("JunR!$A$6:$ZZ$1048576"), MATCH(K$1, JunR!$6:$6, 0), FALSE), 0 ) + IFERROR( VLOOKUP($A11, INDIRECT("JulR!$A$6:$ZZ$1048576"), MATCH(K$1, JulR!$6:$6, 0), FALSE), 0 ) + IFERROR( VLOOKUP($A11, INDIRECT("AgoR!$A$6:$ZZ$1048576"), MATCH(K$1, AgoR!$6:$6, 0), FALSE), 0 ) + IFERROR( VLOOKUP($A11, INDIRECT("SepR!$A$6:$ZZ$1048576"), MATCH(K$1, SepR!$6:$6, 0), FALSE), 0 ) + IFERROR( VLOOKUP($A11, INDIRECT("OctR!$A$6:$ZZ$1048576"), MATCH(K$1, OctR!$6:$6, 0), FALSE), 0 ) + IFERROR( VLOOKUP($A11, INDIRECT("NovR!$A$6:$ZZ$1048576"), MATCH(K$1, NovR!$6:$6, 0), FALSE), 0 ) + IFERROR( VLOOKUP($A11, INDIRECT("DicR!$A$6:$ZZ$1048576"), MATCH(K$1, DicR!$6:$6, 0), FALSE), 0 ) )} -> 0 | ... AY11: {=SUM( IFERROR( VLOOKUP($A11, INDIRECT("EneR!$A$6:$ZZ$1048576"), MATCH(AY$1, EneR!$6:$6, 0), FALSE), 0 ) + IFERROR( VLOOKUP($A11, INDIRECT("FebR!$A$6:$ZZ$1048576"), MATCH(AY$1, FebR!$6:$6, 0), FALSE), 0 ) + IFERROR( VLOOKUP($A11, INDIRECT("MarR!$A$6:$ZZ$1048576"), MATCH(AY$1, MarR!$6:$6, 0), FALSE), 0 ) + IFERROR( VLOOKUP($A11, INDIRECT("AbrR!$A$6:$ZZ$1048576"), MATCH(AY$1, AbrR!$6:$6, 0), FALSE), 0 ) + IFERROR( VLOOKUP($A11, INDIRECT("MayR!$A$6:$ZZ$1048576"), MATCH(AY$1, MayR!$6:$6, 0), FALSE), 0 ) + IFERROR( VLOOKUP($A11, INDIRECT("JunR!$A$6:$ZZ$1048576"), MATCH(AY$1, JunR!$6:$6, 0), FALSE), 0 ) + IFERROR( VLOOKUP($A11, INDIRECT("JulR!$A$6:$ZZ$1048576"), MATCH(AY$1, JulR!$6:$6, 0), FALSE), 0 ) + IFERROR( VLOOKUP($A11, INDIRECT("AgoR!$A$6:$ZZ$1048576"), MATCH(AY$1, AgoR!$6:$6, 0), FALSE), 0 ) + IFERROR( VLOOKUP($A11, INDIRECT("SepR!$A$6:$ZZ$1048576"), MATCH(AY$1, SepR!$6:$6, 0), FALSE), 0 ) + IFERROR( VLOOKUP($A11, INDIRECT("OctR!$A$6:$ZZ$1048576"), MATCH(AY$1, OctR!$6:$6, 0), FALSE), 0 ) + IFERROR( VLOOKUP($A11, INDIRECT("NovR!$A$6:$ZZ$1048576"), MATCH(AY$1, NovR!$6:$6, 0), FALSE), 0 ) + IFERROR( VLOOKUP($A11, INDIRECT("DicR!$A$6:$ZZ$1048576"), MATCH(AY$1, DicR!$6:$6, 0), FALSE), 0 ) )} -> 0
A12: =Menus!R4 | B12: =IFERROR(SUM(D12:AZ12),"") -> 0 | C12: =IFERROR(INDEX($D$1:$AQ129, MATCH($A12, $A$1:$A129, 0), MATCH(C$1, $D$1:AZ$1, 0)), "") | D12: {=SUM( IFERROR( VLOOKUP($A12, INDIRECT("EneR!$A$6:$ZZ$1048576"), MATCH(D$1, EneR!$6:$6, 0), FALSE), 0 ) + IFERROR( VLOOKUP($A12, INDIRECT("FebR!$A$6:$ZZ$1048576"), MATCH(D$1, FebR!$6:$6, 0), FALSE), 0 ) + IFERROR( VLOOKUP($A12, INDIRECT("MarR!$A$6:$ZZ$1048576"), MATCH(D$1, MarR!$6:$6, 0), FALSE), 0 ) + IFERROR( VLOOKUP($A12, INDIRECT("AbrR!$A$6:$ZZ$1048576"), MATCH(D$1, AbrR!$6:$6, 0), FALSE), 0 ) + IFERROR( VLOOKUP($A12, INDIRECT("MayR!$A$6:$ZZ$1048576"), MATCH(D$1, MayR!$6:$6, 0), FALSE), 0 ) + IFERROR( VLOOKUP($A12, INDIRECT("JunR!$A$6:$ZZ$1048576"), MATCH(D$1, JunR!$6:$6, 0), FALSE), 0 ) + IFERROR( VLOOKUP($A12, INDIRECT("JulR!$A$6:$ZZ$1048576"), MATCH(D$1, JulR!$6:$6, 0), FALSE), 0 ) + IFERROR( VLOOKUP($A12, INDIRECT("AgoR!$A$6:$ZZ$1048576"), MATCH(D$1, AgoR!$6:$6, 0), FALSE), 0 ) + IFERROR( VLOOKUP($A12, INDIRECT("SepR!$A$6:$ZZ$1048576"), MATCH(D$1, SepR!$6:$6, 0), FALSE), 0 ) + IFERROR( VLOOKUP($A12, INDIRECT("OctR!$A$6:$ZZ$1048576"), MATCH(D$1, OctR!$6:$6, 0), FALSE), 0 ) + IFERROR( VLOOKUP($A12, INDIRECT("NovR!$A$6:$ZZ$1048576"), MATCH(D$1, NovR!$6:$6, 0), FALSE), 0 ) + IFERROR( VLOOKUP($A12, INDIRECT("DicR!$A$6:$ZZ$1048576"), MATCH(D$1, DicR!$6:$6, 0), FALSE), 0 ) )} -> 0 | E12: {=SUM( IFERROR( VLOOKUP($A12, INDIRECT("EneR!$A$6:$ZZ$1048576"), MATCH(E$1, EneR!$6:$6, 0), FALSE), 0 ) + IFERROR( VLOOKUP($A12, INDIRECT("FebR!$A$6:$ZZ$1048576"), MATCH(E$1, FebR!$6:$6, 0), FALSE), 0 ) + IFERROR( VLOOKUP($A12, INDIRECT("MarR!$A$6:$ZZ$1048576"), MATCH(E$1, MarR!$6:$6, 0), FALSE), 0 ) + IFERROR( VLOOKUP($A12, INDIRECT("AbrR!$A$6:$ZZ$1048576"), MATCH(E$1, AbrR!$6:$6, 0), FALSE), 0 ) + IFERROR( VLOOKUP($A12, INDIRECT("MayR!$A$6:$ZZ$1048576"), MATCH(E$1, MayR!$6:$6, 0), FALSE), 0 ) + IFERROR( VLOOKUP($A12, INDIRECT("JunR!$A$6:$ZZ$1048576"), MATCH(E$1, JunR!$6:$6, 0), FALSE), 0 ) + IFERROR( VLOOKUP($A12, INDIRECT("JulR!$A$6:$ZZ$1048576"), MATCH(E$1, JulR!$6:$6, 0), FALSE), 0 ) + IFERROR( VLOOKUP($A12, INDIRECT("AgoR!$A$6:$ZZ$1048576"), MATCH(E$1, AgoR!$6:$6, 0), FALSE), 0 ) + IFERROR( VLOOKUP($A12, INDIRECT("SepR!$A$6:$ZZ$1048576"), MATCH(E$1, SepR!$6:$6, 0), FALSE), 0 ) + IFERROR( VLOOKUP($A12, INDIRECT("OctR!$A$6:$ZZ$1048576"), MATCH(E$1, OctR!$6:$6, 0), FALSE), 0 ) + IFERROR( VLOOKUP($A12, INDIRECT("NovR!$A$6:$ZZ$1048576"), MATCH(E$1, NovR!$6:$6, 0), FALSE), 0 ) + IFERROR( VLOOKUP($A12, INDIRECT("DicR!$A$6:$ZZ$1048576"), MATCH(E$1, DicR!$6:$6, 0), FALSE), 0 ) )} -> 0 | F12: {=SUM( IFERROR( VLOOKUP($A12, INDIRECT("EneR!$A$6:$ZZ$1048576"), MATCH(F$1, EneR!$6:$6, 0), FALSE), 0 ) + IFERROR( VLOOKUP($A12, INDIRECT("FebR!$A$6:$ZZ$1048576"), MATCH(F$1, FebR!$6:$6, 0), FALSE), 0 ) + IFERROR( VLOOKUP($A12, INDIRECT("MarR!$A$6:$ZZ$1048576"), MATCH(F$1, MarR!$6:$6, 0), FALSE), 0 ) + IFERROR( VLOOKUP($A12, INDIRECT("AbrR!$A$6:$ZZ$1048576"), MATCH(F$1, AbrR!$6:$6, 0), FALSE), 0 ) + IFERROR( VLOOKUP($A12, INDIRECT("MayR!$A$6:$ZZ$1048576"), MATCH(F$1, MayR!$6:$6, 0), FALSE), 0 ) + IFERROR( VLOOKUP($A12, INDIRECT("JunR!$A$6:$ZZ$1048576"), MATCH(F$1, JunR!$6:$6, 0), FALSE), 0 ) + IFERROR( VLOOKUP($A12, INDIRECT("JulR!$A$6:$ZZ$1048576"), MATCH(F$1, JulR!$6:$6, 0), FALSE), 0 ) + IFERROR( VLOOKUP($A12, INDIRECT("AgoR!$A$6:$ZZ$1048576"), MATCH(F$1, AgoR!$6:$6, 0), FALSE), 0 ) + IFERROR( VLOOKUP($A12, INDIRECT("SepR!$A$6:$ZZ$1048576"), MATCH(F$1, SepR!$6:$6, 0), FALSE), 0 ) + IFERROR( VLOOKUP($A12, INDIRECT("OctR!$A$6:$ZZ$1048576"), MATCH(F$1, OctR!$6:$6, 0), FALSE), 0 ) + IFERROR( VLOOKUP($A12, INDIRECT("NovR!$A$6:$ZZ$1048576"), MATCH(F$1, NovR!$6:$6, 0), FALSE), 0 ) + IFERROR( VLOOKUP($A12, INDIRECT("DicR!$A$6:$ZZ$1048576"), MATCH(F$1, DicR!$6:$6, 0), FALSE), 0 ) )} -> 0 | G12: {=SUM( IFERROR( VLOOKUP($A12, INDIRECT("EneR!$A$6:$ZZ$1048576"), MATCH(G$1, EneR!$6:$6, 0), FALSE), 0 ) + IFERROR( VLOOKUP($A12, INDIRECT("FebR!$A$6:$ZZ$1048576"), MATCH(G$1, FebR!$6:$6, 0), FALSE), 0 ) + IFERROR( VLOOKUP($A12, INDIRECT("MarR!$A$6:$ZZ$1048576"), MATCH(G$1, MarR!$6:$6, 0), FALSE), 0 ) + IFERROR( VLOOKUP($A12, INDIRECT("AbrR!$A$6:$ZZ$1048576"), MATCH(G$1, AbrR!$6:$6, 0), FALSE), 0 ) + IFERROR( VLOOKUP($A12, INDIRECT("MayR!$A$6:$ZZ$1048576"), MATCH(G$1, MayR!$6:$6, 0), FALSE), 0 ) + IFERROR( VLOOKUP($A12, INDIRECT("JunR!$A$6:$ZZ$1048576"), MATCH(G$1, JunR!$6:$6, 0), FALSE), 0 ) + IFERROR( VLOOKUP($A12, INDIRECT("JulR!$A$6:$ZZ$1048576"), MATCH(G$1, JulR!$6:$6, 0), FALSE), 0 ) + IFERROR( VLOOKUP($A12, INDIRECT("AgoR!$A$6:$ZZ$1048576"), MATCH(G$1, AgoR!$6:$6, 0), FALSE), 0 ) + IFERROR( VLOOKUP($A12, INDIRECT("SepR!$A$6:$ZZ$1048576"), MATCH(G$1, SepR!$6:$6, 0), FALSE), 0 ) + IFERROR( VLOOKUP($A12, INDIRECT("OctR!$A$6:$ZZ$1048576"), MATCH(G$1, OctR!$6:$6, 0), FALSE), 0 ) + IFERROR( VLOOKUP($A12, INDIRECT("NovR!$A$6:$ZZ$1048576"), MATCH(G$1, NovR!$6:$6, 0), FALSE), 0 ) + IFERROR( VLOOKUP($A12, INDIRECT("DicR!$A$6:$ZZ$1048576"), MATCH(G$1, DicR!$6:$6, 0), FALSE), 0 ) )} -> 0 | H12: {=SUM( IFERROR( VLOOKUP($A12, INDIRECT("EneR!$A$6:$ZZ$1048576"), MATCH(H$1, EneR!$6:$6, 0), FALSE), 0 ) + IFERROR( VLOOKUP($A12, INDIRECT("FebR!$A$6:$ZZ$1048576"), MATCH(H$1, FebR!$6:$6, 0), FALSE), 0 ) + IFERROR( VLOOKUP($A12, INDIRECT("MarR!$A$6:$ZZ$1048576"), MATCH(H$1, MarR!$6:$6, 0), FALSE), 0 ) + IFERROR( VLOOKUP($A12, INDIRECT("AbrR!$A$6:$ZZ$1048576"), MATCH(H$1, AbrR!$6:$6, 0), FALSE), 0 ) + IFERROR( VLOOKUP($A12, INDIRECT("MayR!$A$6:$ZZ$1048576"), MATCH(H$1, MayR!$6:$6, 0), FALSE), 0 ) + IFERROR( VLOOKUP($A12, INDIRECT("JunR!$A$6:$ZZ$1048576"), MATCH(H$1, JunR!$6:$6, 0), FALSE), 0 ) + IFERROR( VLOOKUP($A12, INDIRECT("JulR!$A$6:$ZZ$1048576"), MATCH(H$1, JulR!$6:$6, 0), FALSE), 0 ) + IFERROR( VLOOKUP($A12, INDIRECT("AgoR!$A$6:$ZZ$1048576"), MATCH(H$1, AgoR!$6:$6, 0), FALSE), 0 ) + IFERROR( VLOOKUP($A12, INDIRECT("SepR!$A$6:$ZZ$1048576"), MATCH(H$1, SepR!$6:$6, 0), FALSE), 0 ) + IFERROR( VLOOKUP($A12, INDIRECT("OctR!$A$6:$ZZ$1048576"), MATCH(H$1, OctR!$6:$6, 0), FALSE), 0 ) + IFERROR( VLOOKUP($A12, INDIRECT("NovR!$A$6:$ZZ$1048576"), MATCH(H$1, NovR!$6:$6, 0), FALSE), 0 ) + IFERROR( VLOOKUP($A12, INDIRECT("DicR!$A$6:$ZZ$1048576"), MATCH(H$1, DicR!$6:$6, 0), FALSE), 0 ) )} -> 0 | I12: {=SUM( IFERROR( VLOOKUP($A12, INDIRECT("EneR!$A$6:$ZZ$1048576"), MATCH(I$1, EneR!$6:$6, 0), FALSE), 0 ) + IFERROR( VLOOKUP($A12, INDIRECT("FebR!$A$6:$ZZ$1048576"), MATCH(I$1, FebR!$6:$6, 0), FALSE), 0 ) + IFERROR( VLOOKUP($A12, INDIRECT("MarR!$A$6:$ZZ$1048576"), MATCH(I$1, MarR!$6:$6, 0), FALSE), 0 ) + IFERROR( VLOOKUP($A12, INDIRECT("AbrR!$A$6:$ZZ$1048576"), MATCH(I$1, AbrR!$6:$6, 0), FALSE), 0 ) + IFERROR( VLOOKUP($A12, INDIRECT("MayR!$A$6:$ZZ$1048576"), MATCH(I$1, MayR!$6:$6, 0), FALSE), 0 ) + IFERROR( VLOOKUP($A12, INDIRECT("JunR!$A$6:$ZZ$1048576"), MATCH(I$1, JunR!$6:$6, 0), FALSE), 0 ) + IFERROR( VLOOKUP($A12, INDIRECT("JulR!$A$6:$ZZ$1048576"), MATCH(I$1, JulR!$6:$6, 0), FALSE), 0 ) + IFERROR( VLOOKUP($A12, INDIRECT("AgoR!$A$6:$ZZ$1048576"), MATCH(I$1, AgoR!$6:$6, 0), FALSE), 0 ) + IFERROR( VLOOKUP($A12, INDIRECT("SepR!$A$6:$ZZ$1048576"), MATCH(I$1, SepR!$6:$6, 0), FALSE), 0 ) + IFERROR( VLOOKUP($A12, INDIRECT("OctR!$A$6:$ZZ$1048576"), MATCH(I$1, OctR!$6:$6, 0), FALSE), 0 ) + IFERROR( VLOOKUP($A12, INDIRECT("NovR!$A$6:$ZZ$1048576"), MATCH(I$1, NovR!$6:$6, 0), FALSE), 0 ) + IFERROR( VLOOKUP($A12, INDIRECT("DicR!$A$6:$ZZ$1048576"), MATCH(I$1, DicR!$6:$6, 0), FALSE), 0 ) )} -> 0 | J12: {=SUM( IFERROR( VLOOKUP($A12, INDIRECT("EneR!$A$6:$ZZ$1048576"), MATCH(J$1, EneR!$6:$6, 0), FALSE), 0 ) + IFERROR( VLOOKUP($A12, INDIRECT("FebR!$A$6:$ZZ$1048576"), MATCH(J$1, FebR!$6:$6, 0), FALSE), 0 ) + IFERROR( VLOOKUP($A12, INDIRECT("MarR!$A$6:$ZZ$1048576"), MATCH(J$1, MarR!$6:$6, 0), FALSE), 0 ) + IFERROR( VLOOKUP($A12, INDIRECT("AbrR!$A$6:$ZZ$1048576"), MATCH(J$1, AbrR!$6:$6, 0), FALSE), 0 ) + IFERROR( VLOOKUP($A12, INDIRECT("MayR!$A$6:$ZZ$1048576"), MATCH(J$1, MayR!$6:$6, 0), FALSE), 0 ) + IFERROR( VLOOKUP($A12, INDIRECT("JunR!$A$6:$ZZ$1048576"), MATCH(J$1, JunR!$6:$6, 0), FALSE), 0 ) + IFERROR( VLOOKUP($A12, INDIRECT("JulR!$A$6:$ZZ$1048576"), MATCH(J$1, JulR!$6:$6, 0), FALSE), 0 ) + IFERROR( VLOOKUP($A12, INDIRECT("AgoR!$A$6:$ZZ$1048576"), MATCH(J$1, AgoR!$6:$6, 0), FALSE), 0 ) + IFERROR( VLOOKUP($A12, INDIRECT("SepR!$A$6:$ZZ$1048576"), MATCH(J$1, SepR!$6:$6, 0), FALSE), 0 ) + IFERROR( VLOOKUP($A12, INDIRECT("OctR!$A$6:$ZZ$1048576"), MATCH(J$1, OctR!$6:$6, 0), FALSE), 0 ) + IFERROR( VLOOKUP($A12, INDIRECT("NovR!$A$6:$ZZ$1048576"), MATCH(J$1, NovR!$6:$6, 0), FALSE), 0 ) + IFERROR( VLOOKUP($A12, INDIRECT("DicR!$A$6:$ZZ$1048576"), MATCH(J$1, DicR!$6:$6, 0), FALSE), 0 ) )} -> 0 | K12: {=SUM( IFERROR( VLOOKUP($A12, INDIRECT("EneR!$A$6:$ZZ$1048576"), MATCH(K$1, EneR!$6:$6, 0), FALSE), 0 ) + IFERROR( VLOOKUP($A12, INDIRECT("FebR!$A$6:$ZZ$1048576"), MATCH(K$1, FebR!$6:$6, 0), FALSE), 0 ) + IFERROR( VLOOKUP($A12, INDIRECT("MarR!$A$6:$ZZ$1048576"), MATCH(K$1, MarR!$6:$6, 0), FALSE), 0 ) + IFERROR( VLOOKUP($A12, INDIRECT("AbrR!$A$6:$ZZ$1048576"), MATCH(K$1, AbrR!$6:$6, 0), FALSE), 0 ) + IFERROR( VLOOKUP($A12, INDIRECT("MayR!$A$6:$ZZ$1048576"), MATCH(K$1, MayR!$6:$6, 0), FALSE), 0 ) + IFERROR( VLOOKUP($A12, INDIRECT("JunR!$A$6:$ZZ$1048576"), MATCH(K$1, JunR!$6:$6, 0), FALSE), 0 ) + IFERROR( VLOOKUP($A12, INDIRECT("JulR!$A$6:$ZZ$1048576"), MATCH(K$1, JulR!$6:$6, 0), FALSE), 0 ) + IFERROR( VLOOKUP($A12, INDIRECT("AgoR!$A$6:$ZZ$1048576"), MATCH(K$1, AgoR!$6:$6, 0), FALSE), 0 ) + IFERROR( VLOOKUP($A12, INDIRECT("SepR!$A$6:$ZZ$1048576"), MATCH(K$1, SepR!$6:$6, 0), FALSE), 0 ) + IFERROR( VLOOKUP($A12, INDIRECT("OctR!$A$6:$ZZ$1048576"), MATCH(K$1, OctR!$6:$6, 0), FALSE), 0 ) + IFERROR( VLOOKUP($A12, INDIRECT("NovR!$A$6:$ZZ$1048576"), MATCH(K$1, NovR!$6:$6, 0), FALSE), 0 ) + IFERROR( VLOOKUP($A12, INDIRECT("DicR!$A$6:$ZZ$1048576"), MATCH(K$1, DicR!$6:$6, 0), FALSE), 0 ) )} -> 0 | ... AY12: {=SUM( IFERROR( VLOOKUP($A12, INDIRECT("EneR!$A$6:$ZZ$1048576"), MATCH(AY$1, EneR!$6:$6, 0), FALSE), 0 ) + IFERROR( VLOOKUP($A12, INDIRECT("FebR!$A$6:$ZZ$1048576"), MATCH(AY$1, FebR!$6:$6, 0), FALSE), 0 ) + IFERROR( VLOOKUP($A12, INDIRECT("MarR!$A$6:$ZZ$1048576"), MATCH(AY$1, MarR!$6:$6, 0), FALSE), 0 ) + IFERROR( VLOOKUP($A12, INDIRECT("AbrR!$A$6:$ZZ$1048576"), MATCH(AY$1, AbrR!$6:$6, 0), FALSE), 0 ) + IFERROR( VLOOKUP($A12, INDIRECT("MayR!$A$6:$ZZ$1048576"), MATCH(AY$1, MayR!$6:$6, 0), FALSE), 0 ) + IFERROR( VLOOKUP($A12, INDIRECT("JunR!$A$6:$ZZ$1048576"), MATCH(AY$1, JunR!$6:$6, 0), FALSE), 0 ) + IFERROR( VLOOKUP($A12, INDIRECT("JulR!$A$6:$ZZ$1048576"), MATCH(AY$1, JulR!$6:$6, 0), FALSE), 0 ) + IFERROR( VLOOKUP($A12, INDIRECT("AgoR!$A$6:$ZZ$1048576"), MATCH(AY$1, AgoR!$6:$6, 0), FALSE), 0 ) + IFERROR( VLOOKUP($A12, INDIRECT("SepR!$A$6:$ZZ$1048576"), MATCH(AY$1, SepR!$6:$6, 0), FALSE), 0 ) + IFERROR( VLOOKUP($A12, INDIRECT("OctR!$A$6:$ZZ$1048576"), MATCH(AY$1, OctR!$6:$6, 0), FALSE), 0 ) + IFERROR( VLOOKUP($A12, INDIRECT("NovR!$A$6:$ZZ$1048576"), MATCH(AY$1, NovR!$6:$6, 0), FALSE), 0 ) + IFERROR( VLOOKUP($A12, INDIRECT("DicR!$A$6:$ZZ$1048576"), MATCH(AY$1, DicR!$6:$6, 0), FALSE), 0 ) )} -> 0
A13: =Menus!R5 | B13: =IFERROR(SUM(D13:AZ13),"") -> 0 | C13: =IFERROR(INDEX($D$1:$AQ130, MATCH($A13, $A$1:$A130, 0), MATCH(C$1, $D$1:AZ$1, 0)), "") | D13: {=SUM( IFERROR( VLOOKUP($A13, INDIRECT("EneR!$A$6:$ZZ$1048576"), MATCH(D$1, EneR!$6:$6, 0), FALSE), 0 ) + IFERROR( VLOOKUP($A13, INDIRECT("FebR!$A$6:$ZZ$1048576"), MATCH(D$1, FebR!$6:$6, 0), FALSE), 0 ) + IFERROR( VLOOKUP($A13, INDIRECT("MarR!$A$6:$ZZ$1048576"), MATCH(D$1, MarR!$6:$6, 0), FALSE), 0 ) + IFERROR( VLOOKUP($A13, INDIRECT("AbrR!$A$6:$ZZ$1048576"), MATCH(D$1, AbrR!$6:$6, 0), FALSE), 0 ) + IFERROR( VLOOKUP($A13, INDIRECT("MayR!$A$6:$ZZ$1048576"), MATCH(D$1, MayR!$6:$6, 0), FALSE), 0 ) + IFERROR( VLOOKUP($A13, INDIRECT("JunR!$A$6:$ZZ$1048576"), MATCH(D$1, JunR!$6:$6, 0), FALSE), 0 ) + IFERROR( VLOOKUP($A13, INDIRECT("JulR!$A$6:$ZZ$1048576"), MATCH(D$1, JulR!$6:$6, 0), FALSE), 0 ) + IFERROR( VLOOKUP($A13, INDIRECT("AgoR!$A$6:$ZZ$1048576"), MATCH(D$1, AgoR!$6:$6, 0), FALSE), 0 ) + IFERROR( VLOOKUP($A13, INDIRECT("SepR!$A$6:$ZZ$1048576"), MATCH(D$1, SepR!$6:$6, 0), FALSE), 0 ) + IFERROR( VLOOKUP($A13, INDIRECT("OctR!$A$6:$ZZ$1048576"), MATCH(D$1, OctR!$6:$6, 0), FALSE), 0 ) + IFERROR( VLOOKUP($A13, INDIRECT("NovR!$A$6:$ZZ$1048576"), MATCH(D$1, NovR!$6:$6, 0), FALSE), 0 ) + IFERROR( VLOOKUP($A13, INDIRECT("DicR!$A$6:$ZZ$1048576"), MATCH(D$1, DicR!$6:$6, 0), FALSE), 0 ) )} -> 0 | E13: {=SUM( IFERROR( VLOOKUP($A13, INDIRECT("EneR!$A$6:$ZZ$1048576"), MATCH(E$1, EneR!$6:$6, 0), FALSE), 0 ) + IFERROR( VLOOKUP($A13, INDIRECT("FebR!$A$6:$ZZ$1048576"), MATCH(E$1, FebR!$6:$6, 0), FALSE), 0 ) + IFERROR( VLOOKUP($A13, INDIRECT("MarR!$A$6:$ZZ$1048576"), MATCH(E$1, MarR!$6:$6, 0), FALSE), 0 ) + IFERROR( VLOOKUP($A13, INDIRECT("AbrR!$A$6:$ZZ$1048576"), MATCH(E$1, AbrR!$6:$6, 0), FALSE), 0 ) + IFERROR( VLOOKUP($A13, INDIRECT("MayR!$A$6:$ZZ$1048576"), MATCH(E$1, MayR!$6:$6, 0), FALSE), 0 ) + IFERROR( VLOOKUP($A13, INDIRECT("JunR!$A$6:$ZZ$1048576"), MATCH(E$1, JunR!$6:$6, 0), FALSE), 0 ) + IFERROR( VLOOKUP($A13, INDIRECT("JulR!$A$6:$ZZ$1048576"), MATCH(E$1, JulR!$6:$6, 0), FALSE), 0 ) + IFERROR( VLOOKUP($A13, INDIRECT("AgoR!$A$6:$ZZ$1048576"), MATCH(E$1, AgoR!$6:$6, 0), FALSE), 0 ) + IFERROR( VLOOKUP($A13, INDIRECT("SepR!$A$6:$ZZ$1048576"), MATCH(E$1, SepR!$6:$6, 0), FALSE), 0 ) + IFERROR( VLOOKUP($A13, INDIRECT("OctR!$A$6:$ZZ$1048576"), MATCH(E$1, OctR!$6:$6, 0), FALSE), 0 ) + IFERROR( VLOOKUP($A13, INDIRECT("NovR!$A$6:$ZZ$1048576"), MATCH(E$1, NovR!$6:$6, 0), FALSE), 0 ) + IFERROR( VLOOKUP($A13, INDIRECT("DicR!$A$6:$ZZ$1048576"), MATCH(E$1, DicR!$6:$6, 0), FALSE), 0 ) )} -> 0 | F13: {=SUM( IFERROR( VLOOKUP($A13, INDIRECT("EneR!$A$6:$ZZ$1048576"), MATCH(F$1, EneR!$6:$6, 0), FALSE), 0 ) + IFERROR( VLOOKUP($A13, INDIRECT("FebR!$A$6:$ZZ$1048576"), MATCH(F$1, FebR!$6:$6, 0), FALSE), 0 ) + IFERROR( VLOOKUP($A13, INDIRECT("MarR!$A$6:$ZZ$1048576"), MATCH(F$1, MarR!$6:$6, 0), FALSE), 0 ) + IFERROR( VLOOKUP($A13, INDIRECT("AbrR!$A$6:$ZZ$1048576"), MATCH(F$1, AbrR!$6:$6, 0), FALSE), 0 ) + IFERROR( VLOOKUP($A13, INDIRECT("MayR!$A$6:$ZZ$1048576"), MATCH(F$1, MayR!$6:$6, 0), FALSE), 0 ) + IFERROR( VLOOKUP($A13, INDIRECT("JunR!$A$6:$ZZ$1048576"), MATCH(F$1, JunR!$6:$6, 0), FALSE), 0 ) + IFERROR( VLOOKUP($A13, INDIRECT("JulR!$A$6:$ZZ$1048576"), MATCH(F$1, JulR!$6:$6, 0), FALSE), 0 ) + IFERROR( VLOOKUP($A13, INDIRECT("AgoR!$A$6:$ZZ$1048576"), MATCH(F$1, AgoR!$6:$6, 0), FALSE), 0 ) + IFERROR( VLOOKUP($A13, INDIRECT("SepR!$A$6:$ZZ$1048576"), MATCH(F$1, SepR!$6:$6, 0), FALSE), 0 ) + IFERROR( VLOOKUP($A13, INDIRECT("OctR!$A$6:$ZZ$1048576"), MATCH(F$1, OctR!$6:$6, 0), FALSE), 0 ) + IFERROR( VLOOKUP($A13, INDIRECT("NovR!$A$6:$ZZ$1048576"), MATCH(F$1, NovR!$6:$6, 0), FALSE), 0 ) + IFERROR( VLOOKUP($A13, INDIRECT("DicR!$A$6:$ZZ$1048576"), MATCH(F$1, DicR!$6:$6, 0), FALSE), 0 ) )} -> 0 | G13: {=SUM( IFERROR( VLOOKUP($A13, INDIRECT("EneR!$A$6:$ZZ$1048576"), MATCH(G$1, EneR!$6:$6, 0), FALSE), 0 ) + IFERROR( VLOOKUP($A13, INDIRECT("FebR!$A$6:$ZZ$1048576"), MATCH(G$1, FebR!$6:$6, 0), FALSE), 0 ) + IFERROR( VLOOKUP($A13, INDIRECT("MarR!$A$6:$ZZ$1048576"), MATCH(G$1, MarR!$6:$6, 0), FALSE), 0 ) + IFERROR( VLOOKUP($A13, INDIRECT("AbrR!$A$6:$ZZ$1048576"), MATCH(G$1, AbrR!$6:$6, 0), FALSE), 0 ) + IFERROR( VLOOKUP($A13, INDIRECT("MayR!$A$6:$ZZ$1048576"), MATCH(G$1, MayR!$6:$6, 0), FALSE), 0 ) + IFERROR( VLOOKUP($A13, INDIRECT("JunR!$A$6:$ZZ$1048576"), MATCH(G$1, JunR!$6:$6, 0), FALSE), 0 ) + IFERROR( VLOOKUP($A13, INDIRECT("JulR!$A$6:$ZZ$1048576"), MATCH(G$1, JulR!$6:$6, 0), FALSE), 0 ) + IFERROR( VLOOKUP($A13, INDIRECT("AgoR!$A$6:$ZZ$1048576"), MATCH(G$1, AgoR!$6:$6, 0), FALSE), 0 ) + IFERROR( VLOOKUP($A13, INDIRECT("SepR!$A$6:$ZZ$1048576"), MATCH(G$1, SepR!$6:$6, 0), FALSE), 0 ) + IFERROR( VLOOKUP($A13, INDIRECT("OctR!$A$6:$ZZ$1048576"), MATCH(G$1, OctR!$6:$6, 0), FALSE), 0 ) + IFERROR( VLOOKUP($A13, INDIRECT("NovR!$A$6:$ZZ$1048576"), MATCH(G$1, NovR!$6:$6, 0), FALSE), 0 ) + IFERROR( VLOOKUP($A13, INDIRECT("DicR!$A$6:$ZZ$1048576"), MATCH(G$1, DicR!$6:$6, 0), FALSE), 0 ) )} -> 0 | H13: {=SUM( IFERROR( VLOOKUP($A13, INDIRECT("EneR!$A$6:$ZZ$1048576"), MATCH(H$1, EneR!$6:$6, 0), FALSE), 0 ) + IFERROR( VLOOKUP($A13, INDIRECT("FebR!$A$6:$ZZ$1048576"), MATCH(H$1, FebR!$6:$6, 0), FALSE), 0 ) + IFERROR( VLOOKUP($A13, INDIRECT("MarR!$A$6:$ZZ$1048576"), MATCH(H$1, MarR!$6:$6, 0), FALSE), 0 ) + IFERROR( VLOOKUP($A13, INDIRECT("AbrR!$A$6:$ZZ$1048576"), MATCH(H$1, AbrR!$6:$6, 0), FALSE), 0 ) + IFERROR( VLOOKUP($A13, INDIRECT("MayR!$A$6:$ZZ$1048576"), MATCH(H$1, MayR!$6:$6, 0), FALSE), 0 ) + IFERROR( VLOOKUP($A13, INDIRECT("JunR!$A$6:$ZZ$1048576"), MATCH(H$1, JunR!$6:$6, 0), FALSE), 0 ) + IFERROR( VLOOKUP($A13, INDIRECT("JulR!$A$6:$ZZ$1048576"), MATCH(H$1, JulR!$6:$6, 0), FALSE), 0 ) + IFERROR( VLOOKUP($A13, INDIRECT("AgoR!$A$6:$ZZ$1048576"), MATCH(H$1, AgoR!$6:$6, 0), FALSE), 0 ) + IFERROR( VLOOKUP($A13, INDIRECT("SepR!$A$6:$ZZ$1048576"), MATCH(H$1, SepR!$6:$6, 0), FALSE), 0 ) + IFERROR( VLOOKUP($A13, INDIRECT("OctR!$A$6:$ZZ$1048576"), MATCH(H$1, OctR!$6:$6, 0), FALSE), 0 ) + IFERROR( VLOOKUP($A13, INDIRECT("NovR!$A$6:$ZZ$1048576"), MATCH(H$1, NovR!$6:$6, 0), FALSE), 0 ) + IFERROR( VLOOKUP($A13, INDIRECT("DicR!$A$6:$ZZ$1048576"), MATCH(H$1, DicR!$6:$6, 0), FALSE), 0 ) )} -> 0 | I13: {=SUM( IFERROR( VLOOKUP($A13, INDIRECT("EneR!$A$6:$ZZ$1048576"), MATCH(I$1, EneR!$6:$6, 0), FALSE), 0 ) + IFERROR( VLOOKUP($A13, INDIRECT("FebR!$A$6:$ZZ$1048576"), MATCH(I$1, FebR!$6:$6, 0), FALSE), 0 ) + IFERROR( VLOOKUP($A13, INDIRECT("MarR!$A$6:$ZZ$1048576"), MATCH(I$1, MarR!$6:$6, 0), FALSE), 0 ) + IFERROR( VLOOKUP($A13, INDIRECT("AbrR!$A$6:$ZZ$1048576"), MATCH(I$1, AbrR!$6:$6, 0), FALSE), 0 ) + IFERROR( VLOOKUP($A13, INDIRECT("MayR!$A$6:$ZZ$1048576"), MATCH(I$1, MayR!$6:$6, 0), FALSE), 0 ) + IFERROR( VLOOKUP($A13, INDIRECT("JunR!$A$6:$ZZ$1048576"), MATCH(I$1, JunR!$6:$6, 0), FALSE), 0 ) + IFERROR( VLOOKUP($A13, INDIRECT("JulR!$A$6:$ZZ$1048576"), MATCH(I$1, JulR!$6:$6, 0), FALSE), 0 ) + IFERROR( VLOOKUP($A13, INDIRECT("AgoR!$A$6:$ZZ$1048576"), MATCH(I$1, AgoR!$6:$6, 0), FALSE), 0 ) + IFERROR( VLOOKUP($A13, INDIRECT("SepR!$A$6:$ZZ$1048576"), MATCH(I$1, SepR!$6:$6, 0), FALSE), 0 ) + IFERROR( VLOOKUP($A13, INDIRECT("OctR!$A$6:$ZZ$1048576"), MATCH(I$1, OctR!$6:$6, 0), FALSE), 0 ) + IFERROR( VLOOKUP($A13, INDIRECT("NovR!$A$6:$ZZ$1048576"), MATCH(I$1, NovR!$6:$6, 0), FALSE), 0 ) + IFERROR( VLOOKUP($A13, INDIRECT("DicR!$A$6:$ZZ$1048576"), MATCH(I$1, DicR!$6:$6, 0), FALSE), 0 ) )} -> 0 | J13: {=SUM( IFERROR( VLOOKUP($A13, INDIRECT("EneR!$A$6:$ZZ$1048576"), MATCH(J$1, EneR!$6:$6, 0), FALSE), 0 ) + IFERROR( VLOOKUP($A13, INDIRECT("FebR!$A$6:$ZZ$1048576"), MATCH(J$1, FebR!$6:$6, 0), FALSE), 0 ) + IFERROR( VLOOKUP($A13, INDIRECT("MarR!$A$6:$ZZ$1048576"), MATCH(J$1, MarR!$6:$6, 0), FALSE), 0 ) + IFERROR( VLOOKUP($A13, INDIRECT("AbrR!$A$6:$ZZ$1048576"), MATCH(J$1, AbrR!$6:$6, 0), FALSE), 0 ) + IFERROR( VLOOKUP($A13, INDIRECT("MayR!$A$6:$ZZ$1048576"), MATCH(J$1, MayR!$6:$6, 0), FALSE), 0 ) + IFERROR( VLOOKUP($A13, INDIRECT("JunR!$A$6:$ZZ$1048576"), MATCH(J$1, JunR!$6:$6, 0), FALSE), 0 ) + IFERROR( VLOOKUP($A13, INDIRECT("JulR!$A$6:$ZZ$1048576"), MATCH(J$1, JulR!$6:$6, 0), FALSE), 0 ) + IFERROR( VLOOKUP($A13, INDIRECT("AgoR!$A$6:$ZZ$1048576"), MATCH(J$1, AgoR!$6:$6, 0), FALSE), 0 ) + IFERROR( VLOOKUP($A13, INDIRECT("SepR!$A$6:$ZZ$1048576"), MATCH(J$1, SepR!$6:$6, 0), FALSE), 0 ) + IFERROR( VLOOKUP($A13, INDIRECT("OctR!$A$6:$ZZ$1048576"), MATCH(J$1, OctR!$6:$6, 0), FALSE), 0 ) + IFERROR( VLOOKUP($A13, INDIRECT("NovR!$A$6:$ZZ$1048576"), MATCH(J$1, NovR!$6:$6, 0), FALSE), 0 ) + IFERROR( VLOOKUP($A13, INDIRECT("DicR!$A$6:$ZZ$1048576"), MATCH(J$1, DicR!$6:$6, 0), FALSE), 0 ) )} -> 0 | K13: {=SUM( IFERROR( VLOOKUP($A13, INDIRECT("EneR!$A$6:$ZZ$1048576"), MATCH(K$1, EneR!$6:$6, 0), FALSE), 0 ) + IFERROR( VLOOKUP($A13, INDIRECT("FebR!$A$6:$ZZ$1048576"), MATCH(K$1, FebR!$6:$6, 0), FALSE), 0 ) + IFERROR( VLOOKUP($A13, INDIRECT("MarR!$A$6:$ZZ$1048576"), MATCH(K$1, MarR!$6:$6, 0), FALSE), 0 ) + IFERROR( VLOOKUP($A13, INDIRECT("AbrR!$A$6:$ZZ$1048576"), MATCH(K$1, AbrR!$6:$6, 0), FALSE), 0 ) + IFERROR( VLOOKUP($A13, INDIRECT("MayR!$A$6:$ZZ$1048576"), MATCH(K$1, MayR!$6:$6, 0), FALSE), 0 ) + IFERROR( VLOOKUP($A13, INDIRECT("JunR!$A$6:$ZZ$1048576"), MATCH(K$1, JunR!$6:$6, 0), FALSE), 0 ) + IFERROR( VLOOKUP($A13, INDIRECT("JulR!$A$6:$ZZ$1048576"), MATCH(K$1, JulR!$6:$6, 0), FALSE), 0 ) + IFERROR( VLOOKUP($A13, INDIRECT("AgoR!$A$6:$ZZ$1048576"), MATCH(K$1, AgoR!$6:$6, 0), FALSE), 0 ) + IFERROR( VLOOKUP($A13, INDIRECT("SepR!$A$6:$ZZ$1048576"), MATCH(K$1, SepR!$6:$6, 0), FALSE), 0 ) + IFERROR( VLOOKUP($A13, INDIRECT("OctR!$A$6:$ZZ$1048576"), MATCH(K$1, OctR!$6:$6, 0), FALSE), 0 ) + IFERROR( VLOOKUP($A13, INDIRECT("NovR!$A$6:$ZZ$1048576"), MATCH(K$1, NovR!$6:$6, 0), FALSE), 0 ) + IFERROR( VLOOKUP($A13, INDIRECT("DicR!$A$6:$ZZ$1048576"), MATCH(K$1, DicR!$6:$6, 0), FALSE), 0 ) )} -> 0 | ... AY13: {=SUM( IFERROR( VLOOKUP($A13, INDIRECT("EneR!$A$6:$ZZ$1048576"), MATCH(AY$1, EneR!$6:$6, 0), FALSE), 0 ) + IFERROR( VLOOKUP($A13, INDIRECT("FebR!$A$6:$ZZ$1048576"), MATCH(AY$1, FebR!$6:$6, 0), FALSE), 0 ) + IFERROR( VLOOKUP($A13, INDIRECT("MarR!$A$6:$ZZ$1048576"), MATCH(AY$1, MarR!$6:$6, 0), FALSE), 0 ) + IFERROR( VLOOKUP($A13, INDIRECT("AbrR!$A$6:$ZZ$1048576"), MATCH(AY$1, AbrR!$6:$6, 0), FALSE), 0 ) + IFERROR( VLOOKUP($A13, INDIRECT("MayR!$A$6:$ZZ$1048576"), MATCH(AY$1, MayR!$6:$6, 0), FALSE), 0 ) + IFERROR( VLOOKUP($A13, INDIRECT("JunR!$A$6:$ZZ$1048576"), MATCH(AY$1, JunR!$6:$6, 0), FALSE), 0 ) + IFERROR( VLOOKUP($A13, INDIRECT("JulR!$A$6:$ZZ$1048576"), MATCH(AY$1, JulR!$6:$6, 0), FALSE), 0 ) + IFERROR( VLOOKUP($A13, INDIRECT("AgoR!$A$6:$ZZ$1048576"), MATCH(AY$1, AgoR!$6:$6, 0), FALSE), 0 ) + IFERROR( VLOOKUP($A13, INDIRECT("SepR!$A$6:$ZZ$1048576"), MATCH(AY$1, SepR!$6:$6, 0), FALSE), 0 ) + IFERROR( VLOOKUP($A13, INDIRECT("OctR!$A$6:$ZZ$1048576"), MATCH(AY$1, OctR!$6:$6, 0), FALSE), 0 ) + IFERROR( VLOOKUP($A13, INDIRECT("NovR!$A$6:$ZZ$1048576"), MATCH(AY$1, NovR!$6:$6, 0), FALSE), 0 ) + IFERROR( VLOOKUP($A13, INDIRECT("DicR!$A$6:$ZZ$1048576"), MATCH(AY$1, DicR!$6:$6, 0), FALSE), 0 ) )} -> 0
A14: =Menus!R6 | B14: =IFERROR(SUM(D14:AZ14),"") -> 0 | C14: =IFERROR(INDEX($D$1:$AQ131, MATCH($A14, $A$1:$A131, 0), MATCH(C$1, $D$1:AZ$1, 0)), "") | D14: {=SUM( IFERROR( VLOOKUP($A14, INDIRECT("EneR!$A$6:$ZZ$1048576"), MATCH(D$1, EneR!$6:$6, 0), FALSE), 0 ) + IFERROR( VLOOKUP($A14, INDIRECT("FebR!$A$6:$ZZ$1048576"), MATCH(D$1, FebR!$6:$6, 0), FALSE), 0 ) + IFERROR( VLOOKUP($A14, INDIRECT("MarR!$A$6:$ZZ$1048576"), MATCH(D$1, MarR!$6:$6, 0), FALSE), 0 ) + IFERROR( VLOOKUP($A14, INDIRECT("AbrR!$A$6:$ZZ$1048576"), MATCH(D$1, AbrR!$6:$6, 0), FALSE), 0 ) + IFERROR( VLOOKUP($A14, INDIRECT("MayR!$A$6:$ZZ$1048576"), MATCH(D$1, MayR!$6:$6, 0), FALSE), 0 ) + IFERROR( VLOOKUP($A14, INDIRECT("JunR!$A$6:$ZZ$1048576"), MATCH(D$1, JunR!$6:$6, 0), FALSE), 0 ) + IFERROR( VLOOKUP($A14, INDIRECT("JulR!$A$6:$ZZ$1048576"), MATCH(D$1, JulR!$6:$6, 0), FALSE), 0 ) + IFERROR( VLOOKUP($A14, INDIRECT("AgoR!$A$6:$ZZ$1048576"), MATCH(D$1, AgoR!$6:$6, 0), FALSE), 0 ) + IFERROR( VLOOKUP($A14, INDIRECT("SepR!$A$6:$ZZ$1048576"), MATCH(D$1, SepR!$6:$6, 0), FALSE), 0 ) + IFERROR( VLOOKUP($A14, INDIRECT("OctR!$A$6:$ZZ$1048576"), MATCH(D$1, OctR!$6:$6, 0), FALSE), 0 ) + IFERROR( VLOOKUP($A14, INDIRECT("NovR!$A$6:$ZZ$1048576"), MATCH(D$1, NovR!$6:$6, 0), FALSE), 0 ) + IFERROR( VLOOKUP($A14, INDIRECT("DicR!$A$6:$ZZ$1048576"), MATCH(D$1, DicR!$6:$6, 0), FALSE), 0 ) )} -> 0 | E14: {=SUM( IFERROR( VLOOKUP($A14, INDIRECT("EneR!$A$6:$ZZ$1048576"), MATCH(E$1, EneR!$6:$6, 0), FALSE), 0 ) + IFERROR( VLOOKUP($A14, INDIRECT("FebR!$A$6:$ZZ$1048576"), MATCH(E$1, FebR!$6:$6, 0), FALSE), 0 ) + IFERROR( VLOOKUP($A14, INDIRECT("MarR!$A$6:$ZZ$1048576"), MATCH(E$1, MarR!$6:$6, 0), FALSE), 0 ) + IFERROR( VLOOKUP($A14, INDIRECT("AbrR!$A$6:$ZZ$1048576"), MATCH(E$1, AbrR!$6:$6, 0), FALSE), 0 ) + IFERROR( VLOOKUP($A14, INDIRECT("MayR!$A$6:$ZZ$1048576"), MATCH(E$1, MayR!$6:$6, 0), FALSE), 0 ) + IFERROR( VLOOKUP($A14, INDIRECT("JunR!$A$6:$ZZ$1048576"), MATCH(E$1, JunR!$6:$6, 0), FALSE), 0 ) + IFERROR( VLOOKUP($A14, INDIRECT("JulR!$A$6:$ZZ$1048576"), MATCH(E$1, JulR!$6:$6, 0), FALSE), 0 ) + IFERROR( VLOOKUP($A14, INDIRECT("AgoR!$A$6:$ZZ$1048576"), MATCH(E$1, AgoR!$6:$6, 0), FALSE), 0 ) + IFERROR( VLOOKUP($A14, INDIRECT("SepR!$A$6:$ZZ$1048576"), MATCH(E$1, SepR!$6:$6, 0), FALSE), 0 ) + IFERROR( VLOOKUP($A14, INDIRECT("OctR!$A$6:$ZZ$1048576"), MATCH(E$1, OctR!$6:$6, 0), FALSE), 0 ) + IFERROR( VLOOKUP($A14, INDIRECT("NovR!$A$6:$ZZ$1048576"), MATCH(E$1, NovR!$6:$6, 0), FALSE), 0 ) + IFERROR( VLOOKUP($A14, INDIRECT("DicR!$A$6:$ZZ$1048576"), MATCH(E$1, DicR!$6:$6, 0), FALSE), 0 ) )} -> 0 | F14: {=SUM( IFERROR( VLOOKUP($A14, INDIRECT("EneR!$A$6:$ZZ$1048576"), MATCH(F$1, EneR!$6:$6, 0), FALSE), 0 ) + IFERROR( VLOOKUP($A14, INDIRECT("FebR!$A$6:$ZZ$1048576"), MATCH(F$1, FebR!$6:$6, 0), FALSE), 0 ) + IFERROR( VLOOKUP($A14, INDIRECT("MarR!$A$6:$ZZ$1048576"), MATCH(F$1, MarR!$6:$6, 0), FALSE), 0 ) + IFERROR( VLOOKUP($A14, INDIRECT("AbrR!$A$6:$ZZ$1048576"), MATCH(F$1, AbrR!$6:$6, 0), FALSE), 0 ) + IFERROR( VLOOKUP($A14, INDIRECT("MayR!$A$6:$ZZ$1048576"), MATCH(F$1, MayR!$6:$6, 0), FALSE), 0 ) + IFERROR( VLOOKUP($A14, INDIRECT("JunR!$A$6:$ZZ$1048576"), MATCH(F$1, JunR!$6:$6, 0), FALSE), 0 ) + IFERROR( VLOOKUP($A14, INDIRECT("JulR!$A$6:$ZZ$1048576"), MATCH(F$1, JulR!$6:$6, 0), FALSE), 0 ) + IFERROR( VLOOKUP($A14, INDIRECT("AgoR!$A$6:$ZZ$1048576"), MATCH(F$1, AgoR!$6:$6, 0), FALSE), 0 ) + IFERROR( VLOOKUP($A14, INDIRECT("SepR!$A$6:$ZZ$1048576"), MATCH(F$1, SepR!$6:$6, 0), FALSE), 0 ) + IFERROR( VLOOKUP($A14, INDIRECT("OctR!$A$6:$ZZ$1048576"), MATCH(F$1, OctR!$6:$6, 0), FALSE), 0 ) + IFERROR( VLOOKUP($A14, INDIRECT("NovR!$A$6:$ZZ$1048576"), MATCH(F$1, NovR!$6:$6, 0), FALSE), 0 ) + IFERROR( VLOOKUP($A14, INDIRECT("DicR!$A$6:$ZZ$1048576"), MATCH(F$1, DicR!$6:$6, 0), FALSE), 0 ) )} -> 0 | G14: {=SUM( IFERROR( VLOOKUP($A14, INDIRECT("EneR!$A$6:$ZZ$1048576"), MATCH(G$1, EneR!$6:$6, 0), FALSE), 0 ) + IFERROR( VLOOKUP($A14, INDIRECT("FebR!$A$6:$ZZ$1048576"), MATCH(G$1, FebR!$6:$6, 0), FALSE), 0 ) + IFERROR( VLOOKUP($A14, INDIRECT("MarR!$A$6:$ZZ$1048576"), MATCH(G$1, MarR!$6:$6, 0), FALSE), 0 ) + IFERROR( VLOOKUP($A14, INDIRECT("AbrR!$A$6:$ZZ$1048576"), MATCH(G$1, AbrR!$6:$6, 0), FALSE), 0 ) + IFERROR( VLOOKUP($A14, INDIRECT("MayR!$A$6:$ZZ$1048576"), MATCH(G$1, MayR!$6:$6, 0), FALSE), 0 ) + IFERROR( VLOOKUP($A14, INDIRECT("JunR!$A$6:$ZZ$1048576"), MATCH(G$1, JunR!$6:$6, 0), FALSE), 0 ) + IFERROR( VLOOKUP($A14, INDIRECT("JulR!$A$6:$ZZ$1048576"), MATCH(G$1, JulR!$6:$6, 0), FALSE), 0 ) + IFERROR( VLOOKUP($A14, INDIRECT("AgoR!$A$6:$ZZ$1048576"), MATCH(G$1, AgoR!$6:$6, 0), FALSE), 0 ) + IFERROR( VLOOKUP($A14, INDIRECT("SepR!$A$6:$ZZ$1048576"), MATCH(G$1, SepR!$6:$6, 0), FALSE), 0 ) + IFERROR( VLOOKUP($A14, INDIRECT("OctR!$A$6:$ZZ$1048576"), MATCH(G$1, OctR!$6:$6, 0), FALSE), 0 ) + IFERROR( VLOOKUP($A14, INDIRECT("NovR!$A$6:$ZZ$1048576"), MATCH(G$1, NovR!$6:$6, 0), FALSE), 0 ) + IFERROR( VLOOKUP($A14, INDIRECT("DicR!$A$6:$ZZ$1048576"), MATCH(G$1, DicR!$6:$6, 0), FALSE), 0 ) )} -> 0 | H14: {=SUM( IFERROR( VLOOKUP($A14, INDIRECT("EneR!$A$6:$ZZ$1048576"), MATCH(H$1, EneR!$6:$6, 0), FALSE), 0 ) + IFERROR( VLOOKUP($A14, INDIRECT("FebR!$A$6:$ZZ$1048576"), MATCH(H$1, FebR!$6:$6, 0), FALSE), 0 ) + IFERROR( VLOOKUP($A14, INDIRECT("MarR!$A$6:$ZZ$1048576"), MATCH(H$1, MarR!$6:$6, 0), FALSE), 0 ) + IFERROR( VLOOKUP($A14, INDIRECT("AbrR!$A$6:$ZZ$1048576"), MATCH(H$1, AbrR!$6:$6, 0), FALSE), 0 ) + IFERROR( VLOOKUP($A14, INDIRECT("MayR!$A$6:$ZZ$1048576"), MATCH(H$1, MayR!$6:$6, 0), FALSE), 0 ) + IFERROR( VLOOKUP($A14, INDIRECT("JunR!$A$6:$ZZ$1048576"), MATCH(H$1, JunR!$6:$6, 0), FALSE), 0 ) + IFERROR( VLOOKUP($A14, INDIRECT("JulR!$A$6:$ZZ$1048576"), MATCH(H$1, JulR!$6:$6, 0), FALSE), 0 ) + IFERROR( VLOOKUP($A14, INDIRECT("AgoR!$A$6:$ZZ$1048576"), MATCH(H$1, AgoR!$6:$6, 0), FALSE), 0 ) + IFERROR( VLOOKUP($A14, INDIRECT("SepR!$A$6:$ZZ$1048576"), MATCH(H$1, SepR!$6:$6, 0), FALSE), 0 ) + IFERROR( VLOOKUP($A14, INDIRECT("OctR!$A$6:$ZZ$1048576"), MATCH(H$1, OctR!$6:$6, 0), FALSE), 0 ) + IFERROR( VLOOKUP($A14, INDIRECT("NovR!$A$6:$ZZ$1048576"), MATCH(H$1, NovR!$6:$6, 0), FALSE), 0 ) + IFERROR( VLOOKUP($A14, INDIRECT("DicR!$A$6:$ZZ$1048576"), MATCH(H$1, DicR!$6:$6, 0), FALSE), 0 ) )} -> 0 | I14: {=SUM( IFERROR( VLOOKUP($A14, INDIRECT("EneR!$A$6:$ZZ$1048576"), MATCH(I$1, EneR!$6:$6, 0), FALSE), 0 ) + IFERROR( VLOOKUP($A14, INDIRECT("FebR!$A$6:$ZZ$1048576"), MATCH(I$1, FebR!$6:$6, 0), FALSE), 0 ) + IFERROR( VLOOKUP($A14, INDIRECT("MarR!$A$6:$ZZ$1048576"), MATCH(I$1, MarR!$6:$6, 0), FALSE), 0 ) + IFERROR( VLOOKUP($A14, INDIRECT("AbrR!$A$6:$ZZ$1048576"), MATCH(I$1, AbrR!$6:$6, 0), FALSE), 0 ) + IFERROR( VLOOKUP($A14, INDIRECT("MayR!$A$6:$ZZ$1048576"), MATCH(I$1, MayR!$6:$6, 0), FALSE), 0 ) + IFERROR( VLOOKUP($A14, INDIRECT("JunR!$A$6:$ZZ$1048576"), MATCH(I$1, JunR!$6:$6, 0), FALSE), 0 ) + IFERROR( VLOOKUP($A14, INDIRECT("JulR!$A$6:$ZZ$1048576"), MATCH(I$1, JulR!$6:$6, 0), FALSE), 0 ) + IFERROR( VLOOKUP($A14, INDIRECT("AgoR!$A$6:$ZZ$1048576"), MATCH(I$1, AgoR!$6:$6, 0), FALSE), 0 ) + IFERROR( VLOOKUP($A14, INDIRECT("SepR!$A$6:$ZZ$1048576"), MATCH(I$1, SepR!$6:$6, 0), FALSE), 0 ) + IFERROR( VLOOKUP($A14, INDIRECT("OctR!$A$6:$ZZ$1048576"), MATCH(I$1, OctR!$6:$6, 0), FALSE), 0 ) + IFERROR( VLOOKUP($A14, INDIRECT("NovR!$A$6:$ZZ$1048576"), MATCH(I$1, NovR!$6:$6, 0), FALSE), 0 ) + IFERROR( VLOOKUP($A14, INDIRECT("DicR!$A$6:$ZZ$1048576"), MATCH(I$1, DicR!$6:$6, 0), FALSE), 0 ) )} -> 0 | J14: {=SUM( IFERROR( VLOOKUP($A14, INDIRECT("EneR!$A$6:$ZZ$1048576"), MATCH(J$1, EneR!$6:$6, 0), FALSE), 0 ) + IFERROR( VLOOKUP($A14, INDIRECT("FebR!$A$6:$ZZ$1048576"), MATCH(J$1, FebR!$6:$6, 0), FALSE), 0 ) + IFERROR( VLOOKUP($A14, INDIRECT("MarR!$A$6:$ZZ$1048576"), MATCH(J$1, MarR!$6:$6, 0), FALSE), 0 ) + IFERROR( VLOOKUP($A14, INDIRECT("AbrR!$A$6:$ZZ$1048576"), MATCH(J$1, AbrR!$6:$6, 0), FALSE), 0 ) + IFERROR( VLOOKUP($A14, INDIRECT("MayR!$A$6:$ZZ$1048576"), MATCH(J$1, MayR!$6:$6, 0), FALSE), 0 ) + IFERROR( VLOOKUP($A14, INDIRECT("JunR!$A$6:$ZZ$1048576"), MATCH(J$1, JunR!$6:$6, 0), FALSE), 0 ) + IFERROR( VLOOKUP($A14, INDIRECT("JulR!$A$6:$ZZ$1048576"), MATCH(J$1, JulR!$6:$6, 0), FALSE), 0 ) + IFERROR( VLOOKUP($A14, INDIRECT("AgoR!$A$6:$ZZ$1048576"), MATCH(J$1, AgoR!$6:$6, 0), FALSE), 0 ) + IFERROR( VLOOKUP($A14, INDIRECT("SepR!$A$6:$ZZ$1048576"), MATCH(J$1, SepR!$6:$6, 0), FALSE), 0 ) + IFERROR( VLOOKUP($A14, INDIRECT("OctR!$A$6:$ZZ$1048576"), MATCH(J$1, OctR!$6:$6, 0), FALSE), 0 ) + IFERROR( VLOOKUP($A14, INDIRECT("NovR!$A$6:$ZZ$1048576"), MATCH(J$1, NovR!$6:$6, 0), FALSE), 0 ) + IFERROR( VLOOKUP($A14, INDIRECT("DicR!$A$6:$ZZ$1048576"), MATCH(J$1, DicR!$6:$6, 0), FALSE), 0 ) )} -> 0 | K14: {=SUM( IFERROR( VLOOKUP($A14, INDIRECT("EneR!$A$6:$ZZ$1048576"), MATCH(K$1, EneR!$6:$6, 0), FALSE), 0 ) + IFERROR( VLOOKUP($A14, INDIRECT("FebR!$A$6:$ZZ$1048576"), MATCH(K$1, FebR!$6:$6, 0), FALSE), 0 ) + IFERROR( VLOOKUP($A14, INDIRECT("MarR!$A$6:$ZZ$1048576"), MATCH(K$1, MarR!$6:$6, 0), FALSE), 0 ) + IFERROR( VLOOKUP($A14, INDIRECT("AbrR!$A$6:$ZZ$1048576"), MATCH(K$1, AbrR!$6:$6, 0), FALSE), 0 ) + IFERROR( VLOOKUP($A14, INDIRECT("MayR!$A$6:$ZZ$1048576"), MATCH(K$1, MayR!$6:$6, 0), FALSE), 0 ) + IFERROR( VLOOKUP($A14, INDIRECT("JunR!$A$6:$ZZ$1048576"), MATCH(K$1, JunR!$6:$6, 0), FALSE), 0 ) + IFERROR( VLOOKUP($A14, INDIRECT("JulR!$A$6:$ZZ$1048576"), MATCH(K$1, JulR!$6:$6, 0), FALSE), 0 ) + IFERROR( VLOOKUP($A14, INDIRECT("AgoR!$A$6:$ZZ$1048576"), MATCH(K$1, AgoR!$6:$6, 0), FALSE), 0 ) + IFERROR( VLOOKUP($A14, INDIRECT("SepR!$A$6:$ZZ$1048576"), MATCH(K$1, SepR!$6:$6, 0), FALSE), 0 ) + IFERROR( VLOOKUP($A14, INDIRECT("OctR!$A$6:$ZZ$1048576"), MATCH(K$1, OctR!$6:$6, 0), FALSE), 0 ) + IFERROR( VLOOKUP($A14, INDIRECT("NovR!$A$6:$ZZ$1048576"), MATCH(K$1, NovR!$6:$6, 0), FALSE), 0 ) + IFERROR( VLOOKUP($A14, INDIRECT("DicR!$A$6:$ZZ$1048576"), MATCH(K$1, DicR!$6:$6, 0), FALSE), 0 ) )} -> 0 | ... AY14: {=SUM( IFERROR( VLOOKUP($A14, INDIRECT("EneR!$A$6:$ZZ$1048576"), MATCH(AY$1, EneR!$6:$6, 0), FALSE), 0 ) + IFERROR( VLOOKUP($A14, INDIRECT("FebR!$A$6:$ZZ$1048576"), MATCH(AY$1, FebR!$6:$6, 0), FALSE), 0 ) + IFERROR( VLOOKUP($A14, INDIRECT("MarR!$A$6:$ZZ$1048576"), MATCH(AY$1, MarR!$6:$6, 0), FALSE), 0 ) + IFERROR( VLOOKUP($A14, INDIRECT("AbrR!$A$6:$ZZ$1048576"), MATCH(AY$1, AbrR!$6:$6, 0), FALSE), 0 ) + IFERROR( VLOOKUP($A14, INDIRECT("MayR!$A$6:$ZZ$1048576"), MATCH(AY$1, MayR!$6:$6, 0), FALSE), 0 ) + IFERROR( VLOOKUP($A14, INDIRECT("JunR!$A$6:$ZZ$1048576"), MATCH(AY$1, JunR!$6:$6, 0), FALSE), 0 ) + IFERROR( VLOOKUP($A14, INDIRECT("JulR!$A$6:$ZZ$1048576"), MATCH(AY$1, JulR!$6:$6, 0), FALSE), 0 ) + IFERROR( VLOOKUP($A14, INDIRECT("AgoR!$A$6:$ZZ$1048576"), MATCH(AY$1, AgoR!$6:$6, 0), FALSE), 0 ) + IFERROR( VLOOKUP($A14, INDIRECT("SepR!$A$6:$ZZ$1048576"), MATCH(AY$1, SepR!$6:$6, 0), FALSE), 0 ) + IFERROR( VLOOKUP($A14, INDIRECT("OctR!$A$6:$ZZ$1048576"), MATCH(AY$1, OctR!$6:$6, 0), FALSE), 0 ) + IFERROR( VLOOKUP($A14, INDIRECT("NovR!$A$6:$ZZ$1048576"), MATCH(AY$1, NovR!$6:$6, 0), FALSE), 0 ) + IFERROR( VLOOKUP($A14, INDIRECT("DicR!$A$6:$ZZ$1048576"), MATCH(AY$1, DicR!$6:$6, 0), FALSE), 0 ) )} -> 0
