Workbook

Sheet Acumulado
A1: Sigmaseg S.A. de C.V. | B1: Anual R | C1: Enero | D1: Febrero | E1: Marzo | F1: Abril | G1: Mayo | H1: Junio | I1: Julio | J1: Agosto | K1: Septiembre | L1: Octubre | M1: Noviembre | N1: Diciembre
A3: Utilidad Bruta | B3: =B5-B10+B49-B54 -> 0 | C3: =C5-C10+C49-C54 -> 3185663.1 | D3: =D5-D10+D49-D54 -> 3145495.9 | E3: =E5-E10+E49-E54 -> 3195106.8 | F3: =F5-F10+F49-F54 -> 3039340 | G3: =G5-G10+G49-G54 -> 3048710.1 | H3: =H5-H10+H49-H54 -> 3046771.3 | I3: =I5-I10+I49-I54 -> 3012037.1 | ... N3: =N5-N10+N49-N54 -> 0
A5: Total de Ingresos | B5: =SUM(B6:B8) -> 0 | C5: =SUM(C6:C8) -> 3185663.1 | D5: =SUM(D6:D8) -> 3145495.9 | E5: =SUM(E6:E8) -> 3195106.8 | F5: =SUM(F6:F8) -> 3039340 | G5: =SUM(G6:G8) -> 3048710.1 | H5: =SUM(H6:H8) -> 3046771.3 | I5: =SUM(I6:I8) -> 3012037.1 | ... N5: =SUM(N6:N8) -> 0
A6: A01 Seguridad | B6: =SUM(IF(MONTH(TODAY())>1,C6,0), IF(MONTH(TODAY())>2,D6,0), IF(MONTH(TODAY())>3,E6,0), IF(MONTH(TODAY())>4,F6,0), IF(MONTH(TODAY())>5,G6,0), IF(MONTH(TODAY())>6,H6,0), IF(MONTH(TODAY())>7,I6,0), IF(MONTH(TODAY())>8,J6,0), IF(MONTH(TODAY())>9,K6,0), IF(MONTH(TODAY())>10,L6,0), IF(MONTH(TODAY())>11,M6,0), IF(MONTH(TODAY())>12,N6,0)) -> 0 | C6: =IFERROR( LET( hoja, LEFT(C$1,3)&"R", fila, MATCH( RIGHT($A6, LEN($A6)-4), INDIRECT(hoja&"!$A:$A"), 0 ), columna, MATCH( "Totales", INDIRECT(hoja&"!$6:$6"), 0 ), valor, INDEX( INDIRECT(hoja&"!$A:$ZZ"), fila, columna ), IF(valor="-", "", valor) ), "") -> 3185663.1 | D6: =IFERROR( LET( hoja, LEFT(D$1,3)&"R", fila, MATCH( RIGHT($A6, LEN($A6)-4), INDIRECT(hoja&"!$A:$A"), 0 ), columna, MATCH( "Totales", INDIRECT(hoja&"!$6:$6"), 0 ), valor, INDEX( INDIRECT(hoja&"!$A:$ZZ"), fila, columna ), IF(valor="-", "", valor) ), "") -> 3145495.9 | E6: =IFERROR( LET( hoja, LEFT(E$1,3)&"R", fila, MATCH( RIGHT($A6, LEN($A6)-4), INDIRECT(hoja&"!$A:$A"), 0 ), columna, MATCH( "Totales", INDIRECT(hoja&"!$6:$6"), 0 ), valor, INDEX( INDIRECT(hoja&"!$A:$ZZ"), fila, columna ), IF(valor="-", "", valor) ), "") -> 3173506.8 | F6: =IFERROR( LET( hoja, LEFT(F$1,3)&"R", fila, MATCH( RIGHT($A6, LEN($A6)-4), INDIRECT(hoja&"!$A:$A"), 0 ), columna, MATCH( "Totales", INDIRECT(hoja&"!$6:$6"), 0 ), valor, INDEX( INDIRECT(hoja&"!$A:$ZZ"), fila, columna ), IF(valor="-", "", valor) ), "") -> 3017740 | G6: =IFERROR( LET( hoja, LEFT(G$1,3)&"R", fila, MATCH( RIGHT($A6, LEN($A6)-4), INDIRECT(hoja&"!$A:$A"), 0 ), columna, MATCH( "Totales", INDIRECT(hoja&"!$6:$6"), 0 ), valor, INDEX( INDIRECT(hoja&"!$A:$ZZ"), fila, columna ), IF(valor="-", "", valor) ), "") -> 3027110.1 | H6: =IFERROR( LET( hoja, LEFT(H$1,3)&"R", fila, MATCH( RIGHT($A6, LEN($A6)-4), INDIRECT(hoja&"!$A:$A"), 0 ), columna, MATCH( "Totales", INDIRECT(hoja&"!$6:$6"), 0 ), valor, INDEX( INDIRECT(hoja&"!$A:$ZZ"), fila, columna ), IF(valor="-", "", valor) ), "") -> 3025171.3 | I6: =IFERROR( LET( hoja, LEFT(I$1,3)&"R", fila, MATCH( RIGHT($A6, LEN($A6)-4), INDIRECT(hoja&"!$A:$A"), 0 ), columna, MATCH( "Totales", INDIRECT(hoja&"!$6:$6"), 0 ), valor, INDEX( INDIRECT(hoja&"!$A:$ZZ"), fila, columna ), IF(valor="-", "", valor) ), "") -> 2990437.1 | J6: =IFERROR( LET( hoja, LEFT(J$1,3)&"R", fila, MATCH( RIGHT($A6, LEN($A6)-4), INDIRECT(hoja&"!$A:$A"), 0 ), columna, MATCH( "Totales", INDIRECT(hoja&"!$6:$6"), 0 ), valor, INDEX( INDIRECT(hoja&"!$A:$ZZ"), fila, columna ), IF(valor="-", "", valor) ), "") | ... N6: =IFERROR( LET( hoja, LEFT(N$1,3)&"R", fila, MATCH( RIGHT($A6, LEN($A6)-4), INDIRECT(hoja&"!$A:$A"), 0 ), columna, MATCH( "Totales", INDIRECT(hoja&"!$6:$6"), 0 ), valor, INDEX( INDIRECT(hoja&"!$A:$ZZ"), fila, columna ), IF(valor="-", "", valor) ), "")
A7: A02 Monitoreo | B7: =SUM(IF(MONTH(TODAY())>1,C7,0), IF(MONTH(TODAY())>2,D7,0), IF(MONTH(TODAY())>3,E7,0), IF(MONTH(TODAY())>4,F7,0), IF(MONTH(TODAY())>5,G7,0), IF(MONTH(TODAY())>6,H7,0), IF(MONTH(TODAY())>7,I7,0), IF(MONTH(TODAY())>8,J7,0), IF(MONTH(TODAY())>9,K7,0), IF(MONTH(TODAY())>10,L7,0), IF(MONTH(TODAY())>11,M7,0), IF(MONTH(TODAY())>12,N7,0)) -> 0 | C7: =IFERROR( LET( hoja, LEFT(C$1,3)&"R", fila, MATCH( RIGHT($A7, LEN($A7)-4), INDIRECT(hoja&"!$A:$A"), 0 ), columna, MATCH( "Totales", INDIRECT(hoja&"!$6:$6"), 0 ), valor, INDEX( INDIRECT(hoja&"!$A:$ZZ"), fila, columna ), IF(valor="-", "", valor) ), "") | D7: =IFERROR( LET( hoja, LEFT(D$1,3)&"R", fila, MATCH( RIGHT($A7, LEN($A7)-4), INDIRECT(hoja&"!$A:$A"), 0 ), columna, MATCH( "Totales", INDIRECT(hoja&"!$6:$6"), 0 ), valor, INDEX( INDIRECT(hoja&"!$A:$ZZ"), fila, columna ), IF(valor="-", "", valor) ), "") | E7: =IFERROR( LET( hoja, LEFT(E$1,3)&"R", fila, MATCH( RIGHT($A7, LEN($A7)-4), INDIRECT(hoja&"!$A:$A"), 0 ), columna, MATCH( "Totales", INDIRECT(hoja&"!$6:$6"), 0 ), valor, INDEX( INDIRECT(hoja&"!$A:$ZZ"), fila, columna ), IF(valor="-", "", valor) ), "") -> 21600 | F7: =IFERROR( LET( hoja, LEFT(F$1,3)&"R", fila, MATCH( RIGHT($A7, LEN($A7)-4), INDIRECT(hoja&"!$A:$A"), 0 ), columna, MATCH( "Totales", INDIRECT(hoja&"!$6:$6"), 0 ), valor, INDEX( INDIRECT(hoja&"!$A:$ZZ"), fila, columna ), IF(valor="-", "", valor) ), "") -> 21600 | G7: =IFERROR( LET( hoja, LEFT(G$1,3)&"R", fila, MATCH( RIGHT($A7, LEN($A7)-4), INDIRECT(hoja&"!$A:$A"), 0 ), columna, MATCH( "Totales", INDIRECT(hoja&"!$6:$6"), 0 ), valor, INDEX( INDIRECT(hoja&"!$A:$ZZ"), fila, columna ), IF(valor="-", "", valor) ), "") -> 21600 | H7: =IFERROR( LET( hoja, LEFT(H$1,3)&"R", fila, MATCH( RIGHT($A7, LEN($A7)-4), INDIRECT(hoja&"!$A:$A"), 0 ), columna, MATCH( "Totales", INDIRECT(hoja&"!$6:$6"), 0 ), valor, INDEX( INDIRECT(hoja&"!$A:$ZZ"), fila, columna ), IF(valor="-", "", valor) ), "") -> 21600 | I7: =IFERROR( LET( hoja, LEFT(I$1,3)&"R", fila, MATCH( RIGHT($A7, LEN($A7)-4), INDIRECT(hoja&"!$A:$A"), 0 ), columna, MATCH( "Totales", INDIRECT(hoja&"!$6:$6"), 0 ), valor, INDEX( INDIRECT(hoja&"!$A:$ZZ"), fila, columna ), IF(valor="-", "", valor) ), "") -> 21600 | J7: =IFERROR( LET( hoja, LEFT(J$1,3)&"R", fila, MATCH( RIGHT($A7, LEN($A7)-4), INDIRECT(hoja&"!$A:$A"), 0 ), columna, MATCH( "Totales", INDIRECT(hoja&"!$6:$6"), 0 ), valor, INDEX( INDIRECT(hoja&"!$A:$ZZ"), fila, columna ), IF(valor="-", "", valor) ), "") | ... N7: =IFERROR( LET( hoja, LEFT(N$1,3)&"R", fila, MATCH( RIGHT($A7, LEN($A7)-4), INDIRECT(hoja&"!$A:$A"), 0 ), columna, MATCH( "Totales", INDIRECT(hoja&"!$6:$6"), 0 ), valor, INDEX( INDIRECT(hoja&"!$A:$ZZ"), fila, columna ), IF(valor="-", "", valor) ), "")
B8: =SUM(IF(MONTH(TODAY())>1,C8,0), IF(MONTH(TODAY())>2,D8,0), IF(MONTH(TODAY())>3,E8,0), IF(MONTH(TODAY())>4,F8,0), IF(MONTH(TODAY())>5,G8,0), IF(MONTH(TODAY())>6,H8,0), IF(MONTH(TODAY())>7,I8,0), IF(MONTH(TODAY())>8,J8,0), IF(MONTH(TODAY())>9,K8,0), IF(MONTH(TODAY())>10,L8,0), IF(MONTH(TODAY())>11,M8,0), IF(MONTH(TODAY())>12,N8,0)) -> 0 | C8: =IFERROR( LET( hoja, LEFT(C$1,3)&"R", fila, MATCH( RIGHT($A8, LEN($A8)-4), INDIRECT(hoja&"!$A:$A"), 0 ), columna, MATCH( "Totales", INDIRECT(hoja&"!$6:$6"), 0 ), valor, INDEX( INDIRECT(hoja&"!$A:$ZZ"), fila, columna ), IF(valor="-", "", valor) ), "") | D8: =IFERROR( LET( hoja, LEFT(D$1,3)&"R", fila, MATCH( RIGHT($A8, LEN($A8)-4), INDIRECT(hoja&"!$A:$A"), 0 ), columna, MATCH( "Totales", INDIRECT(hoja&"!$6:$6"), 0 ), valor, INDEX( INDIRECT(hoja&"!$A:$ZZ"), fila, columna ), IF(valor="-", "", valor) ), "") | E8: =IFERROR( LET( hoja, LEFT(E$1,3)&"R", fila, MATCH( RIGHT($A8, LEN($A8)-4), INDIRECT(hoja&"!$A:$A"), 0 ), columna, MATCH( "Totales", INDIRECT(hoja&"!$6:$6"), 0 ), valor, INDEX( INDIRECT(hoja&"!$A:$ZZ"), fila, columna ), IF(valor="-", "", valor) ), "") | F8: =IFERROR( LET( hoja, LEFT(F$1,3)&"R", fila, MATCH( RIGHT($A8, LEN($A8)-4), INDIRECT(hoja&"!$A:$A"), 0 ), columna, MATCH( "Totales", INDIRECT(hoja&"!$6:$6"), 0 ), valor, INDEX( INDIRECT(hoja&"!$A:$ZZ"), fila, columna ), IF(valor="-", "", valor) ), "") | G8: =IFERROR( LET( hoja, LEFT(G$1,3)&"R", fila, MATCH( RIGHT($A8, LEN($A8)-4), INDIRECT(hoja&"!$A:$A"), 0 ), columna, MATCH( "Totales", INDIRECT(hoja&"!$6:$6"), 0 ), valor, INDEX( INDIRECT(hoja&"!$A:$ZZ"), fila, columna ), IF(valor="-", "", valor) ), "") | H8: =IFERROR( LET( hoja, LEFT(H$1,3)&"R", fila, MATCH( RIGHT($A8, LEN($A8)-4), INDIRECT(hoja&"!$A:$A"), 0 ), columna, MATCH( "Totales", INDIRECT(hoja&"!$6:$6"), 0 ), valor, INDEX( INDIRECT(hoja&"!$A:$ZZ"), fila, columna ), IF(valor="-", "", valor) ), "") | I8: =IFERROR( LET( hoja, LEFT(I$1,3)&"R", fila, MATCH( RIGHT($A8, LEN($A8)-4), INDIRECT(hoja&"!$A:$A"), 0 ), columna, MATCH( "Totales", INDIRECT(hoja&"!$6:$6"), 0 ), valor, INDEX( INDIRECT(hoja&"!$A:$ZZ"), fila, columna ), IF(valor="-", "", valor) ), "") | J8: =IFERROR( LET( hoja, LEFT(J$1,3)&"R", fila, MATCH( RIGHT($A8, LEN($A8)-4), INDIRECT(hoja&"!$A:$A"), 0 ), columna, MATCH( "Totales", INDIRECT(hoja&"!$6:$6"), 0 ), valor, INDEX( INDIRECT(hoja&"!$A:$ZZ"), fila, columna ), IF(valor="-", "", valor) ), "") | ... N8: =IFERROR( LET( hoja, LEFT(N$1,3)&"R", fila, MATCH( RIGHT($A8, LEN($A8)-4), INDIRECT(hoja&"!$A:$A"), 0 ), columna, MATCH( "Totales", INDIRECT(hoja&"!$6:$6"), 0 ), valor, INDEX( INDIRECT(hoja&"!$A:$ZZ"), fila, columna ), IF(valor="-", "", valor) ), "")
A10: Total de Egresos | B10: =SUM(B11:B47) -> 0 | C10: =SUM(C11:C47) -> 0 | D10: =SUM(D11:D47) -> 0 | E10: =SUM(E11:E47) -> 0 | F10: =SUM(F11:F47) -> 0 | G10: =SUM(G11:G47) -> 0 | H10: =SUM(H11:H47) -> 0 | I10: =SUM(I11:I47) -> 0 | ... N10: =SUM(N11:N47) -> 0
A11: =Menus!B4 | B11: =SUM(IF(MONTH(TODAY())>1,C11,0), IF(MONTH(TODAY())>2,D11,0), IF(MONTH(TODAY())>3,E11,0), IF(MONTH(TODAY())>4,F11,0), IF(MONTH(TODAY())>5,G11,0), IF(MONTH(TODAY())>6,H11,0), IF(MONTH(TODAY())>7,I11,0), IF(MONTH(TODAY())>8,J11,0), IF(MONTH(TODAY())>9,K11,0), IF(MONTH(TODAY())>10,L11,0), IF(MONTH(TODAY())>11,M11,0), IF(MONTH(TODAY())>12,N11,0)) -> 0 | C11: =IFERROR( LET( hoja, LEFT(C$1,3)&"R", fila, MATCH( RIGHT($A11, LEN($A11)-4), INDIRECT(hoja&"!$A:$A"), 0 ), columna, MATCH( "Totales", INDIRECT(hoja&"!$6:$6"), 0 ), valor, INDEX( INDIRECT(hoja&"!$A:$ZZ"), fila, columna ), IF(valor="-", "", valor) ), "") | D11: =IFERROR( LET( hoja, LEFT(D$1,3)&"R", fila, MATCH( RIGHT($A11, LEN($A11)-4), INDIRECT(hoja&"!$A:$A"), 0 ), columna, MATCH( "Totales", INDIRECT(hoja&"!$6:$6"), 0 ), valor, INDEX( INDIRECT(hoja&"!$A:$ZZ"), fila, columna ), IF(valor="-", "", valor) ), "") | E11: =IFERROR( LET( hoja, LEFT(E$1,3)&"R", fila, MATCH( RIGHT($A11, LEN($A11)-4), INDIRECT(hoja&"!$A:$A"), 0 ), columna, MATCH( "Totales", INDIRECT(hoja&"!$6:$6"), 0 ), valor, INDEX( INDIRECT(hoja&"!$A:$ZZ"), fila, columna ), IF(valor="-", "", valor) ), "") | F11: =IFERROR( LET( hoja, LEFT(F$1,3)&"R", fila, MATCH( RIGHT($A11, LEN($A11)-4), INDIRECT(hoja&"!$A:$A"), 0 ), columna, MATCH( "Totales", INDIRECT(hoja&"!$6:$6"), 0 ), valor, INDEX( INDIRECT(hoja&"!$A:$ZZ"), fila, columna ), IF(valor="-", "", valor) ), "") | G11: =IFERROR( LET( hoja, LEFT(G$1,3)&"R", fila, MATCH( RIGHT($A11, LEN($A11)-4), INDIRECT(hoja&"!$A:$A"), 0 ), columna, MATCH( "Totales", INDIRECT(hoja&"!$6:$6"), 0 ), valor, INDEX( INDIRECT(hoja&"!$A:$ZZ"), fila, columna ), IF(valor="-", "", valor) ), "") | H11: =IFERROR( LET( hoja, LEFT(H$1,3)&"R", fila, MATCH( RIGHT($A11, LEN($A11)-4), INDIRECT(hoja&"!$A:$A"), 0 ), columna, MATCH( "Totales", INDIRECT(hoja&"!$6:$6"), 0 ), valor, INDEX( INDIRECT(hoja&"!$A:$ZZ"), fila, columna ), IF(valor="-", "", valor) ), "") | I11: =IFERROR( LET( hoja, LEFT(I$1,3)&"R", fila, MATCH( RIGHT($A11, LEN($A11)-4), INDIRECT(hoja&"!$A:$A"), 0 ), columna, MATCH( "Totales", INDIRECT(hoja&"!$6:$6"), 0 ), valor, INDEX( INDIRECT(hoja&"!$A:$ZZ"), fila, columna ), IF(valor="-", "", valor) ), "") | J11: =IFERROR( LET( hoja, LEFT(J$1,3)&"R", fila, MATCH( RIGHT($A11, LEN($A11)-4), INDIRECT(hoja&"!$A:$A"), 0 ), columna, MATCH( "Totales", INDIRECT(hoja&"!$6:$6"), 0 ), valor, INDEX( INDIRECT(hoja&"!$A:$ZZ"), fila, columna ), IF(valor="-", "", valor) ), "") | ... N11: =IFERROR( LET( hoja, LEFT(N$1,3)&"R", fila, MATCH( RIGHT($A11, LEN($A11)-4), INDIRECT(hoja&"!$A:$A"), 0 ), columna, MATCH( "Totales", INDIRECT(hoja&"!$6:$6"), 0 ), valor, INDEX( INDIRECT(hoja&"!$A:$ZZ"), fila, columna ), IF(valor="-", "", valor) ), "")
A12: =Menus!B5 | B12: =SUM(IF(MONTH(TODAY())>1,C12,0), IF(MONTH(TODAY())>2,D12,0), IF(MONTH(TODAY())>3,E12,0), IF(MONTH(TODAY())>4,F12,0), IF(MONTH(TODAY())>5,G12,0), IF(MONTH(TODAY())>6,H12,0), IF(MONTH(TODAY())>7,I12,0), IF(MONTH(TODAY())>8,J12,0), IF(MONTH(TODAY())>9,K12,0), IF(MONTH(TODAY())>10,L12,0), IF(MONTH(TODAY())>11,M12,0), IF(MONTH(TODAY())>12,N12,0)) -> 0 | C12: =IFERROR( LET( hoja, LEFT(C$1,3)&"R", fila, MATCH( RIGHT($A12, LEN($A12)-4), INDIRECT(hoja&"!$A:$A"), 0 ), columna, MATCH( "Totales", INDIRECT(hoja&"!$6:$6"), 0 ), valor, INDEX( INDIRECT(hoja&"!$A:$ZZ"), fila, columna ), IF(valor="-", "", valor) ), "") | D12: =IFERROR( LET( hoja, LEFT(D$1,3)&"R", fila, MATCH( RIGHT($A12, LEN($A12)-4), INDIRECT(hoja&"!$A:$A"), 0 ), columna, MATCH( "Totales", INDIRECT(hoja&"!$6:$6"), 0 ), valor, INDEX( INDIRECT(hoja&"!$A:$ZZ"), fila, columna ), IF(valor="-", "", valor) ), "") | E12: =IFERROR( LET( hoja, LEFT(E$1,3)&"R", fila, MATCH( RIGHT($A12, LEN($A12)-4), INDIRECT(hoja&"!$A:$A"), 0 ), columna, MATCH( "Totales", INDIRECT(hoja&"!$6:$6"), 0 ), valor, INDEX( INDIRECT(hoja&"!$A:$ZZ"), fila, columna ), IF(valor="-", "", valor) ), "") | F12: =IFERROR( LET( hoja, LEFT(F$1,3)&"R", fila, MATCH( RIGHT($A12, LEN($A12)-4), INDIRECT(hoja&"!$A:$A"), 0 ), columna, MATCH( "Totales", INDIRECT(hoja&"!$6:$6"), 0 ), valor, INDEX( INDIRECT(hoja&"!$A:$ZZ"), fila, columna ), IF(valor="-", "", valor) ), "") | G12: =IFERROR( LET( hoja, LEFT(G$1,3)&"R", fila, MATCH( RIGHT($A12, LEN($A12)-4), INDIRECT(hoja&"!$A:$A"), 0 ), columna, MATCH( "Totales", INDIRECT(hoja&"!$6:$6"), 0 ), valor, INDEX( INDIRECT(hoja&"!$A:$ZZ"), fila, columna ), IF(valor="-", "", valor) ), "") | H12: =IFERROR( LET( hoja, LEFT(H$1,3)&"R", fila, MATCH( RIGHT($A12, LEN($A12)-4), INDIRECT(hoja&"!$A:$A"), 0 ), columna, MATCH( "Totales", INDIRECT(hoja&"!$6:$6"), 0 ), valor, INDEX( INDIRECT(hoja&"!$A:$ZZ"), fila, columna ), IF(valor="-", "", valor) ), "") | I12: =IFERROR( LET( hoja, LEFT(I$1,3)&"R", fila, MATCH( RIGHT($A12, LEN($A12)-4), INDIRECT(hoja&"!$A:$A"), 0 ), columna, MATCH( "Totales", INDIRECT(hoja&"!$6:$6"), 0 ), valor, INDEX( INDIRECT(hoja&"!$A:$ZZ"), fila, columna ), IF(valor="-", "", valor) ), "") | J12: =IFERROR( LET( hoja, LEFT(J$1,3)&"R", fila, MATCH( RIGHT($A12, LEN($A12)-4), INDIRECT(hoja&"!$A:$A"), 0 ), columna, MATCH( "Totales", INDIRECT(hoja&"!$6:$6"), 0 ), valor, INDEX( INDIRECT(hoja&"!$A:$ZZ"), fila, columna ), IF(valor="-", "", valor) ), "") | ... N12: =IFERROR( LET( hoja, LEFT(N$1,3)&"R", fila, MATCH( RIGHT($A12, LEN($A12)-4), INDIRECT(hoja&"!$A:$A"), 0 ), columna, MATCH( "Totales", INDIRECT(hoja&"!$6:$6"), 0 ), valor, INDEX( INDIRECT(hoja&"!$A:$ZZ"), fila, columna ), IF(valor="-", "", valor) ), "")
A13: =Menus!B6 | B13: =SUM(IF(MONTH(TODAY())>1,C13,0), IF(MONTH(TODAY())>2,D13,0), IF(MONTH(TODAY())>3,E13,0), IF(MONTH(TODAY())>4,F13,0), IF(MONTH(TODAY())>5,G13,0), IF(MONTH(TODAY())>6,H13,0), IF(MONTH(TODAY())>7,I13,0), IF(MONTH(TODAY())>8,J13,0), IF(MONTH(TODAY())>9,K13,0), IF(MONTH(TODAY())>10,L13,0), IF(MONTH(TODAY())>11,M13,0), IF(MONTH(TODAY())>12,N13,0)) -> 0 | C13: =IFERROR( LET( hoja, LEFT(C$1,3)&"R", fila, MATCH( RIGHT($A13, LEN($A13)-4), INDIRECT(hoja&"!$A:$A"), 0 ), columna, MATCH( "Totales", INDIRECT(hoja&"!$6:$6"), 0 ), valor, INDEX( INDIRECT(hoja&"!$A:$ZZ"), fila, columna ), IF(valor="-", "", valor) ), "") | D13: =IFERROR( LET( hoja, LEFT(D$1,3)&"R", fila, MATCH( RIGHT($A13, LEN($A13)-4), INDIRECT(hoja&"!$A:$A"), 0 ), columna, MATCH( "Totales", INDIRECT(hoja&"!$6:$6"), 0 ), valor, INDEX( INDIRECT(hoja&"!$A:$ZZ"), fila, columna ), IF(valor="-", "", valor) ), "") | E13: =IFERROR( LET( hoja, LEFT(E$1,3)&"R", fila, MATCH( RIGHT($A13, LEN($A13)-4), INDIRECT(hoja&"!$A:$A"), 0 ), columna, MATCH( "Totales", INDIRECT(hoja&"!$6:$6"), 0 ), valor, INDEX( INDIRECT(hoja&"!$A:$ZZ"), fila, columna ), IF(valor="-", "", valor) ), "") | F13: =IFERROR( LET( hoja, LEFT(F$1,3)&"R", fila, MATCH( RIGHT($A13, LEN($A13)-4), INDIRECT(hoja&"!$A:$A"), 0 ), columna, MATCH( "Totales", INDIRECT(hoja&"!$6:$6"), 0 ), valor, INDEX( INDIRECT(hoja&"!$A:$ZZ"), fila, columna ), IF(valor="-", "", valor) ), "") | G13: =IFERROR( LET( hoja, LEFT(G$1,3)&"R", fila, MATCH( RIGHT($A13, LEN($A13)-4), INDIRECT(hoja&"!$A:$A"), 0 ), columna, MATCH( "Totales", INDIRECT(hoja&"!$6:$6"), 0 ), valor, INDEX( INDIRECT(hoja&"!$A:$ZZ"), fila, columna ), IF(valor="-", "", valor) ), "") | H13: =IFERROR( LET( hoja, LEFT(H$1,3)&"R", fila, MATCH( RIGHT($A13, LEN($A13)-4), INDIRECT(hoja&"!$A:$A"), 0 ), columna, MATCH( "Totales", INDIRECT(hoja&"!$6:$6"), 0 ), valor, INDEX( INDIRECT(hoja&"!$A:$ZZ"), fila, columna ), IF(valor="-", "", valor) ), "") | I13: =IFERROR( LET( hoja, LEFT(I$1,3)&"R", fila, MATCH( RIGHT($A13, LEN($A13)-4), INDIRECT(hoja&"!$A:$A"), 0 ), columna, MATCH( "Totales", INDIRECT(hoja&"!$6:$6"), 0 ), valor, INDEX( INDIRECT(hoja&"!$A:$ZZ"), fila, columna ), IF(valor="-", "", valor) ), "") | J13: =IFERROR( LET( hoja, LEFT(J$1,3)&"R", fila, MATCH( RIGHT($A13, LEN($A13)-4), INDIRECT(hoja&"!$A:$A"), 0 ), columna, MATCH( "Totales", INDIRECT(hoja&"!$6:$6"), 0 ), valor, INDEX( INDIRECT(hoja&"!$A:$ZZ"), fila, columna ), IF(valor="-", "", valor) ), "") | ... N13: =IFERROR( LET( hoja, LEFT(N$1,3)&"R", fila, MATCH( RIGHT($A13, LEN($A13)-4), INDIRECT(hoja&"!$A:$A"), 0 ), columna, MATCH( "Totales", INDIRECT(hoja&"!$6:$6"), 0 ), valor, INDEX( INDIRECT(hoja&"!$A:$ZZ"), fila, columna ), IF(valor="-", "", valor) ), "")
A14: =Menus!B7 | B14: =SUM(IF(MONTH(TODAY())>1,C14,0), IF(MONTH(TODAY())>2,D14,0), IF(MONTH(TODAY())>3,E14,0), IF(MONTH(TODAY())>4,F14,0), IF(MONTH(TODAY())>5,G14,0), IF(MONTH(TODAY())>6,H14,0), IF(MONTH(TODAY())>7,I14,0), IF(MONTH(TODAY())>8,J14,0), IF(MONTH(TODAY())>9,K14,0), IF(MONTH(TODAY())>10,L14,0), IF(MONTH(TODAY())>11,M14,0), IF(MONTH(TODAY())>12,N14,0)) -> 0 | C14: =IFERROR( LET( hoja, LEFT(C$1,3)&"R", fila, MATCH( RIGHT($A14, LEN($A14)-4), INDIRECT(hoja&"!$A:$A"), 0 ), columna, MATCH( "Totales", INDIRECT(hoja&"!$6:$6"), 0 ), valor, INDEX( INDIRECT(hoja&"!$A:$ZZ"), fila, columna ), IF(valor="-", "", valor) ), "") | D14: =IFERROR( LET( hoja, LEFT(D$1,3)&"R", fila, MATCH( RIGHT($A14, LEN($A14)-4), INDIRECT(hoja&"!$A:$A"), 0 ), columna, MATCH( "Totales", INDIRECT(hoja&"!$6:$6"), 0 ), valor, INDEX( INDIRECT(hoja&"!$A:$ZZ"), fila, columna ), IF(valor="-", "", valor) ), "") | E14: =IFERROR( LET( hoja, LEFT(E$1,3)&"R", fila, MATCH( RIGHT($A14, LEN($A14)-4), INDIRECT(hoja&"!$A:$A"), 0 ), columna, MATCH( "Totales", INDIRECT(hoja&"!$6:$6"), 0 ), valor, INDEX( INDIRECT(hoja&"!$A:$ZZ"), fila, columna ), IF(valor="-", "", valor) ), "") | F14: =IFERROR( LET( hoja, LEFT(F$1,3)&"R", fila, MATCH( RIGHT($A14, LEN($A14)-4), INDIRECT(hoja&"!$A:$A"), 0 ), columna, MATCH( "Totales", INDIRECT(hoja&"!$6:$6"), 0 ), valor, INDEX( INDIRECT(hoja&"!$A:$ZZ"), fila, columna ), IF(valor="-", "", valor) ), "") | G14: =IFERROR( LET( hoja, LEFT(G$1,3)&"R", fila, MATCH( RIGHT($A14, LEN($A14)-4), INDIRECT(hoja&"!$A:$A"), 0 ), columna, MATCH( "Totales", INDIRECT(hoja&"!$6:$6"), 0 ), valor, INDEX( INDIRECT(hoja&"!$A:$ZZ"), fila, columna ), IF(valor="-", "", valor) ), "") | H14: =IFERROR( LET( hoja, LEFT(H$1,3)&"R", fila, MATCH( RIGHT($A14, LEN($A14)-4), INDIRECT(hoja&"!$A:$A"), 0 ), columna, MATCH( "Totales", INDIRECT(hoja&"!$6:$6"), 0 ), valor, INDEX( INDIRECT(hoja&"!$A:$ZZ"), fila, columna ), IF(valor="-", "", valor) ), "") | I14: =IFERROR( LET( hoja, LEFT(I$1,3)&"R", fila, MATCH( RIGHT($A14, LEN($A14)-4), INDIRECT(hoja&"!$A:$A"), 0 ), columna, MATCH( "Totales", INDIRECT(hoja&"!$6:$6"), 0 ), valor, INDEX( INDIRECT(hoja&"!$A:$ZZ"), fila, columna ), IF(valor="-", "", valor) ), "") | J14: =IFERROR( LET( hoja, LEFT(J$1,3)&"R", fila, MATCH( RIGHT($A14, LEN($A14)-4), INDIRECT(hoja&"!$A:$A"), 0 ), columna, MATCH( "Totales", INDIRECT(hoja&"!$6:$6"), 0 ), valor, INDEX( INDIRECT(hoja&"!$A:$ZZ"), fila, columna ), IF(valor="-", "", valor) ), "") | ... N14: =IFERROR( LET( hoja, LEFT(N$1,3)&"R", fila, MATCH( RIGHT($A14, LEN($A14)-4), INDIRECT(hoja&"!$A:$A"), 0 ), columna, MATCH( "Totales", INDIRECT(hoja&"!$6:$6"), 0 ), valor, INDEX( INDIRECT(hoja&"!$A:$ZZ"), fila, columna ), IF(valor="-", "", valor) ), "")
A15: =Menus!B8 | B15: =SUM(IF(MONTH(TODAY())>1,C15,0), IF(MONTH(TODAY())>2,D15,0), IF(MONTH(TODAY())>3,E15,0), IF(MONTH(TODAY())>4,F15,0), IF(MONTH(TODAY())>5,G15,0), IF(MONTH(TODAY())>6,H15,0), IF(MONTH(TODAY())>7,I15,0), IF(MONTH(TODAY())>8,J15,0), IF(MONTH(TODAY())>9,K15,0), IF(MONTH(TODAY())>10,L15,0), IF(MONTH(TODAY())>11,M15,0), IF(MONTH(TODAY())>12,N15,0)) -> 0 | C15: =IFERROR( LET( hoja, LEFT(C$1,3)&"R", fila, MATCH( RIGHT($A15, LEN($A15)-4), INDIRECT(hoja&"!$A:$A"), 0 ), columna, MATCH( "Totales", INDIRECT(hoja&"!$6:$6"), 0 ), valor, INDEX( INDIRECT(hoja&"!$A:$ZZ"), fila, columna ), IF(valor="-", "", valor) ), "") | D15: =IFERROR( LET( hoja, LEFT(D$1,3)&"R", fila, MATCH( RIGHT($A15, LEN($A15)-4), INDIRECT(hoja&"!$A:$A"), 0 ), columna, MATCH( "Totales", INDIRECT(hoja&"!$6:$6"), 0 ), valor, INDEX( INDIRECT(hoja&"!$A:$ZZ"), fila, columna ), IF(valor="-", "", valor) ), "") | E15: =IFERROR( LET( hoja, LEFT(E$1,3)&"R", fila, MATCH( RIGHT($A15, LEN($A15)-4), INDIRECT(hoja&"!$A:$A"), 0 ), columna, MATCH( "Totales", INDIRECT(hoja&"!$6:$6"), 0 ), valor, INDEX( INDIRECT(hoja&"!$A:$ZZ"), fila, columna ), IF(valor="-", "", valor) ), "") | F15: =IFERROR( LET( hoja, LEFT(F$1,3)&"R", fila, MATCH( RIGHT($A15, LEN($A15)-4), INDIRECT(hoja&"!$A:$A"), 0 ), columna, MATCH( "Totales", INDIRECT(hoja&"!$6:$6"), 0 ), valor, INDEX( INDIRECT(hoja&"!$A:$ZZ"), fila, columna ), IF(valor="-", "", valor) ), "") | G15: =IFERROR( LET( hoja, LEFT(G$1,3)&"R", fila, MATCH( RIGHT($A15, LEN($A15)-4), INDIRECT(hoja&"!$A:$A"), 0 ), columna, MATCH( "Totales", INDIRECT(hoja&"!$6:$6"), 0 ), valor, INDEX( INDIRECT(hoja&"!$A:$ZZ"), fila, columna ), IF(valor="-", "", valor) ), "") | H15: =IFERROR( LET( hoja, LEFT(H$1,3)&"R", fila, MATCH( RIGHT($A15, LEN($A15)-4), INDIRECT(hoja&"!$A:$A"), 0 ), columna, MATCH( "Totales", INDIRECT(hoja&"!$6:$6"), 0 ), valor, INDEX( INDIRECT(hoja&"!$A:$ZZ"), fila, columna ), IF(valor="-", "", valor) ), "") | I15: =IFERROR( LET( hoja, LEFT(I$1,3)&"R", fila, MATCH( RIGHT($A15, LEN($A15)-4), INDIRECT(hoja&"!$A:$A"), 0 ), columna, MATCH( "Totales", INDIRECT(hoja&"!$6:$6"), 0 ), valor, INDEX( INDIRECT(hoja&"!$A:$ZZ"), fila, columna ), IF(valor="-", "", valor) ), "") | J15: =IFERROR( LET( hoja, LEFT(J$1,3)&"R", fila, MATCH( RIGHT($A15, LEN($A15)-4), INDIRECT(hoja&"!$A:$A"), 0 ), columna, MATCH( "Totales", INDIRECT(hoja&"!$6:$6"), 0 ), valor, INDEX( INDIRECT(hoja&"!$A:$ZZ"), fila, columna ), IF(valor="-", "", valor) ), "") | ... N15: =IFERROR( LET( hoja, LEFT(N$1,3)&"R", fila, MATCH( RIGHT($A15, LEN($A15)-4), INDIRECT(hoja&"!$A:$A"), 0 ), columna, MATCH( "Totales", INDIRECT(hoja&"!$6:$6"), 0 ), valor, INDEX( INDIRECT(hoja&"!$A:$ZZ"), fila, columna ), IF(valor="-", "", valor) ), "")
A16: =Menus!B9 | B16: =SUM(IF(MONTH(TODAY())>1,C16,0), IF(MONTH(TODAY())>2,D16,0), IF(MONTH(TODAY())>3,E16,0), IF(MONTH(TODAY())>4,F16,0), IF(MONTH(TODAY())>5,G16,0), IF(MONTH(TODAY())>6,H16,0), IF(MONTH(TODAY())>7,I16,0), IF(MONTH(TODAY())>8,J16,0), IF(MONTH(TODAY())>9,K16,0), IF(MONTH(TODAY())>10,L16,0), IF(MONTH(TODAY())>11,M16,0), IF(MONTH(TODAY())>12,N16,0)) -> 0 | C16: =IFERROR( LET( hoja, LEFT(C$1,3)&"R", fila, MATCH( RIGHT($A16, LEN($A16)-4), INDIRECT(hoja&"!$A:$A"), 0 ), columna, MATCH( "Totales", INDIRECT(hoja&"!$6:$6"), 0 ), valor, INDEX( INDIRECT(hoja&"!$A:$ZZ"), fila, columna ), IF(valor="-", "", valor) ), "") | D16: =IFERROR( LET( hoja, LEFT(D$1,3)&"R", fila, MATCH( RIGHT($A16, LEN($A16)-4), INDIRECT(hoja&"!$A:$A"), 0 ), columna, MATCH( "Totales", INDIRECT(hoja&"!$6:$6"), 0 ), valor, INDEX( INDIRECT(hoja&"!$A:$ZZ"), fila, columna ), IF(valor="-", "", valor) ), "") | E16: =IFERROR( LET( hoja, LEFT(E$1,3)&"R", fila, MATCH( RIGHT($A16, LEN($A16)-4), INDIRECT(hoja&"!$A:$A"), 0 ), columna, MATCH( "Totales", INDIRECT(hoja&"!$6:$6"), 0 ), valor, INDEX( INDIRECT(hoja&"!$A:$ZZ"), fila, columna ), IF(valor="-", "", valor) ), "") | F16: =IFERROR( LET( hoja, LEFT(F$1,3)&"R", fila, MATCH( RIGHT($A16, LEN($A16)-4), INDIRECT(hoja&"!$A:$A"), 0 ), columna, MATCH( "Totales", INDIRECT(hoja&"!$6:$6"), 0 ), valor, INDEX( INDIRECT(hoja&"!$A:$ZZ"), fila, columna ), IF(valor="-", "", valor) ), "") | G16: =IFERROR( LET( hoja, LEFT(G$1,3)&"R", fila, MATCH( RIGHT($A16, LEN($A16)-4), INDIRECT(hoja&"!$A:$A"), 0 ), columna, MATCH( "Totales", INDIRECT(hoja&"!$6:$6"), 0 ), valor, INDEX( INDIRECT(hoja&"!$A:$ZZ"), fila, columna ), IF(valor="-", "", valor) ), "") | H16: =IFERROR( LET( hoja, LEFT(H$1,3)&"R", fila, MATCH( RIGHT($A16, LEN($A16)-4), INDIRECT(hoja&"!$A:$A"), 0 ), columna, MATCH( "Totales", INDIRECT(hoja&"!$6:$6"), 0 ), valor, INDEX( INDIRECT(hoja&"!$A:$ZZ"), fila, columna ), IF(valor="-", "", valor) ), "") | I16: =IFERROR( LET( hoja, LEFT(I$1,3)&"R", fila, MATCH( RIGHT($A16, LEN($A16)-4), INDIRECT(hoja&"!$A:$A"), 0 ), columna, MATCH( "Totales", INDIRECT(hoja&"!$6:$6"), 0 ), valor, INDEX( INDIRECT(hoja&"!$A:$ZZ"), fila, columna ), IF(valor="-", "", valor) ), "") | J16: =IFERROR( LET( hoja, LEFT(J$1,3)&"R", fila, MATCH( RIGHT($A16, LEN($A16)-4), INDIRECT(hoja&"!$A:$A"), 0 ), columna, MATCH( "Totales", INDIRECT(hoja&"!$6:$6"), 0 ), valor, INDEX( INDIRECT(hoja&"!$A:$ZZ"), fila, columna ), IF(valor="-", "", valor) ), "") | ... N16: =IFERROR( LET( hoja, LEFT(N$1,3)&"R", fila, MATCH( RIGHT($A16, LEN($A16)-4), INDIRECT(hoja&"!$A:$A"), 0 ), columna, MATCH( "Totales", INDIRECT(hoja&"!$6:$6"), 0 ), valor, INDEX( INDIRECT(hoja&"!$A:$ZZ"), fila, columna ), IF(valor="-", "", valor) ), "")
A17: =Menus!B10 | B17: =SUM(IF(MONTH(TODAY())>1,C17,0), IF(MONTH(TODAY())>2,D17,0), IF(MONTH(TODAY())>3,E17,0), IF(MONTH(TODAY())>4,F17,0), IF(MONTH(TODAY())>5,G17,0), IF(MONTH(TODAY())>6,H17,0), IF(MONTH(TODAY())>7,I17,0), IF(MONTH(TODAY())>8,J17,0), IF(MONTH(TODAY())>9,K17,0), IF(MONTH(TODAY())>10,L17,0), IF(MONTH(TODAY())>11,M17,0), IF(MONTH(TODAY())>12,N17,0)) -> 0 | C17: =IFERROR( LET( hoja, LEFT(C$1,3)&"R", fila, MATCH( RIGHT($A17, LEN($A17)-4), INDIRECT(hoja&"!$A:$A"), 0 ), columna, MATCH( "Totales", INDIRECT(hoja&"!$6:$6"), 0 ), valor, INDEX( INDIRECT(hoja&"!$A:$ZZ"), fila, columna ), IF(valor="-", "", valor) ), "") | D17: =IFERROR( LET( hoja, LEFT(D$1,3)&"R", fila, MATCH( RIGHT($A17, LEN($A17)-4), INDIRECT(hoja&"!$A:$A"), 0 ), columna, MATCH( "Totales", INDIRECT(hoja&"!$6:$6"), 0 ), valor, INDEX( INDIRECT(hoja&"!$A:$ZZ"), fila, columna ), IF(valor="-", "", valor) ), "") | E17: =IFERROR( LET( hoja, LEFT(E$1,3)&"R", fila, MATCH( RIGHT($A17, LEN($A17)-4), INDIRECT(hoja&"!$A:$A"), 0 ), columna, MATCH( "Totales", INDIRECT(hoja&"!$6:$6"), 0 ), valor, INDEX( INDIRECT(hoja&"!$A:$ZZ"), fila, columna ), IF(valor="-", "", valor) ), "") | F17: =IFERROR( LET( hoja, LEFT(F$1,3)&"R", fila, MATCH( RIGHT($A17, LEN($A17)-4), INDIRECT(hoja&"!$A:$A"), 0 ), columna, MATCH( "Totales", INDIRECT(hoja&"!$6:$6"), 0 ), valor, INDEX( INDIRECT(hoja&"!$A:$ZZ"), fila, columna ), IF(valor="-", "", valor) ), "") | G17: =IFERROR( LET( hoja, LEFT(G$1,3)&"R", fila, MATCH( RIGHT($A17, LEN($A17)-4), INDIRECT(hoja&"!$A:$A"), 0 ), columna, MATCH( "Totales", INDIRECT(hoja&"!$6:$6"), 0 ), valor, INDEX( INDIRECT(hoja&"!$A:$ZZ"), fila, columna ), IF(valor="-", "", valor) ), "") | H17: =IFERROR( LET( hoja, LEFT(H$1,3)&"R", fila, MATCH( RIGHT($A17, LEN($A17)-4), INDIRECT(hoja&"!$A:$A"), 0 ), columna, MATCH( "Totales", INDIRECT(hoja&"!$6:$6"), 0 ), valor, INDEX( INDIRECT(hoja&"!$A:$ZZ"), fila, columna ), IF(valor="-", "", valor) ), "") | I17: =IFERROR( LET( hoja, LEFT(I$1,3)&"R", fila, MATCH( RIGHT($A17, LEN($A17)-4), INDIRECT(hoja&"!$A:$A"), 0 ), columna, MATCH( "Totales", INDIRECT(hoja&"!$6:$6"), 0 ), valor, INDEX( INDIRECT(hoja&"!$A:$ZZ"), fila, columna ), IF(valor="-", "", valor) ), "") | J17: =IFERROR( LET( hoja, LEFT(J$1,3)&"R", fila, MATCH( RIGHT($A17, LEN($A17)-4), INDIRECT(hoja&"!$A:$A"), 0 ), columna, MATCH( "Totales", INDIRECT(hoja&"!$6:$6"), 0 ), valor, INDEX( INDIRECT(hoja&"!$A:$ZZ"), fila, columna ), IF(valor="-", "", valor) ), "") | ... N17: =IFERROR( LET( hoja, LEFT(N$1,3)&"R", fila, MATCH( RIGHT($A17, LEN($A17)-4), INDIRECT(hoja&"!$A:$A"), 0 ), columna, MATCH( "Totales", INDIRECT(hoja&"!$6:$6"), 0 ), valor, INDEX( INDIRECT(hoja&"!$A:$ZZ"), fila, columna ), IF(valor="-", "", valor) ), "")
A18: =Menus!B11 | B18: =SUM(IF(MONTH(TODAY())>1,C18,0), IF(MONTH(TODAY())>2,D18,0), IF(MONTH(TODAY())>3,E18,0), IF(MONTH(TODAY())>4,F18,0), IF(MONTH(TODAY())>5,G18,0), IF(MONTH(TODAY())>6,H18,0), IF(MONTH(TODAY())>7,I18,0), IF(MONTH(TODAY())>8,J18,0), IF(MONTH(TODAY())>9,K18,0), IF(MONTH(TODAY())>10,L18,0), IF(MONTH(TODAY())>11,M18,0), IF(MONTH(TODAY())>12,N18,0)) -> 0 | C18: =IFERROR( LET( hoja, LEFT(C$1,3)&"R", fila, MATCH( RIGHT($A18, LEN($A18)-4), INDIRECT(hoja&"!$A:$A"), 0 ), columna, MATCH( "Totales", INDIRECT(hoja&"!$6:$6"), 0 ), valor, INDEX( INDIRECT(hoja&"!$A:$ZZ"), fila, columna ), IF(valor="-", "", valor) ), "") | D18: =IFERROR( LET( hoja, LEFT(D$1,3)&"R", fila, MATCH( RIGHT($A18, LEN($A18)-4), INDIRECT(hoja&"!$A:$A"), 0 ), columna, MATCH( "Totales", INDIRECT(hoja&"!$6:$6"), 0 ), valor, INDEX( INDIRECT(hoja&"!$A:$ZZ"), fila, columna ), IF(valor="-", "", valor) ), "") | E18: =IFERROR( LET( hoja, LEFT(E$1,3)&"R", fila, MATCH( RIGHT($A18, LEN($A18)-4), INDIRECT(hoja&"!$A:$A"), 0 ), columna, MATCH( "Totales", INDIRECT(hoja&"!$6:$6"), 0 ), valor, INDEX( INDIRECT(hoja&"!$A:$ZZ"), fila, columna ), IF(valor="-", "", valor) ), "") | F18: =IFERROR( LET( hoja, LEFT(F$1,3)&"R", fila, MATCH( RIGHT($A18, LEN($A18)-4), INDIRECT(hoja&"!$A:$A"), 0 ), columna, MATCH( "Totales", INDIRECT(hoja&"!$6:$6"), 0 ), valor, INDEX( INDIRECT(hoja&"!$A:$ZZ"), fila, columna ), IF(valor="-", "", valor) ), "") | G18: =IFERROR( LET( hoja, LEFT(G$1,3)&"R", fila, MATCH( RIGHT($A18, LEN($A18)-4), INDIRECT(hoja&"!$A:$A"), 0 ), columna, MATCH( "Totales", INDIRECT(hoja&"!$6:$6"), 0 ), valor, INDEX( INDIRECT(hoja&"!$A:$ZZ"), fila, columna ), IF(valor="-", "", valor) ), "") | H18: =IFERROR( LET( hoja, LEFT(H$1,3)&"R", fila, MATCH( RIGHT($A18, LEN($A18)-4), INDIRECT(hoja&"!$A:$A"), 0 ), columna, MATCH( "Totales", INDIRECT(hoja&"!$6:$6"), 0 ), valor, INDEX( INDIRECT(hoja&"!$A:$ZZ"), fila, columna ), IF(valor="-", "", valor) ), "") | I18: =IFERROR( LET( hoja, LEFT(I$1,3)&"R", fila, MATCH( RIGHT($A18, LEN($A18)-4), INDIRECT(hoja&"!$A:$A"), 0 ), columna, MATCH( "Totales", INDIRECT(hoja&"!$6:$6"), 0 ), valor, INDEX( INDIRECT(hoja&"!$A:$ZZ"), fila, columna ), IF(valor="-", "", valor) ), "") | J18: =IFERROR( LET( hoja, LEFT(J$1,3)&"R", fila, MATCH( RIGHT($A18, LEN($A18)-4), INDIRECT(hoja&"!$A:$A"), 0 ), columna, MATCH( "Totales", INDIRECT(hoja&"!$6:$6"), 0 ), valor, INDEX( INDIRECT(hoja&"!$A:$ZZ"), fila, columna ), IF(valor="-", "", valor) ), "") | ... N18: =IFERROR( LET( hoja, LEFT(N$1,3)&"R", fila, MATCH( RIGHT($A18, LEN($A18)-4), INDIRECT(hoja&"!$A:$A"), 0 ), columna, MATCH( "Totales", INDIRECT(hoja&"!$6:$6"), 0 ), valor, INDEX( INDIRECT(hoja&"!$A:$ZZ"), fila, columna ), IF(valor="-", "", valor) ), "")
A19: =Menus!B12 | B19: =SUM(IF(MONTH(TODAY())>1,C19,0), IF(MONTH(TODAY())>2,D19,0), IF(MONTH(TODAY())>3,E19,0), IF(MONTH(TODAY())>4,F19,0), IF(MONTH(TODAY())>5,G19,0), IF(MONTH(TODAY())>6,H19,0), IF(MONTH(TODAY())>7,I19,0), IF(MONTH(TODAY())>8,J19,0), IF(MONTH(TODAY())>9,K19,0), IF(MONTH(TODAY())>10,L19,0), IF(MONTH(TODAY())>11,M19,0), IF(MONTH(TODAY())>12,N19,0)) -> 0 | C19: =IFERROR( LET( hoja, LEFT(C$1,3)&"R", fila, MATCH( RIGHT($A19, LEN($A19)-4), INDIRECT(hoja&"!$A:$A"), 0 ), columna, MATCH( "Totales", INDIRECT(hoja&"!$6:$6"), 0 ), valor, INDEX( INDIRECT(hoja&"!$A:$ZZ"), fila, columna ), IF(valor="-", "", valor) ), "") | D19: =IFERROR( LET( hoja, LEFT(D$1,3)&"R", fila, MATCH( RIGHT($A19, LEN($A19)-4), INDIRECT(hoja&"!$A:$A"), 0 ), columna, MATCH( "Totales", INDIRECT(hoja&"!$6:$6"), 0 ), valor, INDEX( INDIRECT(hoja&"!$A:$ZZ"), fila, columna ), IF(valor="-", "", valor) ), "") | E19: =IFERROR( LET( hoja, LEFT(E$1,3)&"R", fila, MATCH( RIGHT($A19, LEN($A19)-4), INDIRECT(hoja&"!$A:$A"), 0 ), columna, MATCH( "Totales", INDIRECT(hoja&"!$6:$6"), 0 ), valor, INDEX( INDIRECT(hoja&"!$A:$ZZ"), fila, columna ), IF(valor="-", "", valor) ), "") | F19: =IFERROR( LET( hoja, LEFT(F$1,3)&"R", fila, MATCH( RIGHT($A19, LEN($A19)-4), INDIRECT(hoja&"!$A:$A"), 0 ), columna, MATCH( "Totales", INDIRECT(hoja&"!$6:$6"), 0 ), valor, INDEX( INDIRECT(hoja&"!$A:$ZZ"), fila, columna ), IF(valor="-", "", valor) ), "") | G19: =IFERROR( LET( hoja, LEFT(G$1,3)&"R", fila, MATCH( RIGHT($A19, LEN($A19)-4), INDIRECT(hoja&"!$A:$A"), 0 ), columna, MATCH( "Totales", INDIRECT(hoja&"!$6:$6"), 0 ), valor, INDEX( INDIRECT(hoja&"!$A:$ZZ"), fila, columna ), IF(valor="-", "", valor) ), "") | H19: =IFERROR( LET( hoja, LEFT(H$1,3)&"R", fila, MATCH( RIGHT($A19, LEN($A19)-4), INDIRECT(hoja&"!$A:$A"), 0 ), columna, MATCH( "Totales", INDIRECT(hoja&"!$6:$6"), 0 ), valor, INDEX( INDIRECT(hoja&"!$A:$ZZ"), fila, columna ), IF(valor="-", "", valor) ), "") | I19: =IFERROR( LET( hoja, LEFT(I$1,3)&"R", fila, MATCH( RIGHT($A19, LEN($A19)-4), INDIRECT(hoja&"!$A:$A"), 0 ), columna, MATCH( "Totales", INDIRECT(hoja&"!$6:$6"), 0 ), valor, INDEX( INDIRECT(hoja&"!$A:$ZZ"), fila, columna ), IF(valor="-", "", valor) ), "") | J19: =IFERROR( LET( hoja, LEFT(J$1,3)&"R", fila, MATCH( RIGHT($A19, LEN($A19)-4), INDIRECT(hoja&"!$A:$A"), 0 ), columna, MATCH( "Totales", INDIRECT(hoja&"!$6:$6"), 0 ), valor, INDEX( INDIRECT(hoja&"!$A:$ZZ"), fila, columna ), IF(valor="-", "", valor) ), "") | ... N19: =IFERROR( LET( hoja, LEFT(N$1,3)&"R", fila, MATCH( RIGHT($A19, LEN($A19)-4), INDIRECT(hoja&"!$A:$A"), 0 ), columna, MATCH( "Totales", INDIRECT(hoja&"!$6:$6"), 0 ), valor, INDEX( INDIRECT(hoja&"!$A:$ZZ"), fila, columna ), IF(valor="-", "", valor) ), "")
A20: =Menus!B13 | B20: =SUM(IF(MONTH(TODAY())>1,C20,0), IF(MONTH(TODAY())>2,D20,0), IF(MONTH(TODAY())>3,E20,0), IF(MONTH(TODAY())>4,F20,0), IF(MONTH(TODAY())>5,G20,0), IF(MONTH(TODAY())>6,H20,0), IF(MONTH(TODAY())>7,I20,0), IF(MONTH(TODAY())>8,J20,0), IF(MONTH(TODAY())>9,K20,0), IF(MONTH(TODAY())>10,L20,0), IF(MONTH(TODAY())>11,M20,0), IF(MONTH(TODAY())>12,N20,0)) -> 0 | C20: =IFERROR( LET( hoja, LEFT(C$1,3)&"R", fila, MATCH( RIGHT($A20, LEN($A20)-4), INDIRECT(hoja&"!$A:$A"), 0 ), columna, MATCH( "Totales", INDIRECT(hoja&"!$6:$6"), 0 ), valor, INDEX( INDIRECT(hoja&"!$A:$ZZ"), fila, columna ), IF(valor="-", "", valor) ), "") | D20: =IFERROR( LET( hoja, LEFT(D$1,3)&"R", fila, MATCH( RIGHT($A20, LEN($A20)-4), INDIRECT(hoja&"!$A:$A"), 0 ), columna, MATCH( "Totales", INDIRECT(hoja&"!$6:$6"), 0 ), valor, INDEX( INDIRECT(hoja&"!$A:$ZZ"), fila, columna ), IF(valor="-", "", valor) ), "") | E20: =IFERROR( LET( hoja, LEFT(E$1,3)&"R", fila, MATCH( RIGHT($A20, LEN($A20)-4), INDIRECT(hoja&"!$A:$A"), 0 ), columna, MATCH( "Totales", INDIRECT(hoja&"!$6:$6"), 0 ), valor, INDEX( INDIRECT(hoja&"!$A:$ZZ"), fila, columna ), IF(valor="-", "", valor) ), "") | F20: =IFERROR( LET( hoja, LEFT(F$1,3)&"R", fila, MATCH( RIGHT($A20, LEN($A20)-4), INDIRECT(hoja&"!$A:$A"), 0 ), columna, MATCH( "Totales", INDIRECT(hoja&"!$6:$6"), 0 ), valor, INDEX( INDIRECT(hoja&"!$A:$ZZ"), fila, columna ), IF(valor="-", "", valor) ), "") | G20: =IFERROR( LET( hoja, LEFT(G$1,3)&"R", fila, MATCH( RIGHT($A20, LEN($A20)-4), INDIRECT(hoja&"!$A:$A"), 0 ), columna, MATCH( "Totales", INDIRECT(hoja&"!$6:$6"), 0 ), valor, INDEX( INDIRECT(hoja&"!$A:$ZZ"), fila, columna ), IF(valor="-", "", valor) ), "") | H20: =IFERROR( LET( hoja, LEFT(H$1,3)&"R", fila, MATCH( RIGHT($A20, LEN($A20)-4), INDIRECT(hoja&"!$A:$A"), 0 ), columna, MATCH( "Totales", INDIRECT(hoja&"!$6:$6"), 0 ), valor, INDEX( INDIRECT(hoja&"!$A:$ZZ"), fila, columna ), IF(valor="-", "", valor) ), "") | I20: =IFERROR( LET( hoja, LEFT(I$1,3)&"R", fila, MATCH( RIGHT($A20, LEN($A20)-4), INDIRECT(hoja&"!$A:$A"), 0 ), columna, MATCH( "Totales", INDIRECT(hoja&"!$6:$6"), 0 ), valor, INDEX( INDIRECT(hoja&"!$A:$ZZ"), fila, columna ), IF(valor="-", "", valor) ), "") | J20: =IFERROR( LET( hoja, LEFT(J$1,3)&"R", fila, MATCH( RIGHT($A20, LEN($A20)-4), INDIRECT(hoja&"!$A:$A"), 0 ), columna, MATCH( "Totales", INDIRECT(hoja&"!$6:$6"), 0 ), valor, INDEX( INDIRECT(hoja&"!$A:$ZZ"), fila, columna ), IF(valor="-", "", valor) ), "") | ... N20: =IFERROR( LET( hoja, LEFT(N$1,3)&"R", fila, MATCH( RIGHT($A20, LEN($A20)-4), INDIRECT(hoja&"!$A:$A"), 0 ), columna, MATCH( "Totales", INDIRECT(hoja&"!$6:$6"), 0 ), valor, INDEX( INDIRECT(hoja&"!$A:$ZZ"), fila, columna ), IF(valor="-", "", valor) ), "")
A21: =Menus!B14 | B21: =SUM(IF(MONTH(TODAY())>1,C21,0), IF(MONTH(TODAY())>2,D21,0), IF(MONTH(TODAY())>3,E21,0), IF(MONTH(TODAY())>4,F21,0), IF(MONTH(TODAY())>5,G21,0), IF(MONTH(TODAY())>6,H21,0), IF(MONTH(TODAY())>7,I21,0), IF(MONTH(TODAY())>8,J21,0), IF(MONTH(TODAY())>9,K21,0), IF(MONTH(TODAY())>10,L21,0), IF(MONTH(TODAY())>11,M21,0), IF(MONTH(TODAY())>12,N21,0)) -> 0 | C21: =IFERROR( LET( hoja, LEFT(C$1,3)&"R", fila, MATCH( RIGHT($A21, LEN($A21)-4), INDIRECT(hoja&"!$A:$A"), 0 ), columna, MATCH( "Totales", INDIRECT(hoja&"!$6:$6"), 0 ), valor, INDEX( INDIRECT(hoja&"!$A:$ZZ"), fila, columna ), IF(valor="-", "", valor) ), "") | D21: =IFERROR( LET( hoja, LEFT(D$1,3)&"R", fila, MATCH( RIGHT($A21, LEN($A21)-4), INDIRECT(hoja&"!$A:$A"), 0 ), columna, MATCH( "Totales", INDIRECT(hoja&"!$6:$6"), 0 ), valor, INDEX( INDIRECT(hoja&"!$A:$ZZ"), fila, columna ), IF(valor="-", "", valor) ), "") | E21: =IFERROR( LET( hoja, LEFT(E$1,3)&"R", fila, MATCH( RIGHT($A21, LEN($A21)-4), INDIRECT(hoja&"!$A:$A"), 0 ), columna, MATCH( "Totales", INDIRECT(hoja&"!$6:$6"), 0 ), valor, INDEX( INDIRECT(hoja&"!$A:$ZZ"), fila, columna ), IF(valor="-", "", valor) ), "") | F21: =IFERROR( LET( hoja, LEFT(F$1,3)&"R", fila, MATCH( RIGHT($A21, LEN($A21)-4), INDIRECT(hoja&"!$A:$A"), 0 ), columna, MATCH( "Totales", INDIRECT(hoja&"!$6:$6"), 0 ), valor, INDEX( INDIRECT(hoja&"!$A:$ZZ"), fila, columna ), IF(valor="-", "", valor) ), "") | G21: =IFERROR( LET( hoja, LEFT(G$1,3)&"R", fila, MATCH( RIGHT($A21, LEN($A21)-4), INDIRECT(hoja&"!$A:$A"), 0 ), columna, MATCH( "Totales", INDIRECT(hoja&"!$6:$6"), 0 ), valor, INDEX( INDIRECT(hoja&"!$A:$ZZ"), fila, columna ), IF(valor="-", "", valor) ), "") | H21: =IFERROR( LET( hoja, LEFT(H$1,3)&"R", fila, MATCH( RIGHT($A21, LEN($A21)-4), INDIRECT(hoja&"!$A:$A"), 0 ), columna, MATCH( "Totales", INDIRECT(hoja&"!$6:$6"), 0 ), valor, INDEX( INDIRECT(hoja&"!$A:$ZZ"), fila, columna ), IF(valor="-", "", valor) ), "") | I21: =IFERROR( LET( hoja, LEFT(I$1,3)&"R", fila, MATCH( RIGHT($A21, LEN($A21)-4), INDIRECT(hoja&"!$A:$A"), 0 ), columna, MATCH( "Totales", INDIRECT(hoja&"!$6:$6"), 0 ), valor, INDEX( INDIRECT(hoja&"!$A:$ZZ"), fila, columna ), IF(valor="-", "", valor) ), "") | J21: =IFERROR( LET( hoja, LEFT(J$1,3)&"R", fila, MATCH( RIGHT($A21, LEN($A21)-4), INDIRECT(hoja&"!$A:$A"), 0 ), columna, MATCH( "Totales", INDIRECT(hoja&"!$6:$6"), 0 ), valor, INDEX( INDIRECT(hoja&"!$A:$ZZ"), fila, columna ), IF(valor="-", "", valor) ), "") | ... N21: =IFERROR( LET( hoja, LEFT(N$1,3)&"R", fila, MATCH( RIGHT($A21, LEN($A21)-4), INDIRECT(hoja&"!$A:$A"), 0 ), columna, MATCH( "Totales", INDIRECT(hoja&"!$6:$6"), 0 ), valor, INDEX( INDIRECT(hoja&"!$A:$ZZ"), fila, columna ), IF(valor="-", "", valor) ), "")
A22: =Menus!B15 | B22: =SUM(IF(MONTH(TODAY())>1,C22,0), IF(MONTH(TODAY())>2,D22,0), IF(MONTH(TODAY())>3,E22,0), IF(MONTH(TODAY())>4,F22,0), IF(MONTH(TODAY())>5,G22,0), IF(MONTH(TODAY())>6,H22,0), IF(MONTH(TODAY())>7,I22,0), IF(MONTH(TODAY())>8,J22,0), IF(MONTH(TODAY())>9,K22,0), IF(MONTH(TODAY())>10,L22,0), IF(MONTH(TODAY())>11,M22,0), IF(MONTH(TODAY())>12,N22,0)) -> 0 | C22: =IFERROR( LET( hoja, LEFT(C$1,3)&"R", fila, MATCH( RIGHT($A22, LEN($A22)-4), INDIRECT(hoja&"!$A:$A"), 0 ), columna, MATCH( "Totales", INDIRECT(hoja&"!$6:$6"), 0 ), valor, INDEX( INDIRECT(hoja&"!$A:$ZZ"), fila, columna ), IF(valor="-", "", valor) ), "") | D22: =IFERROR( LET( hoja, LEFT(D$1,3)&"R", fila, MATCH( RIGHT($A22, LEN($A22)-4), INDIRECT(hoja&"!$A:$A"), 0 ), columna, MATCH( "Totales", INDIRECT(hoja&"!$6:$6"), 0 ), valor, INDEX( INDIRECT(hoja&"!$A:$ZZ"), fila, columna ), IF(valor="-", "", valor) ), "") | E22: =IFERROR( LET( hoja, LEFT(E$1,3)&"R", fila, MATCH( RIGHT($A22, LEN($A22)-4), INDIRECT(hoja&"!$A:$A"), 0 ), columna, MATCH( "Totales", INDIRECT(hoja&"!$6:$6"), 0 ), valor, INDEX( INDIRECT(hoja&"!$A:$ZZ"), fila, columna ), IF(valor="-", "", valor) ), "") | F22: =IFERROR( LET( hoja, LEFT(F$1,3)&"R", fila, MATCH( RIGHT($A22, LEN($A22)-4), INDIRECT(hoja&"!$A:$A"), 0 ), columna, MATCH( "Totales", INDIRECT(hoja&"!$6:$6"), 0 ), valor, INDEX( INDIRECT(hoja&"!$A:$ZZ"), fila, columna ), IF(valor="-", "", valor) ), "") | G22: =IFERROR( LET( hoja, LEFT(G$1,3)&"R", fila, MATCH( RIGHT($A22, LEN($A22)-4), INDIRECT(hoja&"!$A:$A"), 0 ), columna, MATCH( "Totales", INDIRECT(hoja&"!$6:$6"), 0 ), valor, INDEX( INDIRECT(hoja&"!$A:$ZZ"), fila, columna ), IF(valor="-", "", valor) ), "") | H22: =IFERROR( LET( hoja, LEFT(H$1,3)&"R", fila, MATCH( RIGHT($A22, LEN($A22)-4), INDIRECT(hoja&"!$A:$A"), 0 ), columna, MATCH( "Totales", INDIRECT(hoja&"!$6:$6"), 0 ), valor, INDEX( INDIRECT(hoja&"!$A:$ZZ"), fila, columna ), IF(valor="-", "", valor) ), "") | I22: =IFERROR( LET( hoja, LEFT(I$1,3)&"R", fila, MATCH( RIGHT($A22, LEN($A22)-4), INDIRECT(hoja&"!$A:$A"), 0 ), columna, MATCH( "Totales", INDIRECT(hoja&"!$6:$6"), 0 ), valor, INDEX( INDIRECT(hoja&"!$A:$ZZ"), fila, columna ), IF(valor="-", "", valor) ), "") | J22: =IFERROR( LET( hoja, LEFT(J$1,3)&"R", fila, MATCH( RIGHT($A22, LEN($A22)-4), INDIRECT(hoja&"!$A:$A"), 0 ), columna, MATCH( "Totales", INDIRECT(hoja&"!$6:$6"), 0 ), valor, INDEX( INDIRECT(hoja&"!$A:$ZZ"), fila, columna ), IF(valor="-", "", valor) ), "") | ... N22: =IFERROR( LET( hoja, LEFT(N$1,3)&"R", fila, MATCH( RIGHT($A22, LEN($A22)-4), INDIRECT(hoja&"!$A:$A"), 0 ), columna, MATCH( "Totales", INDIRECT(hoja&"!$6:$6"), 0 ), valor, INDEX( INDIRECT(hoja&"!$A:$ZZ"), fila, columna ), IF(valor="-", "", valor) ), "")
... A47: =Menus!B40 | B47: =SUM(IF(MONTH(TODAY())>1,C47,0), IF(MONTH(TODAY())>2,D47,0), IF(MONTH(TODAY())>3,E47,0), IF(MONTH(TODAY())>4,F47,0), IF(MONTH(TODAY())>5,G47,0), IF(MONTH(TODAY())>6,H47,0), IF(MONTH(TODAY())>7,I47,0), IF(MONTH(TODAY())>8,J47,0), IF(MONTH(TODAY())>9,K47,0), IF(MONTH(TODAY())>10,L47,0), IF(MONTH(TODAY())>11,M47,0), IF(MONTH(TODAY())>12,N47,0)) -> 0 | C47: =IFERROR( LET( hoja, LEFT(C$1,3)&"R", fila, MATCH( RIGHT($A47, LEN($A47)-4), INDIRECT(hoja&"!$A:$A"), 0 ), columna, MATCH( "Totales", INDIRECT(hoja&"!$6:$6"), 0 ), valor, INDEX( INDIRECT(hoja&"!$A:$ZZ"), fila, columna ), IF(valor="-", "", valor) ), "") | D47: =IFERROR( LET( hoja, LEFT(D$1,3)&"R", fila, MATCH( RIGHT($A47, LEN($A47)-4), INDIRECT(hoja&"!$A:$A"), 0 ), columna, MATCH( "Totales", INDIRECT(hoja&"!$6:$6"), 0 ), valor, INDEX( INDIRECT(hoja&"!$A:$ZZ"), fila, columna ), IF(valor="-", "", valor) ), "") | E47: =IFERROR( LET( hoja, LEFT(E$1,3)&"R", fila, MATCH( RIGHT($A47, LEN($A47)-4), INDIRECT(hoja&"!$A:$A"), 0 ), columna, MATCH( "Totales", INDIRECT(hoja&"!$6:$6"), 0 ), valor, INDEX( INDIRECT(hoja&"!$A:$ZZ"), fila, columna ), IF(valor="-", "", valor) ), "") | F47: =IFERROR( LET( hoja, LEFT(F$1,3)&"R", fila, MATCH( RIGHT($A47, LEN($A47)-4), INDIRECT(hoja&"!$A:$A"), 0 ), columna, MATCH( "Totales", INDIRECT(hoja&"!$6:$6"), 0 ), valor, INDEX( INDIRECT(hoja&"!$A:$ZZ"), fila, columna ), IF(valor="-", "", valor) ), "") | G47: =IFERROR( LET( hoja, LEFT(G$1,3)&"R", fila, MATCH( RIGHT($A47, LEN($A47)-4), INDIRECT(hoja&"!$A:$A"), 0 ), columna, MATCH( "Totales", INDIRECT(hoja&"!$6:$6"), 0 ), valor, INDEX( INDIRECT(hoja&"!$A:$ZZ"), fila, columna ), IF(valor="-", "", valor) ), "") | H47: =IFERROR( LET( hoja, LEFT(H$1,3)&"R", fila, MATCH( RIGHT($A47, LEN($A47)-4), INDIRECT(hoja&"!$A:$A"), 0 ), columna, MATCH( "Totales", INDIRECT(hoja&"!$6:$6"), 0 ), valor, INDEX( INDIRECT(hoja&"!$A:$ZZ"), fila, columna ), IF(valor="-", "", valor) ), "") | I47: =IFERROR( LET( hoja, LEFT(I$1,3)&"R", fila, MATCH( RIGHT($A47, LEN($A47)-4), INDIRECT(hoja&"!$A:$A"), 0 ), columna, MATCH( "Totales", INDIRECT(hoja&"!$6:$6"), 0 ), valor, INDEX( INDIRECT(hoja&"!$A:$ZZ"), fila, columna ), IF(valor="-", "", valor) ), "") | J47: =IFERROR( LET( hoja, LEFT(J$1,3)&"R", fila, MATCH( RIGHT($A47, LEN($A47)-4), INDIRECT(hoja&"!$A:$A"), 0 ), columna, MATCH( "Totales", INDIRECT(hoja&"!$6:$6"), 0 ), valor, INDEX( INDIRECT(hoja&"!$A:$ZZ"), fila, columna ), IF(valor="-", "", valor) ), "") | ... N47: =IFERROR( LET( hoja, LEFT(N$1,3)&"R", fila, MATCH( RIGHT($A47, LEN($A47)-4), INDIRECT(hoja&"!$A:$A"), 0 ), columna, MATCH( "Totales", INDIRECT(hoja&"!$6:$6"), 0 ), valor, INDEX( INDIRECT(hoja&"!$A:$ZZ"), fila, columna ), IF(valor="-", "", valor) ), "")
A49: Otros Ingresos | B49: =SUM(B50:B52) -> 0 | C49: =SUM(C50:C52) -> 0 | D49: =SUM(D50:D52) -> 0 | E49: =SUM(E50:E52) -> 0 | F49: =SUM(F50:F52) -> 0 | G49: =SUM(G50:G52) -> 0 | H49: =SUM(H50:H52) -> 0 | I49: =SUM(I50:I52) -> 0 | ... N49: =SUM(N50:N52) -> 0
A50: =Menus!Q2 | B50: =SUM(IF(MONTH(TODAY())>1,C50,0), IF(MONTH(TODAY())>2,D50,0), IF(MONTH(TODAY())>3,E50,0), IF(MONTH(TODAY())>4,F50,0), IF(MONTH(TODAY())>5,G50,0), IF(MONTH(TODAY())>6,H50,0), IF(MONTH(TODAY())>7,I50,0), IF(MONTH(TODAY())>8,J50,0), IF(MONTH(TODAY())>9,K50,0), IF(MONTH(TODAY())>10,L50,0), IF(MONTH(TODAY())>11,M50,0), IF(MONTH(TODAY())>12,N50,0)) -> 0 | C50: {=IFERROR(SUMIF(OtrosR!$C$3:$C$100, $A50, INDEX(OtrosR!$E$3:$P$100, , MATCH(C$1, OtrosR!$E$2:$P$2, 0))), "")} | D50: {=IFERROR(SUMIF(OtrosR!$C$3:$C$100, $A50, INDEX(OtrosR!$E$3:$P$100, , MATCH(D$1, OtrosR!$E$2:$P$2, 0))), "")} | E50: {=IFERROR(SUMIF(OtrosR!$C$3:$C$100, $A50, INDEX(OtrosR!$E$3:$P$100, , MATCH(E$1, OtrosR!$E$2:$P$2, 0))), "")} | F50: {=IFERROR(SUMIF(OtrosR!$C$3:$C$100, $A50, INDEX(OtrosR!$E$3:$P$100, , MATCH(F$1, OtrosR!$E$2:$P$2, 0))), "")} | G50: {=IFERROR(SUMIF(OtrosR!$C$3:$C$100, $A50, INDEX(OtrosR!$E$3:$P$100, , MATCH(G$1, OtrosR!$E$2:$P$2, 0))), "")} | H50: {=IFERROR(SUMIF(OtrosR!$C$3:$C$100, $A50, INDEX(OtrosR!$E$3:$P$100, , MATCH(H$1, OtrosR!$E$2:$P$2, 0))), "")} | I50: {=IFERROR(SUMIF(OtrosR!$C$3:$C$100, $A50, INDEX(OtrosR!$E$3:$P$100, , MATCH(I$1, OtrosR!$E$2:$P$2, 0))), "")} | J50: {=IFERROR(SUMIF(OtrosR!$C$3:$C$100, $A50, INDEX(OtrosR!$E$3:$P$100, , MATCH(J$1, OtrosR!$E$2:$P$2, 0))), "")} | ... N50: {=IFERROR(SUMIF(OtrosR!$C$3:$C$100, $A50, INDEX(OtrosR!$E$3:$P$100, , MATCH(N$1, OtrosR!$E$2:$P$2, 0))), "")}
B51: =SUM(IF(MONTH(TODAY())>1,C51,0), IF(MONTH(TODAY())>2,D51,0), IF(MONTH(TODAY())>3,E51,0), IF(MONTH(TODAY())>4,F51,0), IF(MONTH(TODAY())>5,G51,0), IF(MONTH(TODAY())>6,H51,0), IF(MONTH(TODAY())>7,I51,0), IF(MONTH(TODAY())>8,J51,0), IF(MONTH(TODAY())>9,K51,0), IF(MONTH(TODAY())>10,L51,0), IF(MONTH(TODAY())>11,M51,0), IF(MONTH(TODAY())>12,N51,0)) -> 0 | C51: {=IFERROR(SUMIF(OtrosR!$C$3:$C$100, $A51, INDEX(OtrosR!$E$3:$P$100, , MATCH(C$1, OtrosR!$E$2:$P$2, 0))), "")} | D51: {=IFERROR(SUMIF(OtrosR!$C$3:$C$100, $A51, INDEX(OtrosR!$E$3:$P$100, , MATCH(D$1, OtrosR!$E$2:$P$2, 0))), "")} | E51: {=IFERROR(SUMIF(OtrosR!$C$3:$C$100, $A51, INDEX(OtrosR!$E$3:$P$100, , MATCH(E$1, OtrosR!$E$2:$P$2, 0))), "")} | F51: {=IFERROR(SUMIF(OtrosR!$C$3:$C$100, $A51, INDEX(OtrosR!$E$3:$P$100, , MATCH(F$1, OtrosR!$E$2:$P$2, 0))), "")} | G51: {=IFERROR(SUMIF(OtrosR!$C$3:$C$100, $A51, INDEX(OtrosR!$E$3:$P$100, , MATCH(G$1, OtrosR!$E$2:$P$2, 0))), "")} | H51: {=IFERROR(SUMIF(OtrosR!$C$3:$C$100, $A51, INDEX(OtrosR!$E$3:$P$100, , MATCH(H$1, OtrosR!$E$2:$P$2, 0))), "")} | I51: {=IFERROR(SUMIF(OtrosR!$C$3:$C$100, $A51, INDEX(OtrosR!$E$3:$P$100, , MATCH(I$1, OtrosR!$E$2:$P$2, 0))), "")} | J51: {=IFERROR(SUMIF(OtrosR!$C$3:$C$100, $A51, INDEX(OtrosR!$E$3:$P$100, , MATCH(J$1, OtrosR!$E$2:$P$2, 0))), "")} | ... N51: {=IFERROR(SUMIF(OtrosR!$C$3:$C$100, $A51, INDEX(OtrosR!$E$3:$P$100, , MATCH(N$1, OtrosR!$E$2:$P$2, 0))), "")}
B52: =SUM(IF(MONTH(TODAY())>1,C52,0), IF(MONTH(TODAY())>2,D52,0), IF(MONTH(TODAY())>3,E52,0), IF(MONTH(TODAY())>4,F52,0), IF(MONTH(TODAY())>5,G52,0), IF(MONTH(TODAY())>6,H52,0), IF(MONTH(TODAY())>7,I52,0), IF(MONTH(TODAY())>8,J52,0), IF(MONTH(TODAY())>9,K52,0), IF(MONTH(TODAY())>10,L52,0), IF(MONTH(TODAY())>11,M52,0), IF(MONTH(TODAY())>12,N52,0)) -> 0 | C52: {=IFERROR(SUMIF(OtrosR!$C$3:$C$100, $A52, INDEX(OtrosR!$E$3:$P$100, , MATCH(C$1, OtrosR!$E$2:$P$2, 0))), "")} | D52: {=IFERROR(SUMIF(OtrosR!$C$3:$C$100, $A52, INDEX(OtrosR!$E$3:$P$100, , MATCH(D$1, OtrosR!$E$2:$P$2, 0))), "")} | E52: {=IFERROR(SUMIF(OtrosR!$C$3:$C$100, $A52, INDEX(OtrosR!$E$3:$P$100, , MATCH(E$1, OtrosR!$E$2:$P$2, 0))), "")} | F52: {=IFERROR(SUMIF(OtrosR!$C$3:$C$100, $A52, INDEX(OtrosR!$E$3:$P$100, , MATCH(F$1, OtrosR!$E$2:$P$2, 0))), "")} | G52: {=IFERROR(SUMIF(OtrosR!$C$3:$C$100, $A52, INDEX(OtrosR!$E$3:$P$100, , MATCH(G$1, OtrosR!$E$2:$P$2, 0))), "")} | H52: {=IFERROR(SUMIF(OtrosR!$C$3:$C$100, $A52, INDEX(OtrosR!$E$3:$P$100, , MATCH(H$1, OtrosR!$E$2:$P$2, 0))), "")} | I52: {=IFERROR(SUMIF(OtrosR!$C$3:$C$100, $A52, INDEX(OtrosR!$E$3:$P$100, , MATCH(I$1, OtrosR!$E$2:$P$2, 0))), "")} | J52: {=IFERROR(SUMIF(OtrosR!$C$3:$C$100, $A52, INDEX(OtrosR!$E$3:$P$100, , MATCH(J$1, OtrosR!$E$2:$P$2, 0))), "")} | ... N52: {=IFERROR(SUMIF(OtrosR!$C$3:$C$100, $A52, INDEX(OtrosR!$E$3:$P$100, , MATCH(N$1, OtrosR!$E$2:$P$2, 0))), "")}
A54: Otros Egresos | B54: =SUM(B55:B63) -> 0 | C54: =SUM(C55:C63) -> 0 | D54: =SUM(D55:D63) -> 0 | E54: =SUM(E55:E63) -> 0 | F54: =SUM(F55:F63) -> 0 | G54: =SUM(G55:G63) -> 0 | H54: =SUM(H55:H63) -> 0 | I54: =SUM(I55:I63) -> 0 | ... N54: =SUM(N55:N63) -> 0
A55: =Menus!Q3 | B55: =SUM(IF(MONTH(TODAY())>1,C55,0), IF(MONTH(TODAY())>2,D55,0), IF(MONTH(TODAY())>3,E55,0), IF(MONTH(TODAY())>4,F55,0), IF(MONTH(TODAY())>5,G55,0), IF(MONTH(TODAY())>6,H55,0), IF(MONTH(TODAY())>7,I55,0), IF(MONTH(TODAY())>8,J55,0), IF(MONTH(TODAY())>9,K55,0), IF(MONTH(TODAY())>10,L55,0), IF(MONTH(TODAY())>11,M55,0), IF(MONTH(TODAY())>12,N55,0)) -> 0 | C55: {=IFERROR(SUMIF(OtrosR!$C$3:$C$100, $A55, INDEX(OtrosR!$E$3:$P$100, , MATCH(C$1, OtrosR!$E$2:$P$2, 0))), "")} | D55: {=IFERROR(SUMIF(OtrosR!$C$3:$C$100, $A55, INDEX(OtrosR!$E$3:$P$100, , MATCH(D$1, OtrosR!$E$2:$P$2, 0))), "")} | E55: {=IFERROR(SUMIF(OtrosR!$C$3:$C$100, $A55, INDEX(OtrosR!$E$3:$P$100, , MATCH(E$1, OtrosR!$E$2:$P$2, 0))), "")} | F55: {=IFERROR(SUMIF(OtrosR!$C$3:$C$100, $A55, INDEX(OtrosR!$E$3:$P$100, , MATCH(F$1, OtrosR!$E$2:$P$2, 0))), "")} | G55: {=IFERROR(SUMIF(OtrosR!$C$3:$C$100, $A55, INDEX(OtrosR!$E$3:$P$100, , MATCH(G$1, OtrosR!$E$2:$P$2, 0))), "")} | H55: {=IFERROR(SUMIF(OtrosR!$C$3:$C$100, $A55, INDEX(OtrosR!$E$3:$P$100, , MATCH(H$1, OtrosR!$E$2:$P$2, 0))), "")} | I55: {=IFERROR(SUMIF(OtrosR!$C$3:$C$100, $A55, INDEX(OtrosR!$E$3:$P$100, , MATCH(I$1, OtrosR!$E$2:$P$2, 0))), "")} | J55: {=IFERROR(SUMIF(OtrosR!$C$3:$C$100, $A55, INDEX(OtrosR!$E$3:$P$100, , MATCH(J$1, OtrosR!$E$2:$P$2, 0))), "")} | ... N55: {=IFERROR(SUMIF(OtrosR!$C$3:$C$100, $A55, INDEX(OtrosR!$E$3:$P$100, , MATCH(N$1, OtrosR!$E$2:$P$2, 0))), "")}
A56: =Menus!Q4 | B56: =SUM(IF(MONTH(TODAY())>1,C56,0), IF(MONTH(TODAY())>2,D56,0), IF(MONTH(TODAY())>3,E56,0), IF(MONTH(TODAY())>4,F56,0), IF(MONTH(TODAY())>5,G56,0), IF(MONTH(TODAY())>6,H56,0), IF(MONTH(TODAY())>7,I56,0), IF(MONTH(TODAY())>8,J56,0), IF(MONTH(TODAY())>9,K56,0), IF(MONTH(TODAY())>10,L56,0), IF(MONTH(TODAY())>11,M56,0), IF(MONTH(TODAY())>12,N56,0)) -> 0 | C56: {=IFERROR(SUMIF(OtrosR!$C$3:$C$100, $A56, INDEX(OtrosR!$E$3:$P$100, , MATCH(C$1, OtrosR!$E$2:$P$2, 0))), "")} | D56: {=IFERROR(SUMIF(OtrosR!$C$3:$C$100, $A56, INDEX(OtrosR!$E$3:$P$100, , MATCH(D$1, OtrosR!$E$2:$P$2, 0))), "")} | E56: {=IFERROR(SUMIF(OtrosR!$C$3:$C$100, $A56, INDEX(OtrosR!$E$3:$P$100, , MATCH(E$1, OtrosR!$E$2:$P$2, 0))), "")} | F56: {=IFERROR(SUMIF(OtrosR!$C$3:$C$100, $A56, INDEX(OtrosR!$E$3:$P$100, , MATCH(F$1, OtrosR!$E$2:$P$2, 0))), "")} | G56: {=IFERROR(SUMIF(OtrosR!$C$3:$C$100, $A56, INDEX(OtrosR!$E$3:$P$100, , MATCH(G$1, OtrosR!$E$2:$P$2, 0))), "")} | H56: {=IFERROR(SUMIF(OtrosR!$C$3:$C$100, $A56, INDEX(OtrosR!$E$3:$P$100, , MATCH(H$1, OtrosR!$E$2:$P$2, 0))), "")} | I56: {=IFERROR(SUMIF(OtrosR!$C$3:$C$100, $A56, INDEX(OtrosR!$E$3:$P$100, , MATCH(I$1, OtrosR!$E$2:$P$2, 0))), "")} | J56: {=IFERROR(SUMIF(OtrosR!$C$3:$C$100, $A56, INDEX(OtrosR!$E$3:$P$100, , MATCH(J$1, OtrosR!$E$2:$P$2, 0))), "")} | ... N56: {=IFERROR(SUMIF(OtrosR!$C$3:$C$100, $A56, INDEX(OtrosR!$E$3:$P$100, , MATCH(N$1, OtrosR!$E$2:$P$2, 0))), "")}
A57: =Menus!Q5 | B57: =SUM(IF(MONTH(TODAY())>1,C57,0), IF(MONTH(TODAY())>2,D57,0), IF(MONTH(TODAY())>3,E57,0), IF(MONTH(TODAY())>4,F57,0), IF(MONTH(TODAY())>5,G57,0), IF(MONTH(TODAY())>6,H57,0), IF(MONTH(TODAY())>7,I57,0), IF(MONTH(TODAY())>8,J57,0), IF(MONTH(TODAY())>9,K57,0), IF(MONTH(TODAY())>10,L57,0), IF(MONTH(TODAY())>11,M57,0), IF(MONTH(TODAY())>12,N57,0)) -> 0 | C57: {=IFERROR(SUMIF(OtrosR!$C$3:$C$100, $A57, INDEX(OtrosR!$E$3:$P$100, , MATCH(C$1, OtrosR!$E$2:$P$2, 0))), "")} | D57: {=IFERROR(SUMIF(OtrosR!$C$3:$C$100, $A57, INDEX(OtrosR!$E$3:$P$100, , MATCH(D$1, OtrosR!$E$2:$P$2, 0))), "")} | E57: {=IFERROR(SUMIF(OtrosR!$C$3:$C$100, $A57, INDEX(OtrosR!$E$3:$P$100, , MATCH(E$1, OtrosR!$E$2:$P$2, 0))), "")} | F57: {=IFERROR(SUMIF(OtrosR!$C$3:$C$100, $A57, INDEX(OtrosR!$E$3:$P$100, , MATCH(F$1, OtrosR!$E$2:$P$2, 0))), "")} | G57: {=IFERROR(SUMIF(OtrosR!$C$3:$C$100, $A57, INDEX(OtrosR!$E$3:$P$100, , MATCH(G$1, OtrosR!$E$2:$P$2, 0))), "")} | H57: {=IFERROR(SUMIF(OtrosR!$C$3:$C$100, $A57, INDEX(OtrosR!$E$3:$P$100, , MATCH(H$1, OtrosR!$E$2:$P$2, 0))), "")} | I57: {=IFERROR(SUMIF(OtrosR!$C$3:$C$100, $A57, INDEX(OtrosR!$E$3:$P$100, , MATCH(I$1, OtrosR!$E$2:$P$2, 0))), "")} | J57: {=IFERROR(SUMIF(OtrosR!$C$3:$C$100, $A57, INDEX(OtrosR!$E$3:$P$100, , MATCH(J$1, OtrosR!$E$2:$P$2, 0))), "")} | ... N57: {=IFERROR(SUMIF(OtrosR!$C$3:$C$100, $A57, INDEX(OtrosR!$E$3:$P$100, , MATCH(N$1, OtrosR!$E$2:$P$2, 0))), "")}
A58: =Menus!Q6 | B58: =SUM(IF(MONTH(TODAY())>1,C58,0), IF(MONTH(TODAY())>2,D58,0), IF(MONTH(TODAY())>3,E58,0), IF(MONTH(TODAY())>4,F58,0), IF(MONTH(TODAY())>5,G58,0), IF(MONTH(TODAY())>6,H58,0), IF(MONTH(TODAY())>7,I58,0), IF(MONTH(TODAY())>8,J58,0), IF(MONTH(TODAY())>9,K58,0), IF(MONTH(TODAY())>10,L58,0), IF(MONTH(TODAY())>11,M58,0), IF(MONTH(TODAY())>12,N58,0)) -> 0 | C58: {=IFERROR(SUMIF(OtrosR!$C$3:$C$100, $A58, INDEX(OtrosR!$E$3:$P$100, , MATCH(C$1, OtrosR!$E$2:$P$2, 0))), "")} | D58: {=IFERROR(SUMIF(OtrosR!$C$3:$C$100, $A58, INDEX(OtrosR!$E$3:$P$100, , MATCH(D$1, OtrosR!$E$2:$P$2, 0))), "")} | E58: {=IFERROR(SUMIF(OtrosR!$C$3:$C$100, $A58, INDEX(OtrosR!$E$3:$P$100, , MATCH(E$1, OtrosR!$E$2:$P$2, 0))), "")} | F58: {=IFERROR(SUMIF(OtrosR!$C$3:$C$100, $A58, INDEX(OtrosR!$E$3:$P$100, , MATCH(F$1, OtrosR!$E$2:$P$2, 0))), "")} | G58: {=IFERROR(SUMIF(OtrosR!$C$3:$C$100, $A58, INDEX(OtrosR!$E$3:$P$100, , MATCH(G$1, OtrosR!$E$2:$P$2, 0))), "")} | H58: {=IFERROR(SUMIF(OtrosR!$C$3:$C$100, $A58, INDEX(OtrosR!$E$3:$P$100, , MATCH(H$1, OtrosR!$E$2:$P$2, 0))), "")} | I58: {=IFERROR(SUMIF(OtrosR!$C$3:$C$100, $A58, INDEX(OtrosR!$E$3:$P$100, , MATCH(I$1, OtrosR!$E$2:$P$2, 0))), "")} | J58: {=IFERROR(SUMIF(OtrosR!$C$3:$C$100, $A58, INDEX(OtrosR!$E$3:$P$100, , MATCH(J$1, OtrosR!$E$2:$P$2, 0))), "")} | ... N58: {=IFERROR(SUMIF(OtrosR!$C$3:$C$100, $A58, INDEX(OtrosR!$E$3:$P$100, , MATCH(N$1, OtrosR!$E$2:$P$2, 0))), "")}
A59: =Menus!Q7 | B59: =SUM(IF(MONTH(TODAY())>1,C59,0), IF(MONTH(TODAY())>2,D59,0), IF(MONTH(TODAY())>3,E59,0), IF(MONTH(TODAY())>4,F59,0), IF(MONTH(TODAY())>5,G59,0), IF(MONTH(TODAY())>6,H59,0), IF(MONTH(TODAY())>7,I59,0), IF(MONTH(TODAY())>8,J59,0), IF(MONTH(TODAY())>9,K59,0), IF(MONTH(TODAY())>10,L59,0), IF(MONTH(TODAY())>11,M59,0), IF(MONTH(TODAY())>12,N59,0)) -> 0 | C59: {=IFERROR(SUMIF(OtrosR!$C$3:$C$100, $A59, INDEX(OtrosR!$E$3:$P$100, , MATCH(C$1, OtrosR!$E$2:$P$2, 0))), "")} | D59: {=IFERROR(SUMIF(OtrosR!$C$3:$C$100, $A59, INDEX(OtrosR!$E$3:$P$100, , MATCH(D$1, OtrosR!$E$2:$P$2, 0))), "")} | E59: {=IFERROR(SUMIF(OtrosR!$C$3:$C$100, $A59, INDEX(OtrosR!$E$3:$P$100, , MATCH(E$1, OtrosR!$E$2:$P$2, 0))), "")} | F59: {=IFERROR(SUMIF(OtrosR!$C$3:$C$100, $A59, INDEX(OtrosR!$E$3:$P$100, , MATCH(F$1, OtrosR!$E$2:$P$2, 0))), "")} | G59: {=IFERROR(SUMIF(OtrosR!$C$3:$C$100, $A59, INDEX(OtrosR!$E$3:$P$100, , MATCH(G$1, OtrosR!$E$2:$P$2, 0))), "")} | H59: {=IFERROR(SUMIF(OtrosR!$C$3:$C$100, $A59, INDEX(OtrosR!$E$3:$P$100, , MATCH(H$1, OtrosR!$E$2:$P$2, 0))), "")} | I59: {=IFERROR(SUMIF(OtrosR!$C$3:$C$100, $A59, INDEX(OtrosR!$E$3:$P$100, , MATCH(I$1, OtrosR!$E$2:$P$2, 0))), "")} | J59: {=IFERROR(SUMIF(OtrosR!$C$3:$C$100, $A59, INDEX(OtrosR!$E$3:$P$100, , MATCH(J$1, OtrosR!$E$2:$P$2, 0))), "")} | ... N59: {=IFERROR(SUMIF(OtrosR!$C$3:$C$100, $A59, INDEX(OtrosR!$E$3:$P$100, , MATCH(N$1, OtrosR!$E$2:$P$2, 0))), "")}
A60: =Menus!Q8 | B60: =SUM(IF(MONTH(TODAY())>1,C60,0), IF(MONTH(TODAY())>2,D60,0), IF(MONTH(TODAY())>3,E60,0), IF(MONTH(TODAY())>4,F60,0), IF(MONTH(TODAY())>5,G60,0), IF(MONTH(TODAY())>6,H60,0), IF(MONTH(TODAY())>7,I60,0), IF(MONTH(TODAY())>8,J60,0), IF(MONTH(TODAY())>9,K60,0), IF(MONTH(TODAY())>10,L60,0), IF(MONTH(TODAY())>11,M60,0), IF(MONTH(TODAY())>12,N60,0)) -> 0 | C60: {=IFERROR(SUMIF(OtrosR!$C$3:$C$100, $A60, INDEX(OtrosR!$E$3:$P$100, , MATCH(C$1, OtrosR!$E$2:$P$2, 0))), "")} | D60: {=IFERROR(SUMIF(OtrosR!$C$3:$C$100, $A60, INDEX(OtrosR!$E$3:$P$100, , MATCH(D$1, OtrosR!$E$2:$P$2, 0))), "")} | E60: {=IFERROR(SUMIF(OtrosR!$C$3:$C$100, $A60, INDEX(OtrosR!$E$3:$P$100, , MATCH(E$1, OtrosR!$E$2:$P$2, 0))), "")} | F60: {=IFERROR(SUMIF(OtrosR!$C$3:$C$100, $A60, INDEX(OtrosR!$E$3:$P$100, , MATCH(F$1, OtrosR!$E$2:$P$2, 0))), "")} | G60: {=IFERROR(SUMIF(OtrosR!$C$3:$C$100, $A60, INDEX(OtrosR!$E$3:$P$100, , MATCH(G$1, OtrosR!$E$2:$P$2, 0))), "")} | H60: {=IFERROR(SUMIF(OtrosR!$C$3:$C$100, $A60, INDEX(OtrosR!$E$3:$P$100, , MATCH(H$1, OtrosR!$E$2:$P$2, 0))), "")} | I60: {=IFERROR(SUMIF(OtrosR!$C$3:$C$100, $A60, INDEX(OtrosR!$E$3:$P$100, , MATCH(I$1, OtrosR!$E$2:$P$2, 0))), "")} | J60: {=IFERROR(SUMIF(OtrosR!$C$3:$C$100, $A60, INDEX(OtrosR!$E$3:$P$100, , MATCH(J$1, OtrosR!$E$2:$P$2, 0))), "")} | ... N60: {=IFERROR(SUMIF(OtrosR!$C$3:$C$100, $A60, INDEX(OtrosR!$E$3:$P$100, , MATCH(N$1, OtrosR!$E$2:$P$2, 0))), "")}
A61: =Menus!Q9 | B61: =SUM(IF(MONTH(TODAY())>1,C61,0), IF(MONTH(TODAY())>2,D61,0), IF(MONTH(TODAY())>3,E61,0), IF(MONTH(TODAY())>4,F61,0), IF(MONTH(TODAY())>5,G61,0), IF(MONTH(TODAY())>6,H61,0), IF(MONTH(TODAY())>7,I61,0), IF(MONTH(TODAY())>8,J61,0), IF(MONTH(TODAY())>9,K61,0), IF(MONTH(TODAY())>10,L61,0), IF(MONTH(TODAY())>11,M61,0), IF(MONTH(TODAY())>12,N61,0)) -> 0 | C61: {=IFERROR(SUMIF(OtrosR!$C$3:$C$100, $A61, INDEX(OtrosR!$E$3:$P$100, , MATCH(C$1, OtrosR!$E$2:$P$2, 0))), "")} | D61: {=IFERROR(SUMIF(OtrosR!$C$3:$C$100, $A61, INDEX(OtrosR!$E$3:$P$100, , MATCH(D$1, OtrosR!$E$2:$P$2, 0))), "")} | E61: {=IFERROR(SUMIF(OtrosR!$C$3:$C$100, $A61, INDEX(OtrosR!$E$3:$P$100, , MATCH(E$1, OtrosR!$E$2:$P$2, 0))), "")} | F61: {=IFERROR(SUMIF(OtrosR!$C$3:$C$100, $A61, INDEX(OtrosR!$E$3:$P$100, , MATCH(F$1, OtrosR!$E$2:$P$2, 0))), "")} | G61: {=IFERROR(SUMIF(OtrosR!$C$3:$C$100, $A61, INDEX(OtrosR!$E$3:$P$100, , MATCH(G$1, OtrosR!$E$2:$P$2, 0))), "")} | H61: {=IFERROR(SUMIF(OtrosR!$C$3:$C$100, $A61, INDEX(OtrosR!$E$3:$P$100, , MATCH(H$1, OtrosR!$E$2:$P$2, 0))), "")} | I61: {=IFERROR(SUMIF(OtrosR!$C$3:$C$100, $A61, INDEX(OtrosR!$E$3:$P$100, , MATCH(I$1, OtrosR!$E$2:$P$2, 0))), "")} | J61: {=IFERROR(SUMIF(OtrosR!$C$3:$C$100, $A61, INDEX(OtrosR!$E$3:$P$100, , MATCH(J$1, OtrosR!$E$2:$P$2, 0))), "")} | ... N61: {=IFERROR(SUMIF(OtrosR!$C$3:$C$100, $A61, INDEX(OtrosR!$E$3:$P$100, , MATCH(N$1, OtrosR!$E$2:$P$2, 0))), "")}
